Workbook

Sheet Index
A1: ID | B1: Card | C1: Type | D1: Stage / Rarity (trainer) | E1: Remaining Evo | F1: Deck Feature Tier | G1: Opener Archetype | H1: Possible CPU Deck Block? | I1: Included in B1 opp Deck? | K1: Feature Tier Key
A2: base1-1 | B2: Alakazam | C2: P | D2: 2 | F2: 2.5 | I2: TRUE | K2: Not shown | L2: Not worth noting
A3: base1-2 | B3: Blastoise | C3: W | D3: 2 | F3: 4 | I3: TRUE | K3: 1 | L3: Strategic Opener / Tank / Other utility
A4: base1-3 | B4: Chansey | C4: C | D4: b | E4: n | F4: 1.5 | G4: t | I4: TRUE | K4: 2 | L4: Secondary Feature
A5: base1-4 | B5: Charizard | C5: R | D5: 2 | F5: 4 | I5: TRUE | K5: 3 | L5: Primary Feature
A6: base1-5 | B6: Clefairy | C6: C | D6: b | E6: y | F6: 0.5 | I6: TRUE | K6: 4 | L6: Elite Feature
A7: base1-6 | B7: Gyarados | C7: W | D7: 1 | E7: n | F7: 2 | I7: TRUE
A8: base1-7 | B8: Hitmonchan | C8: F | D8: b | E8: n | F8: 1 | G8: o | I8: TRUE
A9: base1-8 | B9: Machamp | C9: F | D9: 2 | F9: 3 | I9: TRUE | K9: Tier ranking is only for last of evolution line and select useful others. Partially based in subjectivity and play experience
A10: base1-9 | B10: Magneton | C10: E | D10: 1 | E10: n | F10: 2 | I10: TRUE | K10: Remaining Evo only applies to Basic and Stage 1. All stage 2 are assumed to not have evolutions remaining
A11: base1-10 | B11: Mewtwo | C11: P | D11: b | E11: n | F11: 1 | G11: f | I11: TRUE | K11: Labels here are used for the lookup table on the deck tabs, but we can possibly get utility from it as well with the AI
A12: base1-11 | B12: Nidoking | C12: G | D12: 2 | F12: 3 | I12: TRUE | K12: Trainer rarity is used to gauge usefulness in decks
A13: base1-12 | B13: Ninetales | C13: F | D13: 1 | E13: n | F13: 2 | I13: TRUE | K13: Half steps are used. Consider those candidates for the next tier with proper support
A14: base1-13 | B14: Poliwrath | C14: W | D14: 2 | F14: 3 | I14: TRUE | K14: Opener archetypes per card are tracked. I don't know if we'll need these but it's cheap to do while going through the set anyway. Unlabeled ones should be deferred as openers when possible, but usually committed to once they're in. Based on battle utility, not whether they can evolve, etc
A15: base1-14 | B15: Raichu | C15: E | D15: 1 | E15: n | F15: 2 | I15: TRUE
A16: base1-15 | B16: Venusaur | C16: G | D16: 2 | F16: 3 | I16: TRUE
A17: base1-16 | B17: Zapdos | C17: E | D17: b | E17: n | F17: 1.5 | G17: h | I17: TRUE
A18: base1-17 | B18: Beedrill | C18: G | D18: 2 | F18: 3 | I18: TRUE
A19: base1-18 | B19: Dragonair | C19: C | D19: 1 | E19: y | F19: 1 | I19: TRUE | K19: Opener Archetype Key:
A20: base1-19 | B20: Dugtrio | C20: F | D20: 1 | E20: n | F20: 2 | I20: TRUE
A21: base1-20 | B21: Electabuzz | C21: E | D21: b | E21: n | F21: 1 | I21: TRUE | K21: A | L21: Attack Opener. Openers that use stalling attacks, low damage attacks w/ high HP, or build up to damage quickly without evo. Should be weighted high for starter selection or stalling jobs, lower for retreat. Can sometimes also build up to stronger moves while stalling. Ex: Onix, Jynx
A22: base1-21 | B22: Electrode | C22: E | D22: 1 | E22: n | F22: 2 | I22: TRUE | K22: T | L22: Tanks. Usually used as openers but attacks are usually defensive stalling or card drawing. Usually weighted higher than other openers. Ex: Chansey
A23: base1-22 | B23: Pidgeotto | C23: C | D23: 1 | E23: y | I23: TRUE | K23: F | L23: Fallback opener. Good cheap attack option during game, not a main weapon but capable of bridging gaps. Good opener if other options aren't available. Ex: Mewtwo (1-10)
A24: base1-23 | B24: Arcanine | C24: R | D24: 1 | E24: n | F24: 2 | I24: TRUE | K24: E | L24: Evo openerer. Lower weight when it comes to opening due to evolution possibility but does have stalling moves or can do damage, and should be prioritized when stalling is needed and no other options available. Higher priority if evolution exists in hand and is realistic to survive long enough to evolve. Ex: Squirtle
A25: base1-24 | B25: Charmeleon | C25: R | D25: 1 | E25: y | I25: TRUE | K25: N | L25: Avoid using as an opener when possible. Should be weighted lower than the baseline and possibly even switched out when other options become available. Ex: Magikarp
A26: base1-25 | B26: Dewgong | C26: W | D26: 1 | E26: n | F26: 2 | I26: TRUE | K26: H | L26: HP staller. A high HP card that would normally be used as an attacker is substituted as a tank due to lack of other options. Committed to once in, not retreated or powered up unless smart to do so. A complete sacrifice. Ex: Zapdos (1-16)
A27: base1-26 | B27: Dratini | C27: C | D27: b | E27: y | I27: TRUE
A28: base1-27 | B28: Farfetch'd | C28: C | D28: b | E28: n | G28: a | I28: TRUE
A29: base1-28 | B29: Growlithe | C29: R | D29: b | E29: y | I29: TRUE
A30: base1-29 | B30: Haunter | C30: P | D30: 1 | E30: y | I30: TRUE
A31: base1-30 | B31: Ivysaur | C31: G | D31: 1 | E31: y | I31: TRUE
A32: base1-31 | B32: Jynx | C32: P | D32: b | E32: n | F32: 1 | G32: a | I32: TRUE
A33: base1-32 | B33: Kadabra | C33: P | D33: 1 | E33: y | I33: TRUE
A34: base1-33 | B34: Kakuna | C34: G | D34: 1 | E34: y | I34: TRUE
A35: base1-34 | B35: Machoke | C35: F | D35: 1 | E35: y | I35: TRUE
A36: base1-35 | B36: Magikarp | C36: W | D36: b | E36: y | G36: n | I36: TRUE
A37: base1-36 | B37: Magmar | C37: R | D37: b | E37: n | G37: f | I37: TRUE
A38: base1-37 | B38: Nidorino | C38: G | D38: 1 | E38: y | I38: TRUE
A39: base1-38 | B39: Poliwhirl | C39: W | D39: 1 | E39: y | I39: TRUE
A40: base1-39 | B40: Porygon | C40: C | D40: b | E40: n | G40: a | I40: TRUE
...

Sheet Template
A1: Card | B1: Quantity | C1: Type | D1: ID | E1: Stage / Rarity | F1: Remaining Evo | G1: Feature Weight | I1: Card Total | K1: Type | L1: Num | M1: Basic | N1: S1 Max | O1: S1 Mid | P1: S2 | Q1: No Evolve
C2: {=IF(NOT(ISBLANK($A2)), (_xlfn.XLOOKUP($A2,Index!$B$2:$B$103,Index!$C$2:$C$103,"Not Found")),"")} | D2: {=IF(NOT(ISBLANK(A2)), (_xlfn.XLOOKUP($A2,Index!$B$2:B$103,Index!$A$2:$A$103,"Not Found")),"")} | E2: {=IF(NOT(ISBLANK($A2)), (_xlfn.XLOOKUP($A2,Index!$B$2:$B$103,Index!$D$2:$D$103,"Not Found")),"")} | F2: {=IF(NOT(ISBLANK($A2)), (_xlfn.XLOOKUP($A2,Index!$B$2:$B$103,Index!$E$2:$E$103,"Not Found")),"")} | G2: {=IF(NOT(ISBLANK(A2)), ((_xlfn.XLOOKUP(A2,Index!$B$2:$B$103,Index!$F$2:$F$103,"Not Found"))*B2),"")} | I2: =SUM(B2:B38) -> 0 | L2: =IF(NOT(ISBLANK(K2)), SUM(M2:P2), "") | M2: =IF(NOT(ISBLANK($K2)), SUMIFS($B$2:$B$32, $E$2:$E$32, "B", $C$2:$C$32,$K2), "") | N2: =IF(NOT(ISBLANK($K2)),SUMIFS($B$2:$B$32,$E$2:$E$32, "1", $C$2:$C$32,$K2,$F$2:$F$32,"N"), "") | O2: =IF(NOT(ISBLANK($K2)),SUMIFS($B$2:$B$32,$E$2:$E$32, "1", $C$2:$C$32,$K2,$F$2:$F$32,"Y"), "") | P2: =IF(NOT(ISBLANK($K2)),SUMIFS($B$2:$B$32,$E$2:$E$32, "2", $C$2:$C$32,$K2), "") | Q2: =IF(NOT(ISBLANK($K2)),SUMIFS($B$2:$B$32,$E$2:$E$32, "B", $C$2:$C$32,$K2,$F$2:$F$32,"N"), "")
C3: {=IF(NOT(ISBLANK($A3)), (_xlfn.XLOOKUP($A3,Index!$B$2:$B$103,Index!$C$2:$C$103,"Not Found")),"")} | D3: {=IF(NOT(ISBLANK(A3)), (_xlfn.XLOOKUP($A3,Index!$B$2:B$103,Index!$A$2:$A$103,"Not Found")),"")} | E3: {=IF(NOT(ISBLANK($A3)), (_xlfn.XLOOKUP($A3,Index!$B$2:$B$103,Index!$D$2:$D$103,"Not Found")),"")} | F3: {=IF(NOT(ISBLANK($A3)), (_xlfn.XLOOKUP($A3,Index!$B$2:$B$103,Index!$E$2:$E$103,"Not Found")),"")} | G3: {=IF(NOT(ISBLANK(A3)), ((_xlfn.XLOOKUP(A3,Index!$B$2:$B$103,Index!$F$2:$F$103,"Not Found"))*B3),"")} | L3: =IF(NOT(ISBLANK(K3)), SUM(M3:P3), "") | M3: =IF(NOT(ISBLANK($K3)), SUMIFS($B$2:$B$32, $E$2:$E$32, "B", $C$2:$C$32,$K3), "") | N3: =IF(NOT(ISBLANK($K3)),SUMIFS($B$2:$B$32,$E$2:$E$32, "1", $C$2:$C$32,$K3,$F$2:$F$32,"N"), "") | O3: =IF(NOT(ISBLANK($K3)),SUMIFS($B$2:$B$32,$E$2:$E$32, "1", $C$2:$C$32,$K3,$F$2:$F$32,"Y"), "") | P3: =IF(NOT(ISBLANK($K3)),SUMIFS($B$2:$B$32,$E$2:$E$32, "2", $C$2:$C$32,$K3), "") | Q3: =IF(NOT(ISBLANK($K3)),SUMIFS($B$2:$B$32,$E$2:$E$32, "B", $C$2:$C$32,$K3,$F$2:$F$32,"N"), "")
C4: {=IF(NOT(ISBLANK($A4)), (_xlfn.XLOOKUP($A4,Index!$B$2:$B$103,Index!$C$2:$C$103,"Not Found")),"")} | D4: {=IF(NOT(ISBLANK(A4)), (_xlfn.XLOOKUP($A4,Index!$B$2:B$103,Index!$A$2:$A$103,"Not Found")),"")} | E4: {=IF(NOT(ISBLANK($A4)), (_xlfn.XLOOKUP($A4,Index!$B$2:$B$103,Index!$D$2:$D$103,"Not Found")),"")} | F4: {=IF(NOT(ISBLANK($A4)), (_xlfn.XLOOKUP($A4,Index!$B$2:$B$103,Index!$E$2:$E$103,"Not Found")),"")} | G4: {=IF(NOT(ISBLANK(A4)), ((_xlfn.XLOOKUP(A4,Index!$B$2:$B$103,Index!$F$2:$F$103,"Not Found"))*B4),"")} | L4: =IF(NOT(ISBLANK(K4)), SUM(M4:P4), "") | M4: =IF(NOT(ISBLANK($K4)), SUMIFS($B$2:$B$32, $E$2:$E$32, "B", $C$2:$C$32,$K4), "") | N4: =IF(NOT(ISBLANK($K4)),SUMIFS($B$2:$B$32,$E$2:$E$32, "1", $C$2:$C$32,$K4,$F$2:$F$32,"N"), "") | O4: =IF(NOT(ISBLANK($K4)),SUMIFS($B$2:$B$32,$E$2:$E$32, "1", $C$2:$C$32,$K4,$F$2:$F$32,"Y"), "") | P4: =IF(NOT(ISBLANK($K4)),SUMIFS($B$2:$B$32,$E$2:$E$32, "2", $C$2:$C$32,$K4), "") | Q4: =IF(NOT(ISBLANK($K4)),SUMIFS($B$2:$B$32,$E$2:$E$32, "B", $C$2:$C$32,$K4,$F$2:$F$32,"N"), "")
C5: {=IF(NOT(ISBLANK($A5)), (_xlfn.XLOOKUP($A5,Index!$B$2:$B$103,Index!$C$2:$C$103,"Not Found")),"")} | D5: {=IF(NOT(ISBLANK(A5)), (_xlfn.XLOOKUP($A5,Index!$B$2:B$103,Index!$A$2:$A$103,"Not Found")),"")} | E5: {=IF(NOT(ISBLANK($A5)), (_xlfn.XLOOKUP($A5,Index!$B$2:$B$103,Index!$D$2:$D$103,"Not Found")),"")} | F5: {=IF(NOT(ISBLANK($A5)), (_xlfn.XLOOKUP($A5,Index!$B$2:$B$103,Index!$E$2:$E$103,"Not Found")),"")} | G5: {=IF(NOT(ISBLANK(A5)), ((_xlfn.XLOOKUP(A5,Index!$B$2:$B$103,Index!$F$2:$F$103,"Not Found"))*B5),"")} | L5: =IF(NOT(ISBLANK(K5)), SUM(M5:P5), "") | M5: =IF(NOT(ISBLANK($K5)), SUMIFS($B$2:$B$32, $E$2:$E$32, "B", $C$2:$C$32,$K5), "") | N5: =IF(NOT(ISBLANK($K5)),SUMIFS($B$2:$B$32,$E$2:$E$32, "1", $C$2:$C$32,$K5,$F$2:$F$32,"N"), "") | O5: =IF(NOT(ISBLANK($K5)),SUMIFS($B$2:$B$32,$E$2:$E$32, "1", $C$2:$C$32,$K5,$F$2:$F$32,"Y"), "") | P5: =IF(NOT(ISBLANK($K5)),SUMIFS($B$2:$B$32,$E$2:$E$32, "2", $C$2:$C$32,$K5), "") | Q5: =IF(NOT(ISBLANK($K5)),SUMIFS($B$2:$B$32,$E$2:$E$32, "B", $C$2:$C$32,$K5,$F$2:$F$32,"N"), "")
C6: {=IF(NOT(ISBLANK($A6)), (_xlfn.XLOOKUP($A6,Index!$B$2:$B$103,Index!$C$2:$C$103,"Not Found")),"")} | D6: {=IF(NOT(ISBLANK(A6)), (_xlfn.XLOOKUP($A6,Index!$B$2:B$103,Index!$A$2:$A$103,"Not Found")),"")} | E6: {=IF(NOT(ISBLANK($A6)), (_xlfn.XLOOKUP($A6,Index!$B$2:$B$103,Index!$D$2:$D$103,"Not Found")),"")} | F6: {=IF(NOT(ISBLANK($A6)), (_xlfn.XLOOKUP($A6,Index!$B$2:$B$103,Index!$E$2:$E$103,"Not Found")),"")} | G6: {=IF(NOT(ISBLANK(A6)), ((_xlfn.XLOOKUP(A6,Index!$B$2:$B$103,Index!$F$2:$F$103,"Not Found"))*B6),"")} | L6: =IF(NOT(ISBLANK(K6)), SUM(M6:P6), "") | M6: =IF(NOT(ISBLANK($K6)), COUNTIFS($E$2:$E$32, "B", $C$2:$C$32,$K6), "") | N6: =IF(NOT(ISBLANK(K6)),COUNTIFS($E$2:$E$32, "1", $C$2:$C$32,$K6,$F$2:$F$32,"N"), "") | O6: =IF(NOT(ISBLANK($K6)),COUNTIFS($E$2:$E$32, "1", $C$2:$C$32,$K6,$F$2:$F$32,"Y"), "") | P6: =IF(NOT(ISBLANK($K6)),COUNTIFS($E$2:$E$32, "2", $C$2:$C$32,$K6), "") | Q6: =IF(NOT(ISBLANK($K6)),COUNTIFS($E$2:$E$32, "B", $C$2:$C$32,$K6,$F$2:$F$32,"N"), "")
C7: {=IF(NOT(ISBLANK($A7)), (_xlfn.XLOOKUP($A7,Index!$B$2:$B$103,Index!$C$2:$C$103,"Not Found")),"")} | D7: {=IF(NOT(ISBLANK(A7)), (_xlfn.XLOOKUP($A7,Index!$B$2:B$103,Index!$A$2:$A$103,"Not Found")),"")} | E7: {=IF(NOT(ISBLANK($A7)), (_xlfn.XLOOKUP($A7,Index!$B$2:$B$103,Index!$D$2:$D$103,"Not Found")),"")} | F7: {=IF(NOT(ISBLANK($A7)), (_xlfn.XLOOKUP($A7,Index!$B$2:$B$103,Index!$E$2:$E$103,"Not Found")),"")} | G7: {=IF(NOT(ISBLANK(A7)), ((_xlfn.XLOOKUP(A7,Index!$B$2:$B$103,Index!$F$2:$F$103,"Not Found"))*B7),"")} | K7: Total | L7: =SUM(L2:L6) -> 0 | M7: =SUM(M2:M6) -> 0 | N7: =SUM(N2:N6) -> 0 | O7: =SUM(O2:O6) -> 0 | P7: =SUM(P2:P6) -> 0 | Q7: =SUM(Q2:Q6) -> 0
C8: {=IF(NOT(ISBLANK($A8)), (_xlfn.XLOOKUP($A8,Index!$B$2:$B$103,Index!$C$2:$C$103,"Not Found")),"")} | D8: {=IF(NOT(ISBLANK(A8)), (_xlfn.XLOOKUP($A8,Index!$B$2:B$103,Index!$A$2:$A$103,"Not Found")),"")} | E8: {=IF(NOT(ISBLANK($A8)), (_xlfn.XLOOKUP($A8,Index!$B$2:$B$103,Index!$D$2:$D$103,"Not Found")),"")} | F8: {=IF(NOT(ISBLANK($A8)), (_xlfn.XLOOKUP($A8,Index!$B$2:$B$103,Index!$E$2:$E$103,"Not Found")),"")} | G8: {=IF(NOT(ISBLANK(A8)), ((_xlfn.XLOOKUP(A8,Index!$B$2:$B$103,Index!$F$2:$F$103,"Not Found"))*B8),"")}
C9: {=IF(NOT(ISBLANK($A9)), (_xlfn.XLOOKUP($A9,Index!$B$2:$B$103,Index!$C$2:$C$103,"Not Found")),"")} | D9: {=IF(NOT(ISBLANK(A9)), (_xlfn.XLOOKUP($A9,Index!$B$2:B$103,Index!$A$2:$A$103,"Not Found")),"")} | E9: {=IF(NOT(ISBLANK($A9)), (_xlfn.XLOOKUP($A9,Index!$B$2:$B$103,Index!$D$2:$D$103,"Not Found")),"")} | F9: {=IF(NOT(ISBLANK($A9)), (_xlfn.XLOOKUP($A9,Index!$B$2:$B$103,Index!$E$2:$E$103,"Not Found")),"")} | G9: {=IF(NOT(ISBLANK(A9)), ((_xlfn.XLOOKUP(A9,Index!$B$2:$B$103,Index!$F$2:$F$103,"Not Found"))*B9),"")} | M9: Common | N9: Uncommon | O9: Rare
C10: {=IF(NOT(ISBLANK($A10)), (_xlfn.XLOOKUP($A10,Index!$B$2:$B$103,Index!$C$2:$C$103,"Not Found")),"")} | D10: {=IF(NOT(ISBLANK(A10)), (_xlfn.XLOOKUP($A10,Index!$B$2:B$103,Index!$A$2:$A$103,"Not Found")),"")} | E10: {=IF(NOT(ISBLANK($A10)), (_xlfn.XLOOKUP($A10,Index!$B$2:$B$103,Index!$D$2:$D$103,"Not Found")),"")} | F10: {=IF(NOT(ISBLANK($A10)), (_xlfn.XLOOKUP($A10,Index!$B$2:$B$103,Index!$E$2:$E$103,"Not Found")),"")} | G10: {=IF(NOT(ISBLANK(A10)), ((_xlfn.XLOOKUP(A10,Index!$B$2:$B$103,Index!$F$2:$F$103,"Not Found"))*B10),"")} | K10: Trainer | L10: =SUM(M10:P10) -> 0 | M10: =IF(NOT(ISBLANK($K10)), SUMIFS($B$2:$B$32,$E$2:$E$32, "C", $C$2:$C$32,"T"), "") -> 0 | N10: =IF(NOT(ISBLANK($K10)), SUMIFS($B$2:$B$32,$E$2:$E$32, "U", $C$2:$C$32,"T"), "") -> 0 | O10: =IF(NOT(ISBLANK($K$2)), SUMIFS($B$2:$B$32,$E$2:$E$32, "R", $C$2:$C$32,"T"), "")
C11: {=IF(NOT(ISBLANK($A11)), (_xlfn.XLOOKUP($A11,Index!$B$2:$B$103,Index!$C$2:$C$103,"Not Found")),"")} | D11: {=IF(NOT(ISBLANK(A11)), (_xlfn.XLOOKUP($A11,Index!$B$2:B$103,Index!$A$2:$A$103,"Not Found")),"")} | E11: {=IF(NOT(ISBLANK($A11)), (_xlfn.XLOOKUP($A11,Index!$B$2:$B$103,Index!$D$2:$D$103,"Not Found")),"")} | F11: {=IF(NOT(ISBLANK($A11)), (_xlfn.XLOOKUP($A11,Index!$B$2:$B$103,Index!$E$2:$E$103,"Not Found")),"")} | G11: {=IF(NOT(ISBLANK(A11)), ((_xlfn.XLOOKUP(A11,Index!$B$2:$B$103,Index!$F$2:$F$103,"Not Found"))*B11),"")} | K11: Energy | L11: =IF(NOT(ISBLANK($K$2)), SUMIFS($B$2:$B$32, $C$2:$C$32,"Energy"), "")
C12: {=IF(NOT(ISBLANK($A12)), (_xlfn.XLOOKUP($A12,Index!$B$2:$B$103,Index!$C$2:$C$103,"Not Found")),"")} | D12: {=IF(NOT(ISBLANK(A12)), (_xlfn.XLOOKUP($A12,Index!$B$2:B$103,Index!$A$2:$A$103,"Not Found")),"")} | E12: {=IF(NOT(ISBLANK($A12)), (_xlfn.XLOOKUP($A12,Index!$B$2:$B$103,Index!$D$2:$D$103,"Not Found")),"")} | F12: {=IF(NOT(ISBLANK($A12)), (_xlfn.XLOOKUP($A12,Index!$B$2:$B$103,Index!$E$2:$E$103,"Not Found")),"")} | G12: {=IF(NOT(ISBLANK(A12)), ((_xlfn.XLOOKUP(A12,Index!$B$2:$B$103,Index!$F$2:$F$103,"Not Found"))*B12),"")} | K12: Pokemon | L12: =L7 -> 0
C13: {=IF(NOT(ISBLANK($A13)), (_xlfn.XLOOKUP($A13,Index!$B$2:$B$103,Index!$C$2:$C$103,"Not Found")),"")} | D13: {=IF(NOT(ISBLANK(A13)), (_xlfn.XLOOKUP($A13,Index!$B$2:B$103,Index!$A$2:$A$103,"Not Found")),"")} | E13: {=IF(NOT(ISBLANK($A13)), (_xlfn.XLOOKUP($A13,Index!$B$2:$B$103,Index!$D$2:$D$103,"Not Found")),"")} | F13: {=IF(NOT(ISBLANK($A13)), (_xlfn.XLOOKUP($A13,Index!$B$2:$B$103,Index!$E$2:$E$103,"Not Found")),"")} | G13: {=IF(NOT(ISBLANK(A13)), ((_xlfn.XLOOKUP(A13,Index!$B$2:$B$103,Index!$F$2:$F$103,"Not Found"))*B13),"")}
C14: {=IF(NOT(ISBLANK($A14)), (_xlfn.XLOOKUP($A14,Index!$B$2:$B$103,Index!$C$2:$C$103,"Not Found")),"")} | D14: {=IF(NOT(ISBLANK(A14)), (_xlfn.XLOOKUP($A14,Index!$B$2:B$103,Index!$A$2:$A$103,"Not Found")),"")} | E14: {=IF(NOT(ISBLANK($A14)), (_xlfn.XLOOKUP($A14,Index!$B$2:$B$103,Index!$D$2:$D$103,"Not Found")),"")} | F14: {=IF(NOT(ISBLANK($A14)), (_xlfn.XLOOKUP($A14,Index!$B$2:$B$103,Index!$E$2:$E$103,"Not Found")),"")} | G14: {=IF(NOT(ISBLANK(A14)), ((_xlfn.XLOOKUP(A14,Index!$B$2:$B$103,Index!$F$2:$F$103,"Not Found"))*B14),"")}
C15: {=IF(NOT(ISBLANK($A15)), (_xlfn.XLOOKUP($A15,Index!$B$2:$B$103,Index!$C$2:$C$103,"Not Found")),"")} | D15: {=IF(NOT(ISBLANK(A15)), (_xlfn.XLOOKUP($A15,Index!$B$2:B$103,Index!$A$2:$A$103,"Not Found")),"")} | E15: {=IF(NOT(ISBLANK($A15)), (_xlfn.XLOOKUP($A15,Index!$B$2:$B$103,Index!$D$2:$D$103,"Not Found")),"")} | F15: {=IF(NOT(ISBLANK($A15)), (_xlfn.XLOOKUP($A15,Index!$B$2:$B$103,Index!$E$2:$E$103,"Not Found")),"")} | G15: {=IF(NOT(ISBLANK(A15)), ((_xlfn.XLOOKUP(A15,Index!$B$2:$B$103,Index!$F$2:$F$103,"Not Found"))*B15),"")} | K15: Feature Weight:
C16: {=IF(NOT(ISBLANK($A16)), (_xlfn.XLOOKUP($A16,Index!$B$2:$B$103,Index!$C$2:$C$103,"Not Found")),"")} | D16: {=IF(NOT(ISBLANK(A16)), (_xlfn.XLOOKUP($A16,Index!$B$2:B$103,Index!$A$2:$A$103,"Not Found")),"")} | E16: {=IF(NOT(ISBLANK($A16)), (_xlfn.XLOOKUP($A16,Index!$B$2:$B$103,Index!$D$2:$D$103,"Not Found")),"")} | F16: {=IF(NOT(ISBLANK($A16)), (_xlfn.XLOOKUP($A16,Index!$B$2:$B$103,Index!$E$2:$E$103,"Not Found")),"")} | G16: {=IF(NOT(ISBLANK(A16)), ((_xlfn.XLOOKUP(A16,Index!$B$2:$B$103,Index!$F$2:$F$103,"Not Found"))*B16),"")} | K16: =K2 | L16: =IF(NOT(ISBLANK($K2)), SUMIFS($G$2:$G$32, $C$2:$C$32,$K2), "")
C17: {=IF(NOT(ISBLANK($A17)), (_xlfn.XLOOKUP($A17,Index!$B$2:$B$103,Index!$C$2:$C$103,"Not Found")),"")} | D17: {=IF(NOT(ISBLANK(A17)), (_xlfn.XLOOKUP($A17,Index!$B$2:B$103,Index!$A$2:$A$103,"Not Found")),"")} | E17: {=IF(NOT(ISBLANK($A17)), (_xlfn.XLOOKUP($A17,Index!$B$2:$B$103,Index!$D$2:$D$103,"Not Found")),"")} | F17: {=IF(NOT(ISBLANK($A17)), (_xlfn.XLOOKUP($A17,Index!$B$2:$B$103,Index!$E$2:$E$103,"Not Found")),"")} | G17: {=IF(NOT(ISBLANK(A17)), ((_xlfn.XLOOKUP(A17,Index!$B$2:$B$103,Index!$F$2:$F$103,"Not Found"))*B17),"")} | K17: =K3 | L17: =IF(NOT(ISBLANK($K3)), SUMIFS($G$2:$G$32, $C$2:$C$32,$K3), "")
C18: {=IF(NOT(ISBLANK($A18)), (_xlfn.XLOOKUP($A18,Index!$B$2:$B$103,Index!$C$2:$C$103,"Not Found")),"")} | D18: {=IF(NOT(ISBLANK(A18)), (_xlfn.XLOOKUP($A18,Index!$B$2:B$103,Index!$A$2:$A$103,"Not Found")),"")} | E18: {=IF(NOT(ISBLANK($A18)), (_xlfn.XLOOKUP($A18,Index!$B$2:$B$103,Index!$D$2:$D$103,"Not Found")),"")} | F18: {=IF(NOT(ISBLANK($A18)), (_xlfn.XLOOKUP($A18,Index!$B$2:$B$103,Index!$E$2:$E$103,"Not Found")),"")} | G18: {=IF(NOT(ISBLANK(A18)), ((_xlfn.XLOOKUP(A18,Index!$B$2:$B$103,Index!$F$2:$F$103,"Not Found"))*B18),"")} | K18: =K4 | L18: =IF(NOT(ISBLANK($K4)), SUMIFS($G$2:$G$32, $C$2:$C$32,$K4), "")
C19: {=IF(NOT(ISBLANK($A19)), (_xlfn.XLOOKUP($A19,Index!$B$2:$B$103,Index!$C$2:$C$103,"Not Found")),"")} | D19: {=IF(NOT(ISBLANK(A19)), (_xlfn.XLOOKUP($A19,Index!$B$2:B$103,Index!$A$2:$A$103,"Not Found")),"")} | E19: {=IF(NOT(ISBLANK($A19)), (_xlfn.XLOOKUP($A19,Index!$B$2:$B$103,Index!$D$2:$D$103,"Not Found")),"")} | F19: {=IF(NOT(ISBLANK($A19)), (_xlfn.XLOOKUP($A19,Index!$B$2:$B$103,Index!$E$2:$E$103,"Not Found")),"")} | G19: {=IF(NOT(ISBLANK(A19)), ((_xlfn.XLOOKUP(A19,Index!$B$2:$B$103,Index!$F$2:$F$103,"Not Found"))*B19),"")} | K19: =K5 | L19: =IF(NOT(ISBLANK($K5)), SUMIFS($G$2:$G$32, $C$2:$C$32,$K5), "")
C20: {=IF(NOT(ISBLANK($A20)), (_xlfn.XLOOKUP($A20,Index!$B$2:$B$103,Index!$C$2:$C$103,"Not Found")),"")} | D20: {=IF(NOT(ISBLANK(A20)), (_xlfn.XLOOKUP($A20,Index!$B$2:B$103,Index!$A$2:$A$103,"Not Found")),"")} | E20: {=IF(NOT(ISBLANK($A20)), (_xlfn.XLOOKUP($A20,Index!$B$2:$B$103,Index!$D$2:$D$103,"Not Found")),"")} | F20: {=IF(NOT(ISBLANK($A20)), (_xlfn.XLOOKUP($A20,Index!$B$2:$B$103,Index!$E$2:$E$103,"Not Found")),"")} | G20: {=IF(NOT(ISBLANK(A20)), ((_xlfn.XLOOKUP(A20,Index!$B$2:$B$103,Index!$F$2:$F$103,"Not Found"))*B20),"")} | K20: =K6
C21: {=IF(NOT(ISBLANK($A21)), (_xlfn.XLOOKUP($A21,Index!$B$2:$B$103,Index!$C$2:$C$103,"Not Found")),"")} | D21: {=IF(NOT(ISBLANK(A21)), (_xlfn.XLOOKUP($A21,Index!$B$2:B$103,Index!$A$2:$A$103,"Not Found")),"")} | E21: {=IF(NOT(ISBLANK($A21)), (_xlfn.XLOOKUP($A21,Index!$B$2:$B$103,Index!$D$2:$D$103,"Not Found")),"")} | F21: {=IF(NOT(ISBLANK($A21)), (_xlfn.XLOOKUP($A21,Index!$B$2:$B$103,Index!$E$2:$E$103,"Not Found")),"")} | G21: {=IF(NOT(ISBLANK(A21)), ((_xlfn.XLOOKUP(A21,Index!$B$2:$B$103,Index!$F$2:$F$103,"Not Found"))*B21),"")} | K21: Total: | L21: =SUM(G2:G46) -> 0
C22: {=IF(NOT(ISBLANK($A22)), (_xlfn.XLOOKUP($A22,Index!$B$2:$B$103,Index!$C$2:$C$103,"Not Found")),"")} | D22: {=IF(NOT(ISBLANK(A22)), (_xlfn.XLOOKUP($A22,Index!$B$2:B$103,Index!$A$2:$A$103,"Not Found")),"")} | E22: {=IF(NOT(ISBLANK($A22)), (_xlfn.XLOOKUP($A22,Index!$B$2:$B$103,Index!$D$2:$D$103,"Not Found")),"")} | F22: {=IF(NOT(ISBLANK($A22)), (_xlfn.XLOOKUP($A22,Index!$B$2:$B$103,Index!$E$2:$E$103,"Not Found")),"")} | G22: {=IF(NOT(ISBLANK(A22)), ((_xlfn.XLOOKUP(A22,Index!$B$2:$B$103,Index!$F$2:$F$103,"Not Found"))*B22),"")}
C23: {=IF(NOT(ISBLANK($A23)), (_xlfn.XLOOKUP($A23,Index!$B$2:$B$103,Index!$C$2:$C$103,"Not Found")),"")} | D23: {=IF(NOT(ISBLANK(A23)), (_xlfn.XLOOKUP($A23,Index!$B$2:B$103,Index!$A$2:$A$103,"Not Found")),"")} | E23: {=IF(NOT(ISBLANK($A23)), (_xlfn.XLOOKUP($A23,Index!$B$2:$B$103,Index!$D$2:$D$103,"Not Found")),"")} | F23: {=IF(NOT(ISBLANK($A23)), (_xlfn.XLOOKUP($A23,Index!$B$2:$B$103,Index!$E$2:$E$103,"Not Found")),"")} | G23: {=IF(NOT(ISBLANK(A23)), ((_xlfn.XLOOKUP(A23,Index!$B$2:$B$103,Index!$F$2:$F$103,"Not Found"))*B23),"")}
C24: {=IF(NOT(ISBLANK($A24)), (_xlfn.XLOOKUP($A24,Index!$B$2:$B$103,Index!$C$2:$C$103,"Not Found")),"")} | D24: {=IF(NOT(ISBLANK(A24)), (_xlfn.XLOOKUP($A24,Index!$B$2:B$103,Index!$A$2:$A$103,"Not Found")),"")} | E24: {=IF(NOT(ISBLANK($A24)), (_xlfn.XLOOKUP($A24,Index!$B$2:$B$103,Index!$D$2:$D$103,"Not Found")),"")} | F24: {=IF(NOT(ISBLANK($A24)), (_xlfn.XLOOKUP($A24,Index!$B$2:$B$103,Index!$E$2:$E$103,"Not Found")),"")} | G24: {=IF(NOT(ISBLANK(A24)), ((_xlfn.XLOOKUP(A24,Index!$B$2:$B$103,Index!$F$2:$F$103,"Not Found"))*B24),"")}
C25: {=IF(NOT(ISBLANK($A25)), (_xlfn.XLOOKUP($A25,Index!$B$2:$B$103,Index!$C$2:$C$103,"Not Found")),"")} | D25: {=IF(NOT(ISBLANK(A25)), (_xlfn.XLOOKUP($A25,Index!$B$2:B$103,Index!$A$2:$A$103,"Not Found")),"")} | E25: {=IF(NOT(ISBLANK($A25)), (_xlfn.XLOOKUP($A25,Index!$B$2:$B$103,Index!$D$2:$D$103,"Not Found")),"")} | F25: {=IF(NOT(ISBLANK($A25)), (_xlfn.XLOOKUP($A25,Index!$B$2:$B$103,Index!$E$2:$E$103,"Not Found")),"")} | G25: {=IF(NOT(ISBLANK(A25)), ((_xlfn.XLOOKUP(A25,Index!$B$2:$B$103,Index!$F$2:$F$103,"Not Found"))*B25),"")}
C26: {=IF(NOT(ISBLANK($A26)), (_xlfn.XLOOKUP($A26,Index!$B$2:$B$103,Index!$C$2:$C$103,"Not Found")),"")} | D26: {=IF(NOT(ISBLANK(A26)), (_xlfn.XLOOKUP($A26,Index!$B$2:B$103,Index!$A$2:$A$103,"Not Found")),"")} | E26: {=IF(NOT(ISBLANK($A26)), (_xlfn.XLOOKUP($A26,Index!$B$2:$B$103,Index!$D$2:$D$103,"Not Found")),"")} | F26: {=IF(NOT(ISBLANK($A26)), (_xlfn.XLOOKUP($A26,Index!$B$2:$B$103,Index!$E$2:$E$103,"Not Found")),"")} | G26: {=IF(NOT(ISBLANK(A26)), ((_xlfn.XLOOKUP(A26,Index!$B$2:$B$103,Index!$F$2:$F$103,"Not Found"))*B26),"")}
C27: {=IF(NOT(ISBLANK($A27)), (_xlfn.XLOOKUP($A27,Index!$B$2:$B$103,Index!$C$2:$C$103,"Not Found")),"")} | D27: {=IF(NOT(ISBLANK(A27)), (_xlfn.XLOOKUP($A27,Index!$B$2:B$103,Index!$A$2:$A$103,"Not Found")),"")} | E27: {=IF(NOT(ISBLANK($A27)), (_xlfn.XLOOKUP($A27,Index!$B$2:$B$103,Index!$D$2:$D$103,"Not Found")),"")} | F27: {=IF(NOT(ISBLANK($A27)), (_xlfn.XLOOKUP($A27,Index!$B$2:$B$103,Index!$E$2:$E$103,"Not Found")),"")} | G27: {=IF(NOT(ISBLANK(A27)), ((_xlfn.XLOOKUP(A27,Index!$B$2:$B$103,Index!$F$2:$F$103,"Not Found"))*B27),"")}
C28: {=IF(NOT(ISBLANK($A28)), (_xlfn.XLOOKUP($A28,Index!$B$2:$B$103,Index!$C$2:$C$103,"Not Found")),"")} | D28: {=IF(NOT(ISBLANK(A28)), (_xlfn.XLOOKUP($A28,Index!$B$2:B$103,Index!$A$2:$A$103,"Not Found")),"")} | E28: {=IF(NOT(ISBLANK($A28)), (_xlfn.XLOOKUP($A28,Index!$B$2:$B$103,Index!$D$2:$D$103,"Not Found")),"")} | F28: {=IF(NOT(ISBLANK($A28)), (_xlfn.XLOOKUP($A28,Index!$B$2:$B$103,Index!$E$2:$E$103,"Not Found")),"")} | G28: {=IF(NOT(ISBLANK(A28)), ((_xlfn.XLOOKUP(A28,Index!$B$2:$B$103,Index!$F$2:$F$103,"Not Found"))*B28),"")}
C29: {=IF(NOT(ISBLANK($A29)), (_xlfn.XLOOKUP($A29,Index!$B$2:$B$103,Index!$C$2:$C$103,"Not Found")),"")} | D29: {=IF(NOT(ISBLANK(A29)), (_xlfn.XLOOKUP($A29,Index!$B$2:B$103,Index!$A$2:$A$103,"Not Found")),"")} | E29: {=IF(NOT(ISBLANK($A29)), (_xlfn.XLOOKUP($A29,Index!$B$2:$B$103,Index!$D$2:$D$103,"Not Found")),"")} | F29: {=IF(NOT(ISBLANK($A29)), (_xlfn.XLOOKUP($A29,Index!$B$2:$B$103,Index!$E$2:$E$103,"Not Found")),"")} | G29: {=IF(NOT(ISBLANK(A29)), ((_xlfn.XLOOKUP(A29,Index!$B$2:$B$103,Index!$F$2:$F$103,"Not Found"))*B29),"")}
C30: {=IF(NOT(ISBLANK($A30)), (_xlfn.XLOOKUP($A30,Index!$B$2:$B$103,Index!$C$2:$C$103,"Not Found")),"")} | D30: {=IF(NOT(ISBLANK(A30)), (_xlfn.XLOOKUP($A30,Index!$B$2:B$103,Index!$A$2:$A$103,"Not Found")),"")} | E30: {=IF(NOT(ISBLANK($A30)), (_xlfn.XLOOKUP($A30,Index!$B$2:$B$103,Index!$D$2:$D$103,"Not Found")),"")} | F30: {=IF(NOT(ISBLANK($A30)), (_xlfn.XLOOKUP($A30,Index!$B$2:$B$103,Index!$E$2:$E$103,"Not Found")),"")} | G30: {=IF(NOT(ISBLANK(A30)), ((_xlfn.XLOOKUP(A30,Index!$B$2:$B$103,Index!$F$2:$F$103,"Not Found"))*B30),"")}
C31: {=IF(NOT(ISBLANK($A31)), (_xlfn.XLOOKUP($A31,Index!$B$2:$B$103,Index!$C$2:$C$103,"Not Found")),"")} | D31: {=IF(NOT(ISBLANK(A31)), (_xlfn.XLOOKUP($A31,Index!$B$2:B$103,Index!$A$2:$A$103,"Not Found")),"")} | E31: {=IF(NOT(ISBLANK($A31)), (_xlfn.XLOOKUP($A31,Index!$B$2:$B$103,Index!$D$2:$D$103,"Not Found")),"")} | F31: {=IF(NOT(ISBLANK($A31)), (_xlfn.XLOOKUP($A31,Index!$B$2:$B$103,Index!$E$2:$E$103,"Not Found")),"")} | G31: {=IF(NOT(ISBLANK(A31)), ((_xlfn.XLOOKUP(A31,Index!$B$2:$B$103,Index!$F$2:$F$103,"Not Found"))*B31),"")}
C32: {=IF(NOT(ISBLANK($A32)), (_xlfn.XLOOKUP($A32,Index!$B$2:$B$103,Index!$C$2:$C$103,"Not Found")),"")} | D32: {=IF(NOT(ISBLANK(A32)), (_xlfn.XLOOKUP($A32,Index!$B$2:B$103,Index!$A$2:$A$103,"Not Found")),"")} | E32: {=IF(NOT(ISBLANK($A32)), (_xlfn.XLOOKUP($A32,Index!$B$2:$B$103,Index!$D$2:$D$103,"Not Found")),"")} | F32: {=IF(NOT(ISBLANK($A32)), (_xlfn.XLOOKUP($A32,Index!$B$2:$B$103,Index!$E$2:$E$103,"Not Found")),"")} | G32: {=IF(NOT(ISBLANK(A32)), ((_xlfn.XLOOKUP(A32,Index!$B$2:$B$103,Index!$F$2:$F$103,"Not Found"))*B32),"")}
C33: {=IF(NOT(ISBLANK($A33)), (_xlfn.XLOOKUP($A33,Index!$B$2:$B$103,Index!$C$2:$C$103,"Not Found")),"")} | D33: {=IF(NOT(ISBLANK(A33)), (_xlfn.XLOOKUP($A33,Index!$B$2:B$103,Index!$A$2:$A$103,"Not Found")),"")} | E33: {=IF(NOT(ISBLANK($A33)), (_xlfn.XLOOKUP($A33,Index!$B$2:$B$103,Index!$D$2:$D$103,"Not Found")),"")} | F33: {=IF(NOT(ISBLANK($A33)), (_xlfn.XLOOKUP($A33,Index!$B$2:$B$103,Index!$E$2:$E$103,"Not Found")),"")} | G33: {=IF(NOT(ISBLANK(A33)), ((_xlfn.XLOOKUP(A33,Index!$B$2:$B$103,Index!$F$2:$F$103,"Not Found"))*B33),"")}
... C36: {=IF(NOT(ISBLANK($A36)), (_xlfn.XLOOKUP($A36,Index!$B$2:$B$103,Index!$C$2:$C$103,"Not Found")),"")} | D36: {=IF(NOT(ISBLANK(A36)), (_xlfn.XLOOKUP($A36,Index!$B$2:B$103,Index!$A$2:$A$103,"Not Found")),"")} | E36: {=IF(NOT(ISBLANK($A36)), (_xlfn.XLOOKUP($A36,Index!$B$2:$B$103,Index!$D$2:$D$103,"Not Found")),"")} | F36: {=IF(NOT(ISBLANK($A36)), (_xlfn.XLOOKUP($A36,Index!$B$2:$B$103,Index!$E$2:$E$103,"Not Found")),"")} | G36: {=IF(NOT(ISBLANK(A36)), ((_xlfn.XLOOKUP(A36,Index!$B$2:$B$103,Index!$F$2:$F$103,"Not Found"))*B36),"")}
C37: {=IF(NOT(ISBLANK($A37)), (_xlfn.XLOOKUP($A37,Index!$B$2:$B$103,Index!$C$2:$C$103,"Not Found")),"")} | D37: {=IF(NOT(ISBLANK(A37)), (_xlfn.XLOOKUP($A37,Index!$B$2:B$103,Index!$A$2:$A$103,"Not Found")),"")} | E37: {=IF(NOT(ISBLANK($A37)), (_xlfn.XLOOKUP($A37,Index!$B$2:$B$103,Index!$D$2:$D$103,"Not Found")),"")} | F37: {=IF(NOT(ISBLANK($A37)), (_xlfn.XLOOKUP($A37,Index!$B$2:$B$103,Index!$E$2:$E$103,"Not Found")),"")}
D38: {=IF(NOT(ISBLANK(A38)), (_xlfn.XLOOKUP(A38,Index!$B$2:B$103,Index!$A$2:$A$103,"Not Found")),"")} | E38: {=IF(NOT(ISBLANK($A38)), (_xlfn.XLOOKUP($A38,Index!$B$2:$B$103,Index!$D$2:$D$103,"Not Found")),"")}
D39: {=IF(NOT(ISBLANK(A39)), (_xlfn.XLOOKUP(A39,Index!$B$2:B$103,Index!$A$2:$A$103,"Not Found")),"")} | E39: {=IF(NOT(ISBLANK($A39)), (_xlfn.XLOOKUP($A39,Index!$B$2:$B$103,Index!$D$2:$D$103,"Not Found")),"")}
D40: {=IF(NOT(ISBLANK(A40)), (_xlfn.XLOOKUP(A40,Index!B$2:B$103,Index!A$2:A$103,"Not Found")),"")} | E40: {=IF(NOT(ISBLANK($A40)), (_xlfn.XLOOKUP($A40,Index!$B$2:$B$103,Index!$D$2:$D$103,"Not Found")),"")}
D41: {=IF(NOT(ISBLANK(A41)), (_xlfn.XLOOKUP(A41,Index!B$2:B$103,Index!A$2:A$103,"Not Found")),"")}

Sheet B1 T2-1
A1: Card | B1: Quantity | C1: Type | D1: ID | E1: Stage / Rarity | F1: Remaining Evo | G1: Feature Weight | I1: Card Total | K1: Type | L1: Num | M1: Basic | N1: S1 Max | O1: S1 Mid | P1: S2 | Q1: No Evolve
A2: Sandshrew | B2: 1 | C2: {=IF(NOT(ISBLANK($A2)), (_xlfn.XLOOKUP($A2,Index!$B$2:$B$103,Index!$C$2:$C$103,"Not Found")),"")} -> F | D2: {=IF(NOT(ISBLANK(A2)), (_xlfn.XLOOKUP($A2,Index!$B$2:B$103,Index!$A$2:$A$103,"Not Found")),"")} -> base1-62 | E2: {=IF(NOT(ISBLANK($A2)), (_xlfn.XLOOKUP($A2,Index!$B$2:$B$103,Index!$D$2:$D$103,"Not Found")),"")} -> b | F2: {=IF(NOT(ISBLANK($A2)), (_xlfn.XLOOKUP($A2,Index!$B$2:$B$103,Index!$E$2:$E$103,"Not Found")),"")} -> y | G2: {=IF(NOT(ISBLANK(A2)), ((_xlfn.XLOOKUP(A2,Index!$B$2:$B$103,Index!$F$2:$F$103,"Not Found"))*B2),"")} -> 0 | I2: =SUM(B2:B38) -> 60 | K2: F | L2: =IF(NOT(ISBLANK(K2)), SUM(M2:P2), "") -> 11 | M2: =IF(NOT(ISBLANK($K2)), SUMIFS($B$2:$B$32, $E$2:$E$32, "B", $C$2:$C$32,$K2), "") -> 8 | N2: =IF(NOT(ISBLANK($K2)),SUMIFS($B$2:$B$32,$E$2:$E$32, "1", $C$2:$C$32,$K2,$F$2:$F$32,"N"), "") -> 1 | O2: =IF(NOT(ISBLANK($K2)),SUMIFS($B$2:$B$32,$E$2:$E$32, "1", $C$2:$C$32,$K2,$F$2:$F$32,"Y"), "") -> 2 | P2: =IF(NOT(ISBLANK($K2)),SUMIFS($B$2:$B$32,$E$2:$E$32, "2", $C$2:$C$32,$K2), "") -> 0 | Q2: =IF(NOT(ISBLANK($K2)),SUMIFS($B$2:$B$32,$E$2:$E$32, "B", $C$2:$C$32,$K2,$F$2:$F$32,"N"), "") -> 2
A3: Rattata | B3: 2 | C3: {=IF(NOT(ISBLANK($A3)), (_xlfn.XLOOKUP($A3,Index!$B$2:$B$103,Index!$C$2:$C$103,"Not Found")),"")} -> C | D3: {=IF(NOT(ISBLANK(A3)), (_xlfn.XLOOKUP($A3,Index!$B$2:B$103,Index!$A$2:$A$103,"Not Found")),"")} -> base1-61 | E3: {=IF(NOT(ISBLANK($A3)), (_xlfn.XLOOKUP($A3,Index!$B$2:$B$103,Index!$D$2:$D$103,"Not Found")),"")} -> b | F3: {=IF(NOT(ISBLANK($A3)), (_xlfn.XLOOKUP($A3,Index!$B$2:$B$103,Index!$E$2:$E$103,"Not Found")),"")} -> y | G3: {=IF(NOT(ISBLANK(A3)), ((_xlfn.XLOOKUP(A3,Index!$B$2:$B$103,Index!$F$2:$F$103,"Not Found"))*B3),"")} -> 0 | K3: W | L3: =IF(NOT(ISBLANK(K3)), SUM(M3:P3), "") -> 8 | M3: =IF(NOT(ISBLANK($K3)), SUMIFS($B$2:$B$32, $E$2:$E$32, "B", $C$2:$C$32,$K3), "") -> 5 | N3: =IF(NOT(ISBLANK($K3)),SUMIFS($B$2:$B$32,$E$2:$E$32, "1", $C$2:$C$32,$K3,$F$2:$F$32,"N"), "") -> 2 | O3: =IF(NOT(ISBLANK($K3)),SUMIFS($B$2:$B$32,$E$2:$E$32, "1", $C$2:$C$32,$K3,$F$2:$F$32,"Y"), "") -> 1 | P3: =IF(NOT(ISBLANK($K3)),SUMIFS($B$2:$B$32,$E$2:$E$32, "2", $C$2:$C$32,$K3), "") -> 0 | Q3: =IF(NOT(ISBLANK($K3)),SUMIFS($B$2:$B$32,$E$2:$E$32, "B", $C$2:$C$32,$K3,$F$2:$F$32,"N"), "") -> 0
A4: Machop | B4: 3 | C4: {=IF(NOT(ISBLANK($A4)), (_xlfn.XLOOKUP($A4,Index!$B$2:$B$103,Index!$C$2:$C$103,"Not Found")),"")} -> F | D4: {=IF(NOT(ISBLANK(A4)), (_xlfn.XLOOKUP($A4,Index!$B$2:B$103,Index!$A$2:$A$103,"Not Found")),"")} -> base1-52 | E4: {=IF(NOT(ISBLANK($A4)), (_xlfn.XLOOKUP($A4,Index!$B$2:$B$103,Index!$D$2:$D$103,"Not Found")),"")} -> b | F4: {=IF(NOT(ISBLANK($A4)), (_xlfn.XLOOKUP($A4,Index!$B$2:$B$103,Index!$E$2:$E$103,"Not Found")),"")} -> y | G4: {=IF(NOT(ISBLANK(A4)), ((_xlfn.XLOOKUP(A4,Index!$B$2:$B$103,Index!$F$2:$F$103,"Not Found"))*B4),"")} -> 0 | K4: C | L4: =IF(NOT(ISBLANK(K4)), SUM(M4:P4), "") -> 3 | M4: =IF(NOT(ISBLANK($K4)), SUMIFS($B$2:$B$32, $E$2:$E$32, "B", $C$2:$C$32,$K4), "") -> 2 | N4: =IF(NOT(ISBLANK($K4)),SUMIFS($B$2:$B$32,$E$2:$E$32, "1", $C$2:$C$32,$K4,$F$2:$F$32,"N"), "") -> 1 | O4: =IF(NOT(ISBLANK($K4)),SUMIFS($B$2:$B$32,$E$2:$E$32, "1", $C$2:$C$32,$K4,$F$2:$F$32,"Y"), "") -> 0 | P4: =IF(NOT(ISBLANK($K4)),SUMIFS($B$2:$B$32,$E$2:$E$32, "2", $C$2:$C$32,$K4), "") -> 0 | Q4: =IF(NOT(ISBLANK($K4)),SUMIFS($B$2:$B$32,$E$2:$E$32, "B", $C$2:$C$32,$K4,$F$2:$F$32,"N"), "") -> 0
A5: Machoke | B5: 2 | C5: {=IF(NOT(ISBLANK($A5)), (_xlfn.XLOOKUP($A5,Index!$B$2:$B$103,Index!$C$2:$C$103,"Not Found")),"")} -> F | D5: {=IF(NOT(ISBLANK(A5)), (_xlfn.XLOOKUP($A5,Index!$B$2:B$103,Index!$A$2:$A$103,"Not Found")),"")} -> base1-34 | E5: {=IF(NOT(ISBLANK($A5)), (_xlfn.XLOOKUP($A5,Index!$B$2:$B$103,Index!$D$2:$D$103,"Not Found")),"")} -> 1 | F5: {=IF(NOT(ISBLANK($A5)), (_xlfn.XLOOKUP($A5,Index!$B$2:$B$103,Index!$E$2:$E$103,"Not Found")),"")} -> y | G5: {=IF(NOT(ISBLANK(A5)), ((_xlfn.XLOOKUP(A5,Index!$B$2:$B$103,Index!$F$2:$F$103,"Not Found"))*B5),"")} -> 0 | L5: =IF(NOT(ISBLANK(K5)), SUM(M5:P5), "") | M5: =IF(NOT(ISBLANK($K5)), SUMIFS($B$2:$B$32, $E$2:$E$32, "B", $C$2:$C$32,$K5), "") | N5: =IF(NOT(ISBLANK($K5)),SUMIFS($B$2:$B$32,$E$2:$E$32, "1", $C$2:$C$32,$K5,$F$2:$F$32,"N"), "") | O5: =IF(NOT(ISBLANK($K5)),SUMIFS($B$2:$B$32,$E$2:$E$32, "1", $C$2:$C$32,$K5,$F$2:$F$32,"Y"), "") | P5: =IF(NOT(ISBLANK($K5)),SUMIFS($B$2:$B$32,$E$2:$E$32, "2", $C$2:$C$32,$K5), "") | Q5: =IF(NOT(ISBLANK($K5)),SUMIFS($B$2:$B$32,$E$2:$E$32, "B", $C$2:$C$32,$K5,$F$2:$F$32,"N"), "")
A6: Hitmonchan | B6: 2 | C6: {=IF(NOT(ISBLANK($A6)), (_xlfn.XLOOKUP($A6,Index!$B$2:$B$103,Index!$C$2:$C$103,"Not Found")),"")} -> F | D6: {=IF(NOT(ISBLANK(A6)), (_xlfn.XLOOKUP($A6,Index!$B$2:B$103,Index!$A$2:$A$103,"Not Found")),"")} -> base1-7 | E6: {=IF(NOT(ISBLANK($A6)), (_xlfn.XLOOKUP($A6,Index!$B$2:$B$103,Index!$D$2:$D$103,"Not Found")),"")} -> b | F6: {=IF(NOT(ISBLANK($A6)), (_xlfn.XLOOKUP($A6,Index!$B$2:$B$103,Index!$E$2:$E$103,"Not Found")),"")} -> n | G6: {=IF(NOT(ISBLANK(A6)), ((_xlfn.XLOOKUP(A6,Index!$B$2:$B$103,Index!$F$2:$F$103,"Not Found"))*B6),"")} -> 2 | L6: =IF(NOT(ISBLANK(K6)), SUM(M6:P6), "") | M6: =IF(NOT(ISBLANK($K6)), COUNTIFS($E$2:$E$32, "B", $C$2:$C$32,$K6), "") | N6: =IF(NOT(ISBLANK(K6)),COUNTIFS($E$2:$E$32, "1", $C$2:$C$32,$K6,$F$2:$F$32,"N"), "") | O6: =IF(NOT(ISBLANK($K6)),COUNTIFS($E$2:$E$32, "1", $C$2:$C$32,$K6,$F$2:$F$32,"Y"), "") | P6: =IF(NOT(ISBLANK($K6)),COUNTIFS($E$2:$E$32, "2", $C$2:$C$32,$K6), "") | Q6: =IF(NOT(ISBLANK($K6)),COUNTIFS($E$2:$E$32, "B", $C$2:$C$32,$K6,$F$2:$F$32,"N"), "")
A7: Diglett | B7: 2 | C7: {=IF(NOT(ISBLANK($A7)), (_xlfn.XLOOKUP($A7,Index!$B$2:$B$103,Index!$C$2:$C$103,"Not Found")),"")} -> F | D7: {=IF(NOT(ISBLANK(A7)), (_xlfn.XLOOKUP($A7,Index!$B$2:B$103,Index!$A$2:$A$103,"Not Found")),"")} -> base1-47 | E7: {=IF(NOT(ISBLANK($A7)), (_xlfn.XLOOKUP($A7,Index!$B$2:$B$103,Index!$D$2:$D$103,"Not Found")),"")} -> b | F7: {=IF(NOT(ISBLANK($A7)), (_xlfn.XLOOKUP($A7,Index!$B$2:$B$103,Index!$E$2:$E$103,"Not Found")),"")} -> y | G7: {=IF(NOT(ISBLANK(A7)), ((_xlfn.XLOOKUP(A7,Index!$B$2:$B$103,Index!$F$2:$F$103,"Not Found"))*B7),"")} -> 0 | K7: Total | L7: =SUM(L2:L6) -> 22 | M7: =SUM(M2:M6) -> 15 | N7: =SUM(N2:N6) -> 4 | O7: =SUM(O2:O6) -> 3 | P7: =SUM(P2:P6) -> 0 | Q7: =SUM(Q2:Q6) -> 2
A8: Dugtrio | B8: 1 | C8: {=IF(NOT(ISBLANK($A8)), (_xlfn.XLOOKUP($A8,Index!$B$2:$B$103,Index!$C$2:$C$103,"Not Found")),"")} -> F | D8: {=IF(NOT(ISBLANK(A8)), (_xlfn.XLOOKUP($A8,Index!$B$2:B$103,Index!$A$2:$A$103,"Not Found")),"")} -> base1-19 | E8: {=IF(NOT(ISBLANK($A8)), (_xlfn.XLOOKUP($A8,Index!$B$2:$B$103,Index!$D$2:$D$103,"Not Found")),"")} -> 1 | F8: {=IF(NOT(ISBLANK($A8)), (_xlfn.XLOOKUP($A8,Index!$B$2:$B$103,Index!$E$2:$E$103,"Not Found")),"")} -> n | G8: {=IF(NOT(ISBLANK(A8)), ((_xlfn.XLOOKUP(A8,Index!$B$2:$B$103,Index!$F$2:$F$103,"Not Found"))*B8),"")} -> 2
A9: Staryu | B9: 3 | C9: {=IF(NOT(ISBLANK($A9)), (_xlfn.XLOOKUP($A9,Index!$B$2:$B$103,Index!$C$2:$C$103,"Not Found")),"")} -> W | D9: {=IF(NOT(ISBLANK(A9)), (_xlfn.XLOOKUP($A9,Index!$B$2:B$103,Index!$A$2:$A$103,"Not Found")),"")} -> base1-65 | E9: {=IF(NOT(ISBLANK($A9)), (_xlfn.XLOOKUP($A9,Index!$B$2:$B$103,Index!$D$2:$D$103,"Not Found")),"")} -> b | F9: {=IF(NOT(ISBLANK($A9)), (_xlfn.XLOOKUP($A9,Index!$B$2:$B$103,Index!$E$2:$E$103,"Not Found")),"")} -> y | G9: {=IF(NOT(ISBLANK(A9)), ((_xlfn.XLOOKUP(A9,Index!$B$2:$B$103,Index!$F$2:$F$103,"Not Found"))*B9),"")} -> 0 | M9: Common | N9: Uncommon | O9: Rare
A10: Starmie | B10: 2 | C10: {=IF(NOT(ISBLANK($A10)), (_xlfn.XLOOKUP($A10,Index!$B$2:$B$103,Index!$C$2:$C$103,"Not Found")),"")} -> W | D10: {=IF(NOT(ISBLANK(A10)), (_xlfn.XLOOKUP($A10,Index!$B$2:B$103,Index!$A$2:$A$103,"Not Found")),"")} -> base1-64 | E10: {=IF(NOT(ISBLANK($A10)), (_xlfn.XLOOKUP($A10,Index!$B$2:$B$103,Index!$D$2:$D$103,"Not Found")),"")} -> 1 | F10: {=IF(NOT(ISBLANK($A10)), (_xlfn.XLOOKUP($A10,Index!$B$2:$B$103,Index!$E$2:$E$103,"Not Found")),"")} -> n | G10: {=IF(NOT(ISBLANK(A10)), ((_xlfn.XLOOKUP(A10,Index!$B$2:$B$103,Index!$F$2:$F$103,"Not Found"))*B10),"")} -> 3 | K10: Trainer | L10: =SUM(M10:P10) -> 10 | M10: =IF(NOT(ISBLANK($K10)), SUMIFS($B$2:$B$32,$E$2:$E$32, "C", $C$2:$C$32,"T"), "") -> 6 | N10: =IF(NOT(ISBLANK($K10)), SUMIFS($B$2:$B$32,$E$2:$E$32, "U", $C$2:$C$32,"T"), "") -> 3 | O10: =IF(NOT(ISBLANK($K$2)), SUMIFS($B$2:$B$32,$E$2:$E$32, "R", $C$2:$C$32,"T"), "") -> 1
A11: Raticate | B11: 1 | C11: {=IF(NOT(ISBLANK($A11)), (_xlfn.XLOOKUP($A11,Index!$B$2:$B$103,Index!$C$2:$C$103,"Not Found")),"")} -> C | D11: {=IF(NOT(ISBLANK(A11)), (_xlfn.XLOOKUP($A11,Index!$B$2:B$103,Index!$A$2:$A$103,"Not Found")),"")} -> base1-40 | E11: {=IF(NOT(ISBLANK($A11)), (_xlfn.XLOOKUP($A11,Index!$B$2:$B$103,Index!$D$2:$D$103,"Not Found")),"")} -> 1 | F11: {=IF(NOT(ISBLANK($A11)), (_xlfn.XLOOKUP($A11,Index!$B$2:$B$103,Index!$E$2:$E$103,"Not Found")),"")} -> n | G11: {=IF(NOT(ISBLANK(A11)), ((_xlfn.XLOOKUP(A11,Index!$B$2:$B$103,Index!$F$2:$F$103,"Not Found"))*B11),"")} -> 0 | K11: Energy | L11: =IF(NOT(ISBLANK($K$2)), SUMIFS($B$2:$B$32, $C$2:$C$32,"Energy"), "") -> 28
A12: Squirtle | B12: 2 | C12: {=IF(NOT(ISBLANK($A12)), (_xlfn.XLOOKUP($A12,Index!$B$2:$B$103,Index!$C$2:$C$103,"Not Found")),"")} -> W | D12: {=IF(NOT(ISBLANK(A12)), (_xlfn.XLOOKUP($A12,Index!$B$2:B$103,Index!$A$2:$A$103,"Not Found")),"")} -> base1-63 | E12: {=IF(NOT(ISBLANK($A12)), (_xlfn.XLOOKUP($A12,Index!$B$2:$B$103,Index!$D$2:$D$103,"Not Found")),"")} -> b | F12: {=IF(NOT(ISBLANK($A12)), (_xlfn.XLOOKUP($A12,Index!$B$2:$B$103,Index!$E$2:$E$103,"Not Found")),"")} -> y | G12: {=IF(NOT(ISBLANK(A12)), ((_xlfn.XLOOKUP(A12,Index!$B$2:$B$103,Index!$F$2:$F$103,"Not Found"))*B12),"")} -> 0 | K12: Pokemon | L12: =L7 -> 22
A13: Wartortle | B13: 1 | C13: {=IF(NOT(ISBLANK($A13)), (_xlfn.XLOOKUP($A13,Index!$B$2:$B$103,Index!$C$2:$C$103,"Not Found")),"")} -> W | D13: {=IF(NOT(ISBLANK(A13)), (_xlfn.XLOOKUP($A13,Index!$B$2:B$103,Index!$A$2:$A$103,"Not Found")),"")} -> base1-42 | E13: {=IF(NOT(ISBLANK($A13)), (_xlfn.XLOOKUP($A13,Index!$B$2:$B$103,Index!$D$2:$D$103,"Not Found")),"")} -> 1 | F13: {=IF(NOT(ISBLANK($A13)), (_xlfn.XLOOKUP($A13,Index!$B$2:$B$103,Index!$E$2:$E$103,"Not Found")),"")} -> y | G13: {=IF(NOT(ISBLANK(A13)), ((_xlfn.XLOOKUP(A13,Index!$B$2:$B$103,Index!$F$2:$F$103,"Not Found"))*B13),"")} -> 0
A14: Fighting Energy | B14: 16 | C14: {=IF(NOT(ISBLANK($A14)), (_xlfn.XLOOKUP($A14,Index!$B$2:$B$103,Index!$C$2:$C$103,"Not Found")),"")} -> Energy | D14: {=IF(NOT(ISBLANK(A14)), (_xlfn.XLOOKUP($A14,Index!$B$2:B$103,Index!$A$2:$A$103,"Not Found")),"")} -> base1-97 | E14: {=IF(NOT(ISBLANK($A14)), (_xlfn.XLOOKUP($A14,Index!$B$2:$B$103,Index!$D$2:$D$103,"Not Found")),"")} | F14: {=IF(NOT(ISBLANK($A14)), (_xlfn.XLOOKUP($A14,Index!$B$2:$B$103,Index!$E$2:$E$103,"Not Found")),"")} | G14: {=IF(NOT(ISBLANK(A14)), ((_xlfn.XLOOKUP(A14,Index!$B$2:$B$103,Index!$F$2:$F$103,"Not Found"))*B14),"")} -> 0
A15: Water Energy | B15: 12 | C15: {=IF(NOT(ISBLANK($A15)), (_xlfn.XLOOKUP($A15,Index!$B$2:$B$103,Index!$C$2:$C$103,"Not Found")),"")} -> Energy | D15: {=IF(NOT(ISBLANK(A15)), (_xlfn.XLOOKUP($A15,Index!$B$2:B$103,Index!$A$2:$A$103,"Not Found")),"")} -> base1-102 | E15: {=IF(NOT(ISBLANK($A15)), (_xlfn.XLOOKUP($A15,Index!$B$2:$B$103,Index!$D$2:$D$103,"Not Found")),"")} | F15: {=IF(NOT(ISBLANK($A15)), (_xlfn.XLOOKUP($A15,Index!$B$2:$B$103,Index!$E$2:$E$103,"Not Found")),"")} | G15: {=IF(NOT(ISBLANK(A15)), ((_xlfn.XLOOKUP(A15,Index!$B$2:$B$103,Index!$F$2:$F$103,"Not Found"))*B15),"")} -> 0 | K15: Feature Weight:
A16: Computer Search | B16: 1 | C16: {=IF(NOT(ISBLANK($A16)), (_xlfn.XLOOKUP($A16,Index!$B$2:$B$103,Index!$C$2:$C$103,"Not Found")),"")} -> T | D16: {=IF(NOT(ISBLANK(A16)), (_xlfn.XLOOKUP($A16,Index!$B$2:B$103,Index!$A$2:$A$103,"Not Found")),"")} -> base1-71 | E16: {=IF(NOT(ISBLANK($A16)), (_xlfn.XLOOKUP($A16,Index!$B$2:$B$103,Index!$D$2:$D$103,"Not Found")),"")} -> r | F16: {=IF(NOT(ISBLANK($A16)), (_xlfn.XLOOKUP($A16,Index!$B$2:$B$103,Index!$E$2:$E$103,"Not Found")),"")} | G16: {=IF(NOT(ISBLANK(A16)), ((_xlfn.XLOOKUP(A16,Index!$B$2:$B$103,Index!$F$2:$F$103,"Not Found"))*B16),"")} -> 0 | K16: =K2 -> F | L16: =IF(NOT(ISBLANK($K2)), SUMIFS($G$2:$G$32, $C$2:$C$32,$K2), "") -> 4
A17: Professor Oak | B17: 1 | C17: {=IF(NOT(ISBLANK($A17)), (_xlfn.XLOOKUP($A17,Index!$B$2:$B$103,Index!$C$2:$C$103,"Not Found")),"")} -> T | D17: {=IF(NOT(ISBLANK(A17)), (_xlfn.XLOOKUP($A17,Index!$B$2:B$103,Index!$A$2:$A$103,"Not Found")),"")} -> base1-88 | E17: {=IF(NOT(ISBLANK($A17)), (_xlfn.XLOOKUP($A17,Index!$B$2:$B$103,Index!$D$2:$D$103,"Not Found")),"")} -> u | F17: {=IF(NOT(ISBLANK($A17)), (_xlfn.XLOOKUP($A17,Index!$B$2:$B$103,Index!$E$2:$E$103,"Not Found")),"")} | G17: {=IF(NOT(ISBLANK(A17)), ((_xlfn.XLOOKUP(A17,Index!$B$2:$B$103,Index!$F$2:$F$103,"Not Found"))*B17),"")} -> 0 | K17: =K3 -> W | L17: =IF(NOT(ISBLANK($K3)), SUMIFS($G$2:$G$32, $C$2:$C$32,$K3), "") -> 3
A18: Energy Retrieval | B18: 1 | C18: {=IF(NOT(ISBLANK($A18)), (_xlfn.XLOOKUP($A18,Index!$B$2:$B$103,Index!$C$2:$C$103,"Not Found")),"")} -> T | D18: {=IF(NOT(ISBLANK(A18)), (_xlfn.XLOOKUP($A18,Index!$B$2:B$103,Index!$A$2:$A$103,"Not Found")),"")} -> base1-81 | E18: {=IF(NOT(ISBLANK($A18)), (_xlfn.XLOOKUP($A18,Index!$B$2:$B$103,Index!$D$2:$D$103,"Not Found")),"")} -> u | F18: {=IF(NOT(ISBLANK($A18)), (_xlfn.XLOOKUP($A18,Index!$B$2:$B$103,Index!$E$2:$E$103,"Not Found")),"")} | G18: {=IF(NOT(ISBLANK(A18)), ((_xlfn.XLOOKUP(A18,Index!$B$2:$B$103,Index!$F$2:$F$103,"Not Found"))*B18),"")} -> 0 | K18: =K4 -> C | L18: =IF(NOT(ISBLANK($K4)), SUMIFS($G$2:$G$32, $C$2:$C$32,$K4), "") -> 0
A19: Bill | B19: 2 | C19: {=IF(NOT(ISBLANK($A19)), (_xlfn.XLOOKUP($A19,Index!$B$2:$B$103,Index!$C$2:$C$103,"Not Found")),"")} -> T | D19: {=IF(NOT(ISBLANK(A19)), (_xlfn.XLOOKUP($A19,Index!$B$2:B$103,Index!$A$2:$A$103,"Not Found")),"")} -> base1-91 | E19: {=IF(NOT(ISBLANK($A19)), (_xlfn.XLOOKUP($A19,Index!$B$2:$B$103,Index!$D$2:$D$103,"Not Found")),"")} -> c | F19: {=IF(NOT(ISBLANK($A19)), (_xlfn.XLOOKUP($A19,Index!$B$2:$B$103,Index!$E$2:$E$103,"Not Found")),"")} | G19: {=IF(NOT(ISBLANK(A19)), ((_xlfn.XLOOKUP(A19,Index!$B$2:$B$103,Index!$F$2:$F$103,"Not Found"))*B19),"")} -> 0 | K19: =K5 | L19: =IF(NOT(ISBLANK($K5)), SUMIFS($G$2:$G$32, $C$2:$C$32,$K5), "")
A20: Potion | B20: 2 | C20: {=IF(NOT(ISBLANK($A20)), (_xlfn.XLOOKUP($A20,Index!$B$2:$B$103,Index!$C$2:$C$103,"Not Found")),"")} -> T | D20: {=IF(NOT(ISBLANK(A20)), (_xlfn.XLOOKUP($A20,Index!$B$2:B$103,Index!$A$2:$A$103,"Not Found")),"")} -> base1-94 | E20: {=IF(NOT(ISBLANK($A20)), (_xlfn.XLOOKUP($A20,Index!$B$2:$B$103,Index!$D$2:$D$103,"Not Found")),"")} -> c | F20: {=IF(NOT(ISBLANK($A20)), (_xlfn.XLOOKUP($A20,Index!$B$2:$B$103,Index!$E$2:$E$103,"Not Found")),"")} | G20: {=IF(NOT(ISBLANK(A20)), ((_xlfn.XLOOKUP(A20,Index!$B$2:$B$103,Index!$F$2:$F$103,"Not Found"))*B20),"")} -> 0 | K20: =K6
A21: Switch | B21: 1 | C21: {=IF(NOT(ISBLANK($A21)), (_xlfn.XLOOKUP($A21,Index!$B$2:$B$103,Index!$C$2:$C$103,"Not Found")),"")} -> T | D21: {=IF(NOT(ISBLANK(A21)), (_xlfn.XLOOKUP($A21,Index!$B$2:B$103,Index!$A$2:$A$103,"Not Found")),"")} -> base1-95 | E21: {=IF(NOT(ISBLANK($A21)), (_xlfn.XLOOKUP($A21,Index!$B$2:$B$103,Index!$D$2:$D$103,"Not Found")),"")} -> c | F21: {=IF(NOT(ISBLANK($A21)), (_xlfn.XLOOKUP($A21,Index!$B$2:$B$103,Index!$E$2:$E$103,"Not Found")),"")} | G21: {=IF(NOT(ISBLANK(A21)), ((_xlfn.XLOOKUP(A21,Index!$B$2:$B$103,Index!$F$2:$F$103,"Not Found"))*B21),"")} -> 0 | K21: Total: | L21: =SUM(G2:G46) -> 7
A22: Gust of Wind | B22: 1 | C22: {=IF(NOT(ISBLANK($A22)), (_xlfn.XLOOKUP($A22,Index!$B$2:$B$103,Index!$C$2:$C$103,"Not Found")),"")} -> T | D22: {=IF(NOT(ISBLANK(A22)), (_xlfn.XLOOKUP($A22,Index!$B$2:B$103,Index!$A$2:$A$103,"Not Found")),"")} -> base1-93 | E22: {=IF(NOT(ISBLANK($A22)), (_xlfn.XLOOKUP($A22,Index!$B$2:$B$103,Index!$D$2:$D$103,"Not Found")),"")} -> c | F22: {=IF(NOT(ISBLANK($A22)), (_xlfn.XLOOKUP($A22,Index!$B$2:$B$103,Index!$E$2:$E$103,"Not Found")),"")} | G22: {=IF(NOT(ISBLANK(A22)), ((_xlfn.XLOOKUP(A22,Index!$B$2:$B$103,Index!$F$2:$F$103,"Not Found"))*B22),"")} -> 0
A23: Maintenance | B23: 1 | C23: {=IF(NOT(ISBLANK($A23)), (_xlfn.XLOOKUP($A23,Index!$B$2:$B$103,Index!$C$2:$C$103,"Not Found")),"")} -> T | D23: {=IF(NOT(ISBLANK(A23)), (_xlfn.XLOOKUP($A23,Index!$B$2:B$103,Index!$A$2:$A$103,"Not Found")),"")} -> base1-83 | E23: {=IF(NOT(ISBLANK($A23)), (_xlfn.XLOOKUP($A23,Index!$B$2:$B$103,Index!$D$2:$D$103,"Not Found")),"")} -> u | F23: {=IF(NOT(ISBLANK($A23)), (_xlfn.XLOOKUP($A23,Index!$B$2:$B$103,Index!$E$2:$E$103,"Not Found")),"")} | G23: {=IF(NOT(ISBLANK(A23)), ((_xlfn.XLOOKUP(A23,Index!$B$2:$B$103,Index!$F$2:$F$103,"Not Found"))*B23),"")} -> 0
C24: {=IF(NOT(ISBLANK($A24)), (_xlfn.XLOOKUP($A24,Index!$B$2:$B$103,Index!$C$2:$C$103,"Not Found")),"")} | D24: {=IF(NOT(ISBLANK(A24)), (_xlfn.XLOOKUP($A24,Index!$B$2:B$103,Index!$A$2:$A$103,"Not Found")),"")} | E24: {=IF(NOT(ISBLANK($A24)), (_xlfn.XLOOKUP($A24,Index!$B$2:$B$103,Index!$D$2:$D$103,"Not Found")),"")} | F24: {=IF(NOT(ISBLANK($A24)), (_xlfn.XLOOKUP($A24,Index!$B$2:$B$103,Index!$E$2:$E$103,"Not Found")),"")} | G24: {=IF(NOT(ISBLANK(A24)), ((_xlfn.XLOOKUP(A24,Index!$B$2:$B$103,Index!$F$2:$F$103,"Not Found"))*B24),"")}
C25: {=IF(NOT(ISBLANK($A25)), (_xlfn.XLOOKUP($A25,Index!$B$2:$B$103,Index!$C$2:$C$103,"Not Found")),"")} | D25: {=IF(NOT(ISBLANK(A25)), (_xlfn.XLOOKUP($A25,Index!$B$2:B$103,Index!$A$2:$A$103,"Not Found")),"")} | E25: {=IF(NOT(ISBLANK($A25)), (_xlfn.XLOOKUP($A25,Index!$B$2:$B$103,Index!$D$2:$D$103,"Not Found")),"")} | F25: {=IF(NOT(ISBLANK($A25)), (_xlfn.XLOOKUP($A25,Index!$B$2:$B$103,Index!$E$2:$E$103,"Not Found")),"")} | G25: {=IF(NOT(ISBLANK(A25)), ((_xlfn.XLOOKUP(A25,Index!$B$2:$B$103,Index!$F$2:$F$103,"Not Found"))*B25),"")}
C26: {=IF(NOT(ISBLANK($A26)), (_xlfn.XLOOKUP($A26,Index!$B$2:$B$103,Index!$C$2:$C$103,"Not Found")),"")} | D26: {=IF(NOT(ISBLANK(A26)), (_xlfn.XLOOKUP($A26,Index!$B$2:B$103,Index!$A$2:$A$103,"Not Found")),"")} | E26: {=IF(NOT(ISBLANK($A26)), (_xlfn.XLOOKUP($A26,Index!$B$2:$B$103,Index!$D$2:$D$103,"Not Found")),"")} | F26: {=IF(NOT(ISBLANK($A26)), (_xlfn.XLOOKUP($A26,Index!$B$2:$B$103,Index!$E$2:$E$103,"Not Found")),"")} | G26: {=IF(NOT(ISBLANK(A26)), ((_xlfn.XLOOKUP(A26,Index!$B$2:$B$103,Index!$F$2:$F$103,"Not Found"))*B26),"")}
C27: {=IF(NOT(ISBLANK($A27)), (_xlfn.XLOOKUP($A27,Index!$B$2:$B$103,Index!$C$2:$C$103,"Not Found")),"")} | D27: {=IF(NOT(ISBLANK(A27)), (_xlfn.XLOOKUP($A27,Index!$B$2:B$103,Index!$A$2:$A$103,"Not Found")),"")} | E27: {=IF(NOT(ISBLANK($A27)), (_xlfn.XLOOKUP($A27,Index!$B$2:$B$103,Index!$D$2:$D$103,"Not Found")),"")} | F27: {=IF(NOT(ISBLANK($A27)), (_xlfn.XLOOKUP($A27,Index!$B$2:$B$103,Index!$E$2:$E$103,"Not Found")),"")} | G27: {=IF(NOT(ISBLANK(A27)), ((_xlfn.XLOOKUP(A27,Index!$B$2:$B$103,Index!$F$2:$F$103,"Not Found"))*B27),"")}
C28: {=IF(NOT(ISBLANK($A28)), (_xlfn.XLOOKUP($A28,Index!$B$2:$B$103,Index!$C$2:$C$103,"Not Found")),"")} | D28: {=IF(NOT(ISBLANK(A28)), (_xlfn.XLOOKUP($A28,Index!$B$2:B$103,Index!$A$2:$A$103,"Not Found")),"")} | E28: {=IF(NOT(ISBLANK($A28)), (_xlfn.XLOOKUP($A28,Index!$B$2:$B$103,Index!$D$2:$D$103,"Not Found")),"")} | F28: {=IF(NOT(ISBLANK($A28)), (_xlfn.XLOOKUP($A28,Index!$B$2:$B$103,Index!$E$2:$E$103,"Not Found")),"")} | G28: {=IF(NOT(ISBLANK(A28)), ((_xlfn.XLOOKUP(A28,Index!$B$2:$B$103,Index!$F$2:$F$103,"Not Found"))*B28),"")}
C29: {=IF(NOT(ISBLANK($A29)), (_xlfn.XLOOKUP($A29,Index!$B$2:$B$103,Index!$C$2:$C$103,"Not Found")),"")} | D29: {=IF(NOT(ISBLANK(A29)), (_xlfn.XLOOKUP($A29,Index!$B$2:B$103,Index!$A$2:$A$103,"Not Found")),"")} | E29: {=IF(NOT(ISBLANK($A29)), (_xlfn.XLOOKUP($A29,Index!$B$2:$B$103,Index!$D$2:$D$103,"Not Found")),"")} | F29: {=IF(NOT(ISBLANK($A29)), (_xlfn.XLOOKUP($A29,Index!$B$2:$B$103,Index!$E$2:$E$103,"Not Found")),"")} | G29: {=IF(NOT(ISBLANK(A29)), ((_xlfn.XLOOKUP(A29,Index!$B$2:$B$103,Index!$F$2:$F$103,"Not Found"))*B29),"")}
C30: {=IF(NOT(ISBLANK($A30)), (_xlfn.XLOOKUP($A30,Index!$B$2:$B$103,Index!$C$2:$C$103,"Not Found")),"")} | D30: {=IF(NOT(ISBLANK(A30)), (_xlfn.XLOOKUP($A30,Index!$B$2:B$103,Index!$A$2:$A$103,"Not Found")),"")} | E30: {=IF(NOT(ISBLANK($A30)), (_xlfn.XLOOKUP($A30,Index!$B$2:$B$103,Index!$D$2:$D$103,"Not Found")),"")} | F30: {=IF(NOT(ISBLANK($A30)), (_xlfn.XLOOKUP($A30,Index!$B$2:$B$103,Index!$E$2:$E$103,"Not Found")),"")} | G30: {=IF(NOT(ISBLANK(A30)), ((_xlfn.XLOOKUP(A30,Index!$B$2:$B$103,Index!$F$2:$F$103,"Not Found"))*B30),"")}
C31: {=IF(NOT(ISBLANK($A31)), (_xlfn.XLOOKUP($A31,Index!$B$2:$B$103,Index!$C$2:$C$103,"Not Found")),"")} | D31: {=IF(NOT(ISBLANK(A31)), (_xlfn.XLOOKUP($A31,Index!$B$2:B$103,Index!$A$2:$A$103,"Not Found")),"")} | E31: {=IF(NOT(ISBLANK($A31)), (_xlfn.XLOOKUP($A31,Index!$B$2:$B$103,Index!$D$2:$D$103,"Not Found")),"")} | F31: {=IF(NOT(ISBLANK($A31)), (_xlfn.XLOOKUP($A31,Index!$B$2:$B$103,Index!$E$2:$E$103,"Not Found")),"")} | G31: {=IF(NOT(ISBLANK(A31)), ((_xlfn.XLOOKUP(A31,Index!$B$2:$B$103,Index!$F$2:$F$103,"Not Found"))*B31),"")}
C32: {=IF(NOT(ISBLANK($A32)), (_xlfn.XLOOKUP($A32,Index!$B$2:$B$103,Index!$C$2:$C$103,"Not Found")),"")} | D32: {=IF(NOT(ISBLANK(A32)), (_xlfn.XLOOKUP($A32,Index!$B$2:B$103,Index!$A$2:$A$103,"Not Found")),"")} | E32: {=IF(NOT(ISBLANK($A32)), (_xlfn.XLOOKUP($A32,Index!$B$2:$B$103,Index!$D$2:$D$103,"Not Found")),"")} | F32: {=IF(NOT(ISBLANK($A32)), (_xlfn.XLOOKUP($A32,Index!$B$2:$B$103,Index!$E$2:$E$103,"Not Found")),"")} | G32: {=IF(NOT(ISBLANK(A32)), ((_xlfn.XLOOKUP(A32,Index!$B$2:$B$103,Index!$F$2:$F$103,"Not Found"))*B32),"")}
C33: {=IF(NOT(ISBLANK($A33)), (_xlfn.XLOOKUP($A33,Index!$B$2:$B$103,Index!$C$2:$C$103,"Not Found")),"")} | D33: {=IF(NOT(ISBLANK(A33)), (_xlfn.XLOOKUP($A33,Index!$B$2:B$103,Index!$A$2:$A$103,"Not Found")),"")} | E33: {=IF(NOT(ISBLANK($A33)), (_xlfn.XLOOKUP($A33,Index!$B$2:$B$103,Index!$D$2:$D$103,"Not Found")),"")} | F33: {=IF(NOT(ISBLANK($A33)), (_xlfn.XLOOKUP($A33,Index!$B$2:$B$103,Index!$E$2:$E$103,"Not Found")),"")} | G33: {=IF(NOT(ISBLANK(A33)), ((_xlfn.XLOOKUP(A33,Index!$B$2:$B$103,Index!$F$2:$F$103,"Not Found"))*B33),"")}
C34: {=IF(NOT(ISBLANK($A34)), (_xlfn.XLOOKUP($A34,Index!$B$2:$B$103,Index!$C$2:$C$103,"Not Found")),"")} | D34: {=IF(NOT(ISBLANK(A34)), (_xlfn.XLOOKUP($A34,Index!$B$2:B$103,Index!$A$2:$A$103,"Not Found")),"")} | E34: {=IF(NOT(ISBLANK($A34)), (_xlfn.XLOOKUP($A34,Index!$B$2:$B$103,Index!$D$2:$D$103,"Not Found")),"")} | F34: {=IF(NOT(ISBLANK($A34)), (_xlfn.XLOOKUP($A34,Index!$B$2:$B$103,Index!$E$2:$E$103,"Not Found")),"")} | G34: {=IF(NOT(ISBLANK(A34)), ((_xlfn.XLOOKUP(A34,Index!$B$2:$B$103,Index!$F$2:$F$103,"Not Found"))*B34),"")}
C35: {=IF(NOT(ISBLANK($A35)), (_xlfn.XLOOKUP($A35,Index!$B$2:$B$103,Index!$C$2:$C$103,"Not Found")),"")} | D35: {=IF(NOT(ISBLANK(A35)), (_xlfn.XLOOKUP($A35,Index!$B$2:B$103,Index!$A$2:$A$103,"Not Found")),"")} | E35: {=IF(NOT(ISBLANK($A35)), (_xlfn.XLOOKUP($A35,Index!$B$2:$B$103,Index!$D$2:$D$103,"Not Found")),"")} | F35: {=IF(NOT(ISBLANK($A35)), (_xlfn.XLOOKUP($A35,Index!$B$2:$B$103,Index!$E$2:$E$103,"Not Found")),"")} | G35: {=IF(NOT(ISBLANK(A35)), ((_xlfn.XLOOKUP(A35,Index!$B$2:$B$103,Index!$F$2:$F$103,"Not Found"))*B35),"")}
C36: {=IF(NOT(ISBLANK($A36)), (_xlfn.XLOOKUP($A36,Index!$B$2:$B$103,Index!$C$2:$C$103,"Not Found")),"")} | D36: {=IF(NOT(ISBLANK(A36)), (_xlfn.XLOOKUP($A36,Index!$B$2:B$103,Index!$A$2:$A$103,"Not Found")),"")} | E36: {=IF(NOT(ISBLANK($A36)), (_xlfn.XLOOKUP($A36,Index!$B$2:$B$103,Index!$D$2:$D$103,"Not Found")),"")} | F36: {=IF(NOT(ISBLANK($A36)), (_xlfn.XLOOKUP($A36,Index!$B$2:$B$103,Index!$E$2:$E$103,"Not Found")),"")} | G36: {=IF(NOT(ISBLANK(A36)), ((_xlfn.XLOOKUP(A36,Index!$B$2:$B$103,Index!$F$2:$F$103,"Not Found"))*B36),"")}
C37: {=IF(NOT(ISBLANK($A37)), (_xlfn.XLOOKUP($A37,Index!$B$2:$B$103,Index!$C$2:$C$103,"Not Found")),"")} | D37: {=IF(NOT(ISBLANK(A37)), (_xlfn.XLOOKUP($A37,Index!$B$2:B$103,Index!$A$2:$A$103,"Not Found")),"")} | E37: {=IF(NOT(ISBLANK($A37)), (_xlfn.XLOOKUP($A37,Index!$B$2:$B$103,Index!$D$2:$D$103,"Not Found")),"")} | F37: {=IF(NOT(ISBLANK($A37)), (_xlfn.XLOOKUP($A37,Index!$B$2:$B$103,Index!$E$2:$E$103,"Not Found")),"")}
D38: {=IF(NOT(ISBLANK(A38)), (_xlfn.XLOOKUP(A38,Index!$B$2:B$103,Index!$A$2:$A$103,"Not Found")),"")} | E38: {=IF(NOT(ISBLANK($A38)), (_xlfn.XLOOKUP($A38,Index!$B$2:$B$103,Index!$D$2:$D$103,"Not Found")),"")}
D39: {=IF(NOT(ISBLANK(A39)), (_xlfn.XLOOKUP(A39,Index!$B$2:B$103,Index!$A$2:$A$103,"Not Found")),"")} | E39: {=IF(NOT(ISBLANK($A39)), (_xlfn.XLOOKUP($A39,Index!$B$2:$B$103,Index!$D$2:$D$103,"Not Found")),"")}
D40: {=IF(NOT(ISBLANK(A40)), (_xlfn.XLOOKUP(A40,Index!B$2:B$103,Index!A$2:A$103,"Not Found")),"")} | E40: {=IF(NOT(ISBLANK($A40)), (_xlfn.XLOOKUP($A40,Index!$B$2:$B$103,Index!$D$2:$D$103,"Not Found")),"")}
...

Sheet B1 T2-2
A1: Card | B1: Quantity | C1: Type | D1: ID | E1: Stage / Rarity | F1: Remaining Evo | G1: Feature Weight | I1: Card Total | K1: Type | L1: Num | M1: Basic | N1: S1 Max | O1: S1 Mid | P1: S2 | Q1: No Evolve
A2: Abra | B2: 3 | C2: {=IF(NOT(ISBLANK($A2)), (_xlfn.XLOOKUP($A2,Index!$B$2:$B$103,Index!$C$2:$C$103,"Not Found")),"")} -> P | D2: {=IF(NOT(ISBLANK(A2)), (_xlfn.XLOOKUP($A2,Index!$B$2:B$103,Index!$A$2:$A$103,"Not Found")),"")} -> base1-43 | E2: {=IF(NOT(ISBLANK($A2)), (_xlfn.XLOOKUP($A2,Index!$B$2:$B$103,Index!$D$2:$D$103,"Not Found")),"")} -> b | F2: {=IF(NOT(ISBLANK($A2)), (_xlfn.XLOOKUP($A2,Index!$B$2:$B$103,Index!$E$2:$E$103,"Not Found")),"")} -> y | G2: {=IF(NOT(ISBLANK(A2)), ((_xlfn.XLOOKUP(A2,Index!$B$2:$B$103,Index!$F$2:$F$103,"Not Found"))*B2),"")} -> 0 | I2: =SUM(B2:B38) -> 60 | K2: P | L2: =IF(NOT(ISBLANK(K2)), SUM(M2:P2), "") -> 12 | M2: =IF(NOT(ISBLANK($K2)), SUMIFS($B$2:$B$32, $E$2:$E$32, "B", $C$2:$C$32,$K2), "") -> 8 | N2: =IF(NOT(ISBLANK($K2)),SUMIFS($B$2:$B$32,$E$2:$E$32, "1", $C$2:$C$32,$K2,$F$2:$F$32,"N"), "") -> 0 | O2: =IF(NOT(ISBLANK($K2)),SUMIFS($B$2:$B$32,$E$2:$E$32, "1", $C$2:$C$32,$K2,$F$2:$F$32,"Y"), "") -> 3 | P2: =IF(NOT(ISBLANK($K2)),SUMIFS($B$2:$B$32,$E$2:$E$32, "2", $C$2:$C$32,$K2), "") -> 1 | Q2: =IF(NOT(ISBLANK($K2)),SUMIFS($B$2:$B$32,$E$2:$E$32, "B", $C$2:$C$32,$K2,$F$2:$F$32,"N"), "") -> 3
A3: Kadabra | B3: 2 | C3: {=IF(NOT(ISBLANK($A3)), (_xlfn.XLOOKUP($A3,Index!$B$2:$B$103,Index!$C$2:$C$103,"Not Found")),"")} -> P | D3: {=IF(NOT(ISBLANK(A3)), (_xlfn.XLOOKUP($A3,Index!$B$2:B$103,Index!$A$2:$A$103,"Not Found")),"")} -> base1-32 | E3: {=IF(NOT(ISBLANK($A3)), (_xlfn.XLOOKUP($A3,Index!$B$2:$B$103,Index!$D$2:$D$103,"Not Found")),"")} -> 1 | F3: {=IF(NOT(ISBLANK($A3)), (_xlfn.XLOOKUP($A3,Index!$B$2:$B$103,Index!$E$2:$E$103,"Not Found")),"")} -> y | G3: {=IF(NOT(ISBLANK(A3)), ((_xlfn.XLOOKUP(A3,Index!$B$2:$B$103,Index!$F$2:$F$103,"Not Found"))*B3),"")} -> 0 | K3: R | L3: =IF(NOT(ISBLANK(K3)), SUM(M3:P3), "") -> 6 | M3: =IF(NOT(ISBLANK($K3)), SUMIFS($B$2:$B$32, $E$2:$E$32, "B", $C$2:$C$32,$K3), "") -> 5 | N3: =IF(NOT(ISBLANK($K3)),SUMIFS($B$2:$B$32,$E$2:$E$32, "1", $C$2:$C$32,$K3,$F$2:$F$32,"N"), "") -> 1 | O3: =IF(NOT(ISBLANK($K3)),SUMIFS($B$2:$B$32,$E$2:$E$32, "1", $C$2:$C$32,$K3,$F$2:$F$32,"Y"), "") -> 0 | P3: =IF(NOT(ISBLANK($K3)),SUMIFS($B$2:$B$32,$E$2:$E$32, "2", $C$2:$C$32,$K3), "") -> 0 | Q3: =IF(NOT(ISBLANK($K3)),SUMIFS($B$2:$B$32,$E$2:$E$32, "B", $C$2:$C$32,$K3,$F$2:$F$32,"N"), "") -> 2
A4: Alakazam | B4: 1 | C4: {=IF(NOT(ISBLANK($A4)), (_xlfn.XLOOKUP($A4,Index!$B$2:$B$103,Index!$C$2:$C$103,"Not Found")),"")} -> P | D4: {=IF(NOT(ISBLANK(A4)), (_xlfn.XLOOKUP($A4,Index!$B$2:B$103,Index!$A$2:$A$103,"Not Found")),"")} -> base1-1 | E4: {=IF(NOT(ISBLANK($A4)), (_xlfn.XLOOKUP($A4,Index!$B$2:$B$103,Index!$D$2:$D$103,"Not Found")),"")} -> 2 | F4: {=IF(NOT(ISBLANK($A4)), (_xlfn.XLOOKUP($A4,Index!$B$2:$B$103,Index!$E$2:$E$103,"Not Found")),"")} | G4: {=IF(NOT(ISBLANK(A4)), ((_xlfn.XLOOKUP(A4,Index!$B$2:$B$103,Index!$F$2:$F$103,"Not Found"))*B4),"")} -> 2.5 | K4: C | L4: =IF(NOT(ISBLANK(K4)), SUM(M4:P4), "") -> 3 | M4: =IF(NOT(ISBLANK($K4)), SUMIFS($B$2:$B$32, $E$2:$E$32, "B", $C$2:$C$32,$K4), "") -> 3 | N4: =IF(NOT(ISBLANK($K4)),SUMIFS($B$2:$B$32,$E$2:$E$32, "1", $C$2:$C$32,$K4,$F$2:$F$32,"N"), "") -> 0 | O4: =IF(NOT(ISBLANK($K4)),SUMIFS($B$2:$B$32,$E$2:$E$32, "1", $C$2:$C$32,$K4,$F$2:$F$32,"Y"), "") -> 0 | P4: =IF(NOT(ISBLANK($K4)),SUMIFS($B$2:$B$32,$E$2:$E$32, "2", $C$2:$C$32,$K4), "") -> 0 | Q4: =IF(NOT(ISBLANK($K4)),SUMIFS($B$2:$B$32,$E$2:$E$32, "B", $C$2:$C$32,$K4,$F$2:$F$32,"N"), "") -> 3
A5: Gastly | B5: 2 | C5: {=IF(NOT(ISBLANK($A5)), (_xlfn.XLOOKUP($A5,Index!$B$2:$B$103,Index!$C$2:$C$103,"Not Found")),"")} -> P | D5: {=IF(NOT(ISBLANK(A5)), (_xlfn.XLOOKUP($A5,Index!$B$2:B$103,Index!$A$2:$A$103,"Not Found")),"")} -> base1-50 | E5: {=IF(NOT(ISBLANK($A5)), (_xlfn.XLOOKUP($A5,Index!$B$2:$B$103,Index!$D$2:$D$103,"Not Found")),"")} -> b | F5: {=IF(NOT(ISBLANK($A5)), (_xlfn.XLOOKUP($A5,Index!$B$2:$B$103,Index!$E$2:$E$103,"Not Found")),"")} -> y | G5: {=IF(NOT(ISBLANK(A5)), ((_xlfn.XLOOKUP(A5,Index!$B$2:$B$103,Index!$F$2:$F$103,"Not Found"))*B5),"")} -> 0 | L5: =IF(NOT(ISBLANK(K5)), SUM(M5:P5), "") | M5: =IF(NOT(ISBLANK($K5)), SUMIFS($B$2:$B$32, $E$2:$E$32, "B", $C$2:$C$32,$K5), "") | N5: =IF(NOT(ISBLANK($K5)),SUMIFS($B$2:$B$32,$E$2:$E$32, "1", $C$2:$C$32,$K5,$F$2:$F$32,"N"), "") | O5: =IF(NOT(ISBLANK($K5)),SUMIFS($B$2:$B$32,$E$2:$E$32, "1", $C$2:$C$32,$K5,$F$2:$F$32,"Y"), "") | P5: =IF(NOT(ISBLANK($K5)),SUMIFS($B$2:$B$32,$E$2:$E$32, "2", $C$2:$C$32,$K5), "") | Q5: =IF(NOT(ISBLANK($K5)),SUMIFS($B$2:$B$32,$E$2:$E$32, "B", $C$2:$C$32,$K5,$F$2:$F$32,"N"), "")
A6: Haunter | B6: 1 | C6: {=IF(NOT(ISBLANK($A6)), (_xlfn.XLOOKUP($A6,Index!$B$2:$B$103,Index!$C$2:$C$103,"Not Found")),"")} -> P | D6: {=IF(NOT(ISBLANK(A6)), (_xlfn.XLOOKUP($A6,Index!$B$2:B$103,Index!$A$2:$A$103,"Not Found")),"")} -> base1-29 | E6: {=IF(NOT(ISBLANK($A6)), (_xlfn.XLOOKUP($A6,Index!$B$2:$B$103,Index!$D$2:$D$103,"Not Found")),"")} -> 1 | F6: {=IF(NOT(ISBLANK($A6)), (_xlfn.XLOOKUP($A6,Index!$B$2:$B$103,Index!$E$2:$E$103,"Not Found")),"")} -> y | G6: {=IF(NOT(ISBLANK(A6)), ((_xlfn.XLOOKUP(A6,Index!$B$2:$B$103,Index!$F$2:$F$103,"Not Found"))*B6),"")} -> 0 | L6: =IF(NOT(ISBLANK(K6)), SUM(M6:P6), "") | M6: =IF(NOT(ISBLANK($K6)), COUNTIFS($E$2:$E$32, "B", $C$2:$C$32,$K6), "") | N6: =IF(NOT(ISBLANK(K6)),COUNTIFS($E$2:$E$32, "1", $C$2:$C$32,$K6,$F$2:$F$32,"N"), "") | O6: =IF(NOT(ISBLANK($K6)),COUNTIFS($E$2:$E$32, "1", $C$2:$C$32,$K6,$F$2:$F$32,"Y"), "") | P6: =IF(NOT(ISBLANK($K6)),COUNTIFS($E$2:$E$32, "2", $C$2:$C$32,$K6), "") | Q6: =IF(NOT(ISBLANK($K6)),COUNTIFS($E$2:$E$32, "B", $C$2:$C$32,$K6,$F$2:$F$32,"N"), "")
A7: Mewtwo | B7: 1 | C7: {=IF(NOT(ISBLANK($A7)), (_xlfn.XLOOKUP($A7,Index!$B$2:$B$103,Index!$C$2:$C$103,"Not Found")),"")} -> P | D7: {=IF(NOT(ISBLANK(A7)), (_xlfn.XLOOKUP($A7,Index!$B$2:B$103,Index!$A$2:$A$103,"Not Found")),"")} -> base1-10 | E7: {=IF(NOT(ISBLANK($A7)), (_xlfn.XLOOKUP($A7,Index!$B$2:$B$103,Index!$D$2:$D$103,"Not Found")),"")} -> b | F7: {=IF(NOT(ISBLANK($A7)), (_xlfn.XLOOKUP($A7,Index!$B$2:$B$103,Index!$E$2:$E$103,"Not Found")),"")} -> n | G7: {=IF(NOT(ISBLANK(A7)), ((_xlfn.XLOOKUP(A7,Index!$B$2:$B$103,Index!$F$2:$F$103,"Not Found"))*B7),"")} -> 1 | K7: Total | L7: =SUM(L2:L6) -> 21 | M7: =SUM(M2:M6) -> 16 | N7: =SUM(N2:N6) -> 1 | O7: =SUM(O2:O6) -> 3 | P7: =SUM(P2:P6) -> 1 | Q7: =SUM(Q2:Q6) -> 8
A8: Jynx | B8: 2 | C8: {=IF(NOT(ISBLANK($A8)), (_xlfn.XLOOKUP($A8,Index!$B$2:$B$103,Index!$C$2:$C$103,"Not Found")),"")} -> P | D8: {=IF(NOT(ISBLANK(A8)), (_xlfn.XLOOKUP($A8,Index!$B$2:B$103,Index!$A$2:$A$103,"Not Found")),"")} -> base1-31 | E8: {=IF(NOT(ISBLANK($A8)), (_xlfn.XLOOKUP($A8,Index!$B$2:$B$103,Index!$D$2:$D$103,"Not Found")),"")} -> b | F8: {=IF(NOT(ISBLANK($A8)), (_xlfn.XLOOKUP($A8,Index!$B$2:$B$103,Index!$E$2:$E$103,"Not Found")),"")} -> n | G8: {=IF(NOT(ISBLANK(A8)), ((_xlfn.XLOOKUP(A8,Index!$B$2:$B$103,Index!$F$2:$F$103,"Not Found"))*B8),"")} -> 2
