Workbook

Sheet Index
A1: ID | B1: Card | C1: Type | D1: Stage / Rarity (trainer) | E1: Remaining Evo | F1: Deck Feature Tier | G1: Opener Archetype | H1: Pressure | I1: Wants | J1: Possible CPU Deck Block? | K1: Included in opp Deck? | L1: Gated Until (promo only) | N1: Feature Tier Key
A2: base1-3 | B2: Chansey | C2: C | D2: b | E2: n | F2: 1 | G2: t | H2: WP | I2: Power up Scrunch and then tank | K2: TRUE | N2: Not shown | O2: Not worth noting
A3: base2-1 | B3: Clefable | C3: C | D3: 1 | E3: n | F3: 2 | H3: HD | I3: A turn to copy a high damage opp pokemon's move | K3: TRUE | N3: 1 | O3: Strategic Opener / Tank / Other utility
A4: base2-17 | B4: Clefable NH | C4: C | D4: 1 | E4: n | F4: 2 | H4: HD | I4: A turn to copy a high damage opp pokemon's move | K4: TRUE | N4: 2 | O4: Secondary Feature
A5: base1-5 | B5: Clefairy | C5: C | D5: b | E5: y | F5: 0.5 | K5: TRUE | N5: 3 | O5: Primary Feature
A6: basep-15 | B6: Cool Porygon | C6: C | D6: b | E6: n | G6: n | H6: WP | I6: To change its resistance to the defending pokemon's attack type | K6: FALSE | L6: Challenge 1 | N6: 4 | O6: Elite Feature
A7: basep-17 | B7: Dark Persian CH | C7: C | D7: 1 | E7: n | K7: FALSE | L7: Team Rocket
A8: base3-3 | B8: Ditto | C8: C | D8: b | E8: n | F8: 0.5 | I8: A low energy cost, high damage or otherwise pesky opponent to copy | K8: TRUE
A9: base3-18 | B9: Ditto NH | C9: C | D9: b | E9: n | F9: 0.5 | I9: A low energy cost, high damage or otherwise pesky opponent to copy | K9: TRUE | N9: Tier ranking is only for last of evolution line and select useful others. Partially based in subjectivity and play experience
A10: base2-34 | B10: Dodrio | C10: C | D10: 1 | E10: n | F10: 1 | I10: To stay in when it takes high damage and is capable of using Rage | K10: TRUE | N10: Remaining Evo only applies to Basic and Stage 1. All stage 2 are assumed to not have evolutions remaining
A11: base1-48 | B11: Doduo | C11: C | D11: b | E11: y | G11: a | K11: TRUE | N11: Labels here are used for the lookup table on the deck tabs, but we can possibly get utility from it as well with the AI
A12: base1-18 | B12: Dragonair | C12: C | D12: 1 | E12: y | F12: 1 | K12: TRUE | N12: Trainer rarity is used to gauge usefulness in decks
A13: base3-4 | B13: Dragonite | C13: C | D13: 2 | F13: 3 | H13: HD, PC | I13: To wait on the bench and use its Pokemon Power to Step In at opportune times | K13: TRUE | N13: Half steps are used. Consider those candidates for the next tier with proper support
A14: basep-5 | B14: Dragonite MS | C14: C | D14: 2 | F14: 1.5 | H14: BG | I14: To sit on the bench and use its Pokemon Power when needed | K14: FALSE | L14: Jungle | N14: Opener archetypes per card are tracked. I don't know if we'll need these but it's cheap to do while going through the set anyway. Unlabeled ones should be deferred as openers when possible, but usually committed to once they're in. Based on battle utility, not whether they can evolve, etc
A15: base3-19 | B15: Dragonite NH | C15: C | D15: 2 | F15: 3 | H15: HD, PC | I15: To wait on the bench and use its Pokemon Power to Step In at opportune times | K15: TRUE | N15: Numbers added to the end of names is for differentiation purposes between cards with the same name. Ex: B2 means base2/Jungle
A16: base1-26 | B16: Dratini | C16: C | D16: b | E16: y | K16: TRUE | N16: Nonholo duplicates are tagged with NH after their name. It helps the lookup table
A17: base2-51 | B17: Eevee | C17: C | D17: b | E17: y | G17: e | H17: AP, SL | K17: TRUE | N17: Trainer Function Key, Pressure, and Wants were added at the advice of #15 and haven't been fully applied retroactively yet
A18: basep-11 | B18: Eevee CH | C18: C | D18: b | E18: y | F18: 0.5 | G18: e | H18: BG | I18: To jump in play and evolve quickly | K18: FALSE | L18: Fossil | N18: Opener archetypes are only applied to basic pokemon here
A19: base1-27 | B19: Farfetch'd | C19: C | D19: b | E19: n | G19: a | K19: TRUE
A20: base2-36 | B20: Fearow | C20: C | D20: 1 | E20: n | F20: 1 | H20: WP | I20: To use Agility unless Drill Peck can kill | K20: TRUE
A21: base2-54 | B21: Jigglypuff | C21: C | D21: b | E21: y | G21: a | H21: SL | K21: TRUE | N21: Opener Archetype Key:
A22: basep-7 | B22: Jigglypuff GP | C22: C | D22: b | E22: n | I22: To evolve before fighting | K22: FALSE | L22: Fossil
A23: base2-5 | B23: Kangaskhan | C23: C | D23: b | E23: n | F23: 1.5 | G23: t | H23: BG | I23: To go first/stall while using Fetch. Only rarely wants to use Comet Punch | K23: TRUE | N23: A | O23: Attack Opener. Openers that use stalling attacks, low damage attacks w/ high HP, or build up to damage quickly without evo. Should be weighted high for starter selection or stalling jobs, lower for retreat. Can sometimes also build up to stronger moves while stalling. Ex: Onix, Jynx
A24: base2-21 | B24: Kangaskhan NH | C24: C | D24: b | E24: n | F24: 1.5 | G24: t | H24: BG | I24: To go first/stall while using Fetch. Only rarely wants to use Comet Punch | K24: TRUE | N24: T | O24: Tanks. Usually used as openers but attacks are usually defensive stalling or card drawing. Usually weighted higher than other openers. Ex: Chansey
A25: base2-38 | B25: Lickitung | C25: C | D25: b | E25: n | F25: 0.5 | G25: t | H25: SL | I25: An opening role | K25: TRUE | N25: F | O25: Fallback opener. Good cheap attack option during game, not a main weapon but capable of bridging gaps. Good opener if other options aren't available. Ex: Mewtwo (1-10)
A26: base2-56 | B26: Meowth | C26: C | D26: b | E26: y | G26: a | H26: BG | I26: To go first/early and use Pay Day | K26: TRUE | N26: E | O26: Evo openerer. Lower weight when it comes to opening due to evolution possibility but does have stalling moves or can do damage, and should be prioritized when stalling is needed and no other options available. Higher priority if evolution exists in hand and is realistic to survive long enough to evolve. Ex: Squirtle
A27: basep-10 | B27: Meowth CH | C27: C | D27: b | E27: y | G27: a | H27: BD | I27: To open and disrupt | K27: FALSE | L27: Fossil | N27: N | O27: Avoid using as an opener when possible. Should be weighted lower than the baseline and possibly even switched out when other options become available. Ex: Magikarp
A28: base2-42 | B28: Persian | C28: C | D28: 1 | E28: n | F28: 1 | H28: WP | K28: TRUE | N28: H | O28: HP staller. A high HP card that would normally be used as an attacker is substituted as a tank due to lack of other options. Committed to once in, not retreated or powered up unless smart to do so. A complete sacrifice. Ex: Zapdos
A29: base2-8 | B29: Pidgeot | C29: C | D29: 2 | F29: 3 | H29: PC | K29: TRUE
A30: base2-24 | B30: Pidgeot NH | C30: C | D30: 2 | F30: 3 | H30: PC | K30: TRUE
A31: base1-22 | B31: Pidgeotto | C31: C | D31: 1 | E31: y | K31: TRUE
A32: base1-57 | B32: Pidgey | C32: C | D32: b | E32: y | K32: TRUE | N32: Trainer Function Key:
A33: base1-39 | B33: Porygon | C33: C | D33: b | E33: n | G33: a | K33: TRUE | N33: D | O33: Draw. Cards are picked up from the top of the deck
A34: base1-40 | B34: Raticate | C34: C | D34: 1 | E34: n | K34: TRUE | N34: S | O34: Search. Search for a card in the deck
A35: base1-61 | B35: Rattata | C35: C | D35: b | E35: y | K35: TRUE | N35: P | O35: Disruption. Interferes with the opponent or the status of the board
A36: base2-11 | B36: Snorlax | C36: C | D36: b | E36: n | F36: 1 | G36: t | H36: WP | I36: To stall, not attack or retreat | K36: TRUE | N36: H | O36: Heal. Removes damage from Pokemon
A37: base2-27 | B37: Snorlax NH | C37: C | D37: b | E37: n | F37: 1 | G37: t | H37: WP | I37: To stall, not attack or retreat | K37: TRUE | N37: M | O37: Movement. Moves someone from somewhere to somewhere
A38: base2-62 | B38: Spearow | C38: C | D38: b | E38: y | K38: TRUE | N38: R | O38: Recovery. Removes status conditions
A39: base2-47 | B39: Tauros | C39: C | D39: b | E39: n | G39: f | I39: To stay in and use Rampage when highly damaged | K39: TRUE | N39: E | O39: Exclude from baseline. Doesn't fall in with the other functions but should be excluded from baseline readings
A40: basep-18 | B40: Team Rocket's Meowth | C40: C | D40: b | E40: y | G40: f | H40: HD | I40: To enter play when a lot of pokemon occupy both benches and kamazake itself for high damage | K40: FALSE | L40: Gym Challenge
...

Sheet Template
A1: Card | B1: Quantity | C1: Type | D1: ID | E1: Stage / Rarity | F1: Remaining Evo | G1: Feature Weight | I1: Card Total | K1: Type | L1: Num | M1: Basic | N1: S1 Max | O1: S1 Mid | P1: S2 | Q1: No Evolve
C2: {=IF(NOT(ISBLANK($A2)), (_xlfn.XLOOKUP($A2,Index!$B$2:$B$995,Index!$C$2:$C$995,"Not Found")),"")} | D2: {=IF(NOT(ISBLANK(A2)), (_xlfn.XLOOKUP($A2,Index!$B$2:B$995,Index!$A$2:$A$995,"Not Found")),"")} | E2: {=IF(NOT(ISBLANK($A2)), (_xlfn.XLOOKUP($A2,Index!$B$2:$B$995,Index!$D$2:$D$995,"Not Found")),"")} | F2: {=IF(NOT(ISBLANK($A2)), (_xlfn.XLOOKUP($A2,Index!$B$2:$B$995,Index!$E$2:$E$995,"Not Found")),"")} | G2: {=IF(NOT(ISBLANK(A2)), ((_xlfn.XLOOKUP(A2,Index!$B$2:$B$995,Index!$F$2:$F$995,"Not Found"))*B2),"")} | I2: =SUM(B2:B38) -> 0 | L2: =IF(NOT(ISBLANK(K2)), SUM(M2:P2), "") | M2: =IF(NOT(ISBLANK($K2)), SUMIFS($B$2:$B$32, $E$2:$E$32, "B", $C$2:$C$32,$K2), "") | N2: =IF(NOT(ISBLANK($K2)),SUMIFS($B$2:$B$32,$E$2:$E$32, "1", $C$2:$C$32,$K2,$F$2:$F$32,"N"), "") | O2: =IF(NOT(ISBLANK($K2)),SUMIFS($B$2:$B$32,$E$2:$E$32, "1", $C$2:$C$32,$K2,$F$2:$F$32,"Y"), "") | P2: =IF(NOT(ISBLANK($K2)),SUMIFS($B$2:$B$32,$E$2:$E$32, "2", $C$2:$C$32,$K2), "") | Q2: =IF(NOT(ISBLANK($K2)),SUMIFS($B$2:$B$32,$E$2:$E$32, "B", $C$2:$C$32,$K2,$F$2:$F$32,"N"), "")
C3: {=IF(NOT(ISBLANK($A3)), (_xlfn.XLOOKUP($A3,Index!$B$2:$B$995,Index!$C$2:$C$995,"Not Found")),"")} | D3: {=IF(NOT(ISBLANK(A3)), (_xlfn.XLOOKUP($A3,Index!$B$2:B$995,Index!$A$2:$A$995,"Not Found")),"")} | E3: {=IF(NOT(ISBLANK($A3)), (_xlfn.XLOOKUP($A3,Index!$B$2:$B$995,Index!$D$2:$D$995,"Not Found")),"")} | F3: {=IF(NOT(ISBLANK($A3)), (_xlfn.XLOOKUP($A3,Index!$B$2:$B$995,Index!$E$2:$E$995,"Not Found")),"")} | G3: {=IF(NOT(ISBLANK(A3)), ((_xlfn.XLOOKUP(A3,Index!$B$2:$B$995,Index!$F$2:$F$995,"Not Found"))*B3),"")} | L3: =IF(NOT(ISBLANK(K3)), SUM(M3:P3), "") | M3: =IF(NOT(ISBLANK($K3)), SUMIFS($B$2:$B$32, $E$2:$E$32, "B", $C$2:$C$32,$K3), "") | N3: =IF(NOT(ISBLANK($K3)),SUMIFS($B$2:$B$32,$E$2:$E$32, "1", $C$2:$C$32,$K3,$F$2:$F$32,"N"), "") | O3: =IF(NOT(ISBLANK($K3)),SUMIFS($B$2:$B$32,$E$2:$E$32, "1", $C$2:$C$32,$K3,$F$2:$F$32,"Y"), "") | P3: =IF(NOT(ISBLANK($K3)),SUMIFS($B$2:$B$32,$E$2:$E$32, "2", $C$2:$C$32,$K3), "") | Q3: =IF(NOT(ISBLANK($K3)),SUMIFS($B$2:$B$32,$E$2:$E$32, "B", $C$2:$C$32,$K3,$F$2:$F$32,"N"), "")
C4: {=IF(NOT(ISBLANK($A4)), (_xlfn.XLOOKUP($A4,Index!$B$2:$B$995,Index!$C$2:$C$995,"Not Found")),"")} | D4: {=IF(NOT(ISBLANK(A4)), (_xlfn.XLOOKUP($A4,Index!$B$2:B$995,Index!$A$2:$A$995,"Not Found")),"")} | E4: {=IF(NOT(ISBLANK($A4)), (_xlfn.XLOOKUP($A4,Index!$B$2:$B$995,Index!$D$2:$D$995,"Not Found")),"")} | F4: {=IF(NOT(ISBLANK($A4)), (_xlfn.XLOOKUP($A4,Index!$B$2:$B$995,Index!$E$2:$E$995,"Not Found")),"")} | G4: {=IF(NOT(ISBLANK(A4)), ((_xlfn.XLOOKUP(A4,Index!$B$2:$B$995,Index!$F$2:$F$995,"Not Found"))*B4),"")} | L4: =IF(NOT(ISBLANK(K4)), SUM(M4:P4), "") | M4: =IF(NOT(ISBLANK($K4)), SUMIFS($B$2:$B$32, $E$2:$E$32, "B", $C$2:$C$32,$K4), "") | N4: =IF(NOT(ISBLANK($K4)),SUMIFS($B$2:$B$32,$E$2:$E$32, "1", $C$2:$C$32,$K4,$F$2:$F$32,"N"), "") | O4: =IF(NOT(ISBLANK($K4)),SUMIFS($B$2:$B$32,$E$2:$E$32, "1", $C$2:$C$32,$K4,$F$2:$F$32,"Y"), "") | P4: =IF(NOT(ISBLANK($K4)),SUMIFS($B$2:$B$32,$E$2:$E$32, "2", $C$2:$C$32,$K4), "") | Q4: =IF(NOT(ISBLANK($K4)),SUMIFS($B$2:$B$32,$E$2:$E$32, "B", $C$2:$C$32,$K4,$F$2:$F$32,"N"), "")
C5: {=IF(NOT(ISBLANK($A5)), (_xlfn.XLOOKUP($A5,Index!$B$2:$B$995,Index!$C$2:$C$995,"Not Found")),"")} | D5: {=IF(NOT(ISBLANK(A5)), (_xlfn.XLOOKUP($A5,Index!$B$2:B$995,Index!$A$2:$A$995,"Not Found")),"")} | E5: {=IF(NOT(ISBLANK($A5)), (_xlfn.XLOOKUP($A5,Index!$B$2:$B$995,Index!$D$2:$D$995,"Not Found")),"")} | F5: {=IF(NOT(ISBLANK($A5)), (_xlfn.XLOOKUP($A5,Index!$B$2:$B$995,Index!$E$2:$E$995,"Not Found")),"")} | G5: {=IF(NOT(ISBLANK(A5)), ((_xlfn.XLOOKUP(A5,Index!$B$2:$B$995,Index!$F$2:$F$995,"Not Found"))*B5),"")} | L5: =IF(NOT(ISBLANK(K5)), SUM(M5:P5), "") | M5: =IF(NOT(ISBLANK($K5)), SUMIFS($B$2:$B$32, $E$2:$E$32, "B", $C$2:$C$32,$K5), "") | N5: =IF(NOT(ISBLANK($K5)),SUMIFS($B$2:$B$32,$E$2:$E$32, "1", $C$2:$C$32,$K5,$F$2:$F$32,"N"), "") | O5: =IF(NOT(ISBLANK($K5)),SUMIFS($B$2:$B$32,$E$2:$E$32, "1", $C$2:$C$32,$K5,$F$2:$F$32,"Y"), "") | P5: =IF(NOT(ISBLANK($K5)),SUMIFS($B$2:$B$32,$E$2:$E$32, "2", $C$2:$C$32,$K5), "") | Q5: =IF(NOT(ISBLANK($K5)),SUMIFS($B$2:$B$32,$E$2:$E$32, "B", $C$2:$C$32,$K5,$F$2:$F$32,"N"), "")
C6: {=IF(NOT(ISBLANK($A6)), (_xlfn.XLOOKUP($A6,Index!$B$2:$B$995,Index!$C$2:$C$995,"Not Found")),"")} | D6: {=IF(NOT(ISBLANK(A6)), (_xlfn.XLOOKUP($A6,Index!$B$2:B$995,Index!$A$2:$A$995,"Not Found")),"")} | E6: {=IF(NOT(ISBLANK($A6)), (_xlfn.XLOOKUP($A6,Index!$B$2:$B$995,Index!$D$2:$D$995,"Not Found")),"")} | F6: {=IF(NOT(ISBLANK($A6)), (_xlfn.XLOOKUP($A6,Index!$B$2:$B$995,Index!$E$2:$E$995,"Not Found")),"")} | G6: {=IF(NOT(ISBLANK(A6)), ((_xlfn.XLOOKUP(A6,Index!$B$2:$B$995,Index!$F$2:$F$995,"Not Found"))*B6),"")} | L6: =IF(NOT(ISBLANK(K6)), SUM(M6:P6), "") | M6: =IF(NOT(ISBLANK($K6)), COUNTIFS($E$2:$E$32, "B", $C$2:$C$32,$K6), "") | N6: =IF(NOT(ISBLANK(K6)),COUNTIFS($E$2:$E$32, "1", $C$2:$C$32,$K6,$F$2:$F$32,"N"), "") | O6: =IF(NOT(ISBLANK($K6)),COUNTIFS($E$2:$E$32, "1", $C$2:$C$32,$K6,$F$2:$F$32,"Y"), "") | P6: =IF(NOT(ISBLANK($K6)),COUNTIFS($E$2:$E$32, "2", $C$2:$C$32,$K6), "") | Q6: =IF(NOT(ISBLANK($K6)),COUNTIFS($E$2:$E$32, "B", $C$2:$C$32,$K6,$F$2:$F$32,"N"), "")
C7: {=IF(NOT(ISBLANK($A7)), (_xlfn.XLOOKUP($A7,Index!$B$2:$B$995,Index!$C$2:$C$995,"Not Found")),"")} | D7: {=IF(NOT(ISBLANK(A7)), (_xlfn.XLOOKUP($A7,Index!$B$2:B$995,Index!$A$2:$A$995,"Not Found")),"")} | E7: {=IF(NOT(ISBLANK($A7)), (_xlfn.XLOOKUP($A7,Index!$B$2:$B$995,Index!$D$2:$D$995,"Not Found")),"")} | F7: {=IF(NOT(ISBLANK($A7)), (_xlfn.XLOOKUP($A7,Index!$B$2:$B$995,Index!$E$2:$E$995,"Not Found")),"")} | G7: {=IF(NOT(ISBLANK(A7)), ((_xlfn.XLOOKUP(A7,Index!$B$2:$B$995,Index!$F$2:$F$995,"Not Found"))*B7),"")} | K7: Total | L7: =SUM(L2:L6) -> 0 | M7: =SUM(M2:M6) -> 0 | N7: =SUM(N2:N6) -> 0 | O7: =SUM(O2:O6) -> 0 | P7: =SUM(P2:P6) -> 0 | Q7: =SUM(Q2:Q6) -> 0
C8: {=IF(NOT(ISBLANK($A8)), (_xlfn.XLOOKUP($A8,Index!$B$2:$B$995,Index!$C$2:$C$995,"Not Found")),"")} | D8: {=IF(NOT(ISBLANK(A8)), (_xlfn.XLOOKUP($A8,Index!$B$2:B$995,Index!$A$2:$A$995,"Not Found")),"")} | E8: {=IF(NOT(ISBLANK($A8)), (_xlfn.XLOOKUP($A8,Index!$B$2:$B$995,Index!$D$2:$D$995,"Not Found")),"")} | F8: {=IF(NOT(ISBLANK($A8)), (_xlfn.XLOOKUP($A8,Index!$B$2:$B$995,Index!$E$2:$E$995,"Not Found")),"")} | G8: {=IF(NOT(ISBLANK(A8)), ((_xlfn.XLOOKUP(A8,Index!$B$2:$B$995,Index!$F$2:$F$995,"Not Found"))*B8),"")}
C9: {=IF(NOT(ISBLANK($A9)), (_xlfn.XLOOKUP($A9,Index!$B$2:$B$995,Index!$C$2:$C$995,"Not Found")),"")} | D9: {=IF(NOT(ISBLANK(A9)), (_xlfn.XLOOKUP($A9,Index!$B$2:B$995,Index!$A$2:$A$995,"Not Found")),"")} | E9: {=IF(NOT(ISBLANK($A9)), (_xlfn.XLOOKUP($A9,Index!$B$2:$B$995,Index!$D$2:$D$995,"Not Found")),"")} | F9: {=IF(NOT(ISBLANK($A9)), (_xlfn.XLOOKUP($A9,Index!$B$2:$B$995,Index!$E$2:$E$995,"Not Found")),"")} | G9: {=IF(NOT(ISBLANK(A9)), ((_xlfn.XLOOKUP(A9,Index!$B$2:$B$995,Index!$F$2:$F$995,"Not Found"))*B9),"")} | M9: Common | N9: Uncommon | O9: Rare
C10: {=IF(NOT(ISBLANK($A10)), (_xlfn.XLOOKUP($A10,Index!$B$2:$B$995,Index!$C$2:$C$995,"Not Found")),"")} | D10: {=IF(NOT(ISBLANK(A10)), (_xlfn.XLOOKUP($A10,Index!$B$2:B$995,Index!$A$2:$A$995,"Not Found")),"")} | E10: {=IF(NOT(ISBLANK($A10)), (_xlfn.XLOOKUP($A10,Index!$B$2:$B$995,Index!$D$2:$D$995,"Not Found")),"")} | F10: {=IF(NOT(ISBLANK($A10)), (_xlfn.XLOOKUP($A10,Index!$B$2:$B$995,Index!$E$2:$E$995,"Not Found")),"")} | G10: {=IF(NOT(ISBLANK(A10)), ((_xlfn.XLOOKUP(A10,Index!$B$2:$B$995,Index!$F$2:$F$995,"Not Found"))*B10),"")} | K10: Trainer | L10: =SUM(M10:P10) -> 0 | M10: =IF(NOT(ISBLANK($K10)), SUMIFS($B$2:$B$32,$E$2:$E$32, "C", $C$2:$C$32,"T"), "") -> 0 | N10: =IF(NOT(ISBLANK($K10)), SUMIFS($B$2:$B$32,$E$2:$E$32, "U", $C$2:$C$32,"T"), "") -> 0 | O10: =IF(NOT(ISBLANK($K$2)), SUMIFS($B$2:$B$32,$E$2:$E$32, "R", $C$2:$C$32,"T"), "")
C11: {=IF(NOT(ISBLANK($A11)), (_xlfn.XLOOKUP($A11,Index!$B$2:$B$995,Index!$C$2:$C$995,"Not Found")),"")} | D11: {=IF(NOT(ISBLANK(A11)), (_xlfn.XLOOKUP($A11,Index!$B$2:B$995,Index!$A$2:$A$995,"Not Found")),"")} | E11: {=IF(NOT(ISBLANK($A11)), (_xlfn.XLOOKUP($A11,Index!$B$2:$B$995,Index!$D$2:$D$995,"Not Found")),"")} | F11: {=IF(NOT(ISBLANK($A11)), (_xlfn.XLOOKUP($A11,Index!$B$2:$B$995,Index!$E$2:$E$995,"Not Found")),"")} | G11: {=IF(NOT(ISBLANK(A11)), ((_xlfn.XLOOKUP(A11,Index!$B$2:$B$995,Index!$F$2:$F$995,"Not Found"))*B11),"")} | K11: Energy | L11: =IF(NOT(ISBLANK($K$2)), SUMIFS($B$2:$B$32, $C$2:$C$32,"Energy"), "")
C12: {=IF(NOT(ISBLANK($A12)), (_xlfn.XLOOKUP($A12,Index!$B$2:$B$995,Index!$C$2:$C$995,"Not Found")),"")} | D12: {=IF(NOT(ISBLANK(A12)), (_xlfn.XLOOKUP($A12,Index!$B$2:B$995,Index!$A$2:$A$995,"Not Found")),"")} | E12: {=IF(NOT(ISBLANK($A12)), (_xlfn.XLOOKUP($A12,Index!$B$2:$B$995,Index!$D$2:$D$995,"Not Found")),"")} | F12: {=IF(NOT(ISBLANK($A12)), (_xlfn.XLOOKUP($A12,Index!$B$2:$B$995,Index!$E$2:$E$995,"Not Found")),"")} | G12: {=IF(NOT(ISBLANK(A12)), ((_xlfn.XLOOKUP(A12,Index!$B$2:$B$995,Index!$F$2:$F$995,"Not Found"))*B12),"")} | K12: Pokemon | L12: =L7 -> 0
C13: {=IF(NOT(ISBLANK($A13)), (_xlfn.XLOOKUP($A13,Index!$B$2:$B$995,Index!$C$2:$C$995,"Not Found")),"")} | D13: {=IF(NOT(ISBLANK(A13)), (_xlfn.XLOOKUP($A13,Index!$B$2:B$995,Index!$A$2:$A$995,"Not Found")),"")} | E13: {=IF(NOT(ISBLANK($A13)), (_xlfn.XLOOKUP($A13,Index!$B$2:$B$995,Index!$D$2:$D$995,"Not Found")),"")} | F13: {=IF(NOT(ISBLANK($A13)), (_xlfn.XLOOKUP($A13,Index!$B$2:$B$995,Index!$E$2:$E$995,"Not Found")),"")} | G13: {=IF(NOT(ISBLANK(A13)), ((_xlfn.XLOOKUP(A13,Index!$B$2:$B$995,Index!$F$2:$F$995,"Not Found"))*B13),"")}
C14: {=IF(NOT(ISBLANK($A14)), (_xlfn.XLOOKUP($A14,Index!$B$2:$B$995,Index!$C$2:$C$995,"Not Found")),"")} | D14: {=IF(NOT(ISBLANK(A14)), (_xlfn.XLOOKUP($A14,Index!$B$2:B$995,Index!$A$2:$A$995,"Not Found")),"")} | E14: {=IF(NOT(ISBLANK($A14)), (_xlfn.XLOOKUP($A14,Index!$B$2:$B$995,Index!$D$2:$D$995,"Not Found")),"")} | F14: {=IF(NOT(ISBLANK($A14)), (_xlfn.XLOOKUP($A14,Index!$B$2:$B$995,Index!$E$2:$E$995,"Not Found")),"")} | G14: {=IF(NOT(ISBLANK(A14)), ((_xlfn.XLOOKUP(A14,Index!$B$2:$B$995,Index!$F$2:$F$995,"Not Found"))*B14),"")}
C15: {=IF(NOT(ISBLANK($A15)), (_xlfn.XLOOKUP($A15,Index!$B$2:$B$995,Index!$C$2:$C$995,"Not Found")),"")} | D15: {=IF(NOT(ISBLANK(A15)), (_xlfn.XLOOKUP($A15,Index!$B$2:B$995,Index!$A$2:$A$995,"Not Found")),"")} | E15: {=IF(NOT(ISBLANK($A15)), (_xlfn.XLOOKUP($A15,Index!$B$2:$B$995,Index!$D$2:$D$995,"Not Found")),"")} | F15: {=IF(NOT(ISBLANK($A15)), (_xlfn.XLOOKUP($A15,Index!$B$2:$B$995,Index!$E$2:$E$995,"Not Found")),"")} | G15: {=IF(NOT(ISBLANK(A15)), ((_xlfn.XLOOKUP(A15,Index!$B$2:$B$995,Index!$F$2:$F$995,"Not Found"))*B15),"")} | K15: Feature Weight:
C16: {=IF(NOT(ISBLANK($A16)), (_xlfn.XLOOKUP($A16,Index!$B$2:$B$995,Index!$C$2:$C$995,"Not Found")),"")} | D16: {=IF(NOT(ISBLANK(A16)), (_xlfn.XLOOKUP($A16,Index!$B$2:B$995,Index!$A$2:$A$995,"Not Found")),"")} | E16: {=IF(NOT(ISBLANK($A16)), (_xlfn.XLOOKUP($A16,Index!$B$2:$B$995,Index!$D$2:$D$995,"Not Found")),"")} | F16: {=IF(NOT(ISBLANK($A16)), (_xlfn.XLOOKUP($A16,Index!$B$2:$B$995,Index!$E$2:$E$995,"Not Found")),"")} | G16: {=IF(NOT(ISBLANK(A16)), ((_xlfn.XLOOKUP(A16,Index!$B$2:$B$995,Index!$F$2:$F$995,"Not Found"))*B16),"")} | K16: =K2 | L16: =IF(NOT(ISBLANK($K2)), SUMIFS($G$2:$G$32, $C$2:$C$32,$K2), "")
C17: {=IF(NOT(ISBLANK($A17)), (_xlfn.XLOOKUP($A17,Index!$B$2:$B$995,Index!$C$2:$C$995,"Not Found")),"")} | D17: {=IF(NOT(ISBLANK(A17)), (_xlfn.XLOOKUP($A17,Index!$B$2:B$995,Index!$A$2:$A$995,"Not Found")),"")} | E17: {=IF(NOT(ISBLANK($A17)), (_xlfn.XLOOKUP($A17,Index!$B$2:$B$995,Index!$D$2:$D$995,"Not Found")),"")} | F17: {=IF(NOT(ISBLANK($A17)), (_xlfn.XLOOKUP($A17,Index!$B$2:$B$995,Index!$E$2:$E$995,"Not Found")),"")} | G17: {=IF(NOT(ISBLANK(A17)), ((_xlfn.XLOOKUP(A17,Index!$B$2:$B$995,Index!$F$2:$F$995,"Not Found"))*B17),"")} | K17: =K3 | L17: =IF(NOT(ISBLANK($K3)), SUMIFS($G$2:$G$32, $C$2:$C$32,$K3), "")
C18: {=IF(NOT(ISBLANK($A18)), (_xlfn.XLOOKUP($A18,Index!$B$2:$B$995,Index!$C$2:$C$995,"Not Found")),"")} | D18: {=IF(NOT(ISBLANK(A18)), (_xlfn.XLOOKUP($A18,Index!$B$2:B$995,Index!$A$2:$A$995,"Not Found")),"")} | E18: {=IF(NOT(ISBLANK($A18)), (_xlfn.XLOOKUP($A18,Index!$B$2:$B$995,Index!$D$2:$D$995,"Not Found")),"")} | F18: {=IF(NOT(ISBLANK($A18)), (_xlfn.XLOOKUP($A18,Index!$B$2:$B$995,Index!$E$2:$E$995,"Not Found")),"")} | G18: {=IF(NOT(ISBLANK(A18)), ((_xlfn.XLOOKUP(A18,Index!$B$2:$B$995,Index!$F$2:$F$995,"Not Found"))*B18),"")} | K18: =K4 | L18: =IF(NOT(ISBLANK($K4)), SUMIFS($G$2:$G$32, $C$2:$C$32,$K4), "")
C19: {=IF(NOT(ISBLANK($A19)), (_xlfn.XLOOKUP($A19,Index!$B$2:$B$995,Index!$C$2:$C$995,"Not Found")),"")} | D19: {=IF(NOT(ISBLANK(A19)), (_xlfn.XLOOKUP($A19,Index!$B$2:B$995,Index!$A$2:$A$995,"Not Found")),"")} | E19: {=IF(NOT(ISBLANK($A19)), (_xlfn.XLOOKUP($A19,Index!$B$2:$B$995,Index!$D$2:$D$995,"Not Found")),"")} | F19: {=IF(NOT(ISBLANK($A19)), (_xlfn.XLOOKUP($A19,Index!$B$2:$B$995,Index!$E$2:$E$995,"Not Found")),"")} | G19: {=IF(NOT(ISBLANK(A19)), ((_xlfn.XLOOKUP(A19,Index!$B$2:$B$995,Index!$F$2:$F$995,"Not Found"))*B19),"")} | K19: =K5 | L19: =IF(NOT(ISBLANK($K5)), SUMIFS($G$2:$G$32, $C$2:$C$32,$K5), "")
C20: {=IF(NOT(ISBLANK($A20)), (_xlfn.XLOOKUP($A20,Index!$B$2:$B$995,Index!$C$2:$C$995,"Not Found")),"")} | D20: {=IF(NOT(ISBLANK(A20)), (_xlfn.XLOOKUP($A20,Index!$B$2:B$995,Index!$A$2:$A$995,"Not Found")),"")} | E20: {=IF(NOT(ISBLANK($A20)), (_xlfn.XLOOKUP($A20,Index!$B$2:$B$995,Index!$D$2:$D$995,"Not Found")),"")} | F20: {=IF(NOT(ISBLANK($A20)), (_xlfn.XLOOKUP($A20,Index!$B$2:$B$995,Index!$E$2:$E$995,"Not Found")),"")} | G20: {=IF(NOT(ISBLANK(A20)), ((_xlfn.XLOOKUP(A20,Index!$B$2:$B$995,Index!$F$2:$F$995,"Not Found"))*B20),"")} | K20: =K6
C21: {=IF(NOT(ISBLANK($A21)), (_xlfn.XLOOKUP($A21,Index!$B$2:$B$995,Index!$C$2:$C$995,"Not Found")),"")} | D21: {=IF(NOT(ISBLANK(A21)), (_xlfn.XLOOKUP($A21,Index!$B$2:B$995,Index!$A$2:$A$995,"Not Found")),"")} | E21: {=IF(NOT(ISBLANK($A21)), (_xlfn.XLOOKUP($A21,Index!$B$2:$B$995,Index!$D$2:$D$995,"Not Found")),"")} | F21: {=IF(NOT(ISBLANK($A21)), (_xlfn.XLOOKUP($A21,Index!$B$2:$B$995,Index!$E$2:$E$995,"Not Found")),"")} | G21: {=IF(NOT(ISBLANK(A21)), ((_xlfn.XLOOKUP(A21,Index!$B$2:$B$995,Index!$F$2:$F$995,"Not Found"))*B21),"")} | K21: Total: | L21: =SUM(L15:L19) -> 0
C22: {=IF(NOT(ISBLANK($A22)), (_xlfn.XLOOKUP($A22,Index!$B$2:$B$995,Index!$C$2:$C$995,"Not Found")),"")} | D22: {=IF(NOT(ISBLANK(A22)), (_xlfn.XLOOKUP($A22,Index!$B$2:B$995,Index!$A$2:$A$995,"Not Found")),"")} | E22: {=IF(NOT(ISBLANK($A22)), (_xlfn.XLOOKUP($A22,Index!$B$2:$B$995,Index!$D$2:$D$995,"Not Found")),"")} | F22: {=IF(NOT(ISBLANK($A22)), (_xlfn.XLOOKUP($A22,Index!$B$2:$B$995,Index!$E$2:$E$995,"Not Found")),"")} | G22: {=IF(NOT(ISBLANK(A22)), ((_xlfn.XLOOKUP(A22,Index!$B$2:$B$995,Index!$F$2:$F$995,"Not Found"))*B22),"")}
C23: {=IF(NOT(ISBLANK($A23)), (_xlfn.XLOOKUP($A23,Index!$B$2:$B$995,Index!$C$2:$C$995,"Not Found")),"")} | D23: {=IF(NOT(ISBLANK(A23)), (_xlfn.XLOOKUP($A23,Index!$B$2:B$995,Index!$A$2:$A$995,"Not Found")),"")} | E23: {=IF(NOT(ISBLANK($A23)), (_xlfn.XLOOKUP($A23,Index!$B$2:$B$995,Index!$D$2:$D$995,"Not Found")),"")} | F23: {=IF(NOT(ISBLANK($A23)), (_xlfn.XLOOKUP($A23,Index!$B$2:$B$995,Index!$E$2:$E$995,"Not Found")),"")} | G23: {=IF(NOT(ISBLANK(A23)), ((_xlfn.XLOOKUP(A23,Index!$B$2:$B$995,Index!$F$2:$F$995,"Not Found"))*B23),"")}
C24: {=IF(NOT(ISBLANK($A24)), (_xlfn.XLOOKUP($A24,Index!$B$2:$B$995,Index!$C$2:$C$995,"Not Found")),"")} | D24: {=IF(NOT(ISBLANK(A24)), (_xlfn.XLOOKUP($A24,Index!$B$2:B$995,Index!$A$2:$A$995,"Not Found")),"")} | E24: {=IF(NOT(ISBLANK($A24)), (_xlfn.XLOOKUP($A24,Index!$B$2:$B$995,Index!$D$2:$D$995,"Not Found")),"")} | F24: {=IF(NOT(ISBLANK($A24)), (_xlfn.XLOOKUP($A24,Index!$B$2:$B$995,Index!$E$2:$E$995,"Not Found")),"")} | G24: {=IF(NOT(ISBLANK(A24)), ((_xlfn.XLOOKUP(A24,Index!$B$2:$B$995,Index!$F$2:$F$995,"Not Found"))*B24),"")} | K24: Cover Card:
C25: {=IF(NOT(ISBLANK($A25)), (_xlfn.XLOOKUP($A25,Index!$B$2:$B$995,Index!$C$2:$C$995,"Not Found")),"")} | D25: {=IF(NOT(ISBLANK(A25)), (_xlfn.XLOOKUP($A25,Index!$B$2:B$995,Index!$A$2:$A$995,"Not Found")),"")} | E25: {=IF(NOT(ISBLANK($A25)), (_xlfn.XLOOKUP($A25,Index!$B$2:$B$995,Index!$D$2:$D$995,"Not Found")),"")} | F25: {=IF(NOT(ISBLANK($A25)), (_xlfn.XLOOKUP($A25,Index!$B$2:$B$995,Index!$E$2:$E$995,"Not Found")),"")} | G25: {=IF(NOT(ISBLANK(A25)), ((_xlfn.XLOOKUP(A25,Index!$B$2:$B$995,Index!$F$2:$F$995,"Not Found"))*B25),"")}
C26: {=IF(NOT(ISBLANK($A26)), (_xlfn.XLOOKUP($A26,Index!$B$2:$B$995,Index!$C$2:$C$995,"Not Found")),"")} | D26: {=IF(NOT(ISBLANK(A26)), (_xlfn.XLOOKUP($A26,Index!$B$2:B$995,Index!$A$2:$A$995,"Not Found")),"")} | E26: {=IF(NOT(ISBLANK($A26)), (_xlfn.XLOOKUP($A26,Index!$B$2:$B$995,Index!$D$2:$D$995,"Not Found")),"")} | F26: {=IF(NOT(ISBLANK($A26)), (_xlfn.XLOOKUP($A26,Index!$B$2:$B$995,Index!$E$2:$E$995,"Not Found")),"")} | G26: {=IF(NOT(ISBLANK(A26)), ((_xlfn.XLOOKUP(A26,Index!$B$2:$B$995,Index!$F$2:$F$995,"Not Found"))*B26),"")}
C27: {=IF(NOT(ISBLANK($A27)), (_xlfn.XLOOKUP($A27,Index!$B$2:$B$995,Index!$C$2:$C$995,"Not Found")),"")} | D27: {=IF(NOT(ISBLANK(A27)), (_xlfn.XLOOKUP($A27,Index!$B$2:B$995,Index!$A$2:$A$995,"Not Found")),"")} | E27: {=IF(NOT(ISBLANK($A27)), (_xlfn.XLOOKUP($A27,Index!$B$2:$B$995,Index!$D$2:$D$995,"Not Found")),"")} | F27: {=IF(NOT(ISBLANK($A27)), (_xlfn.XLOOKUP($A27,Index!$B$2:$B$995,Index!$E$2:$E$995,"Not Found")),"")} | G27: {=IF(NOT(ISBLANK(A27)), ((_xlfn.XLOOKUP(A27,Index!$B$2:$B$995,Index!$F$2:$F$995,"Not Found"))*B27),"")}
C28: {=IF(NOT(ISBLANK($A28)), (_xlfn.XLOOKUP($A28,Index!$B$2:$B$995,Index!$C$2:$C$995,"Not Found")),"")} | D28: {=IF(NOT(ISBLANK(A28)), (_xlfn.XLOOKUP($A28,Index!$B$2:B$995,Index!$A$2:$A$995,"Not Found")),"")} | E28: {=IF(NOT(ISBLANK($A28)), (_xlfn.XLOOKUP($A28,Index!$B$2:$B$995,Index!$D$2:$D$995,"Not Found")),"")} | F28: {=IF(NOT(ISBLANK($A28)), (_xlfn.XLOOKUP($A28,Index!$B$2:$B$995,Index!$E$2:$E$995,"Not Found")),"")} | G28: {=IF(NOT(ISBLANK(A28)), ((_xlfn.XLOOKUP(A28,Index!$B$2:$B$995,Index!$F$2:$F$995,"Not Found"))*B28),"")}
C29: {=IF(NOT(ISBLANK($A29)), (_xlfn.XLOOKUP($A29,Index!$B$2:$B$995,Index!$C$2:$C$995,"Not Found")),"")} | D29: {=IF(NOT(ISBLANK(A29)), (_xlfn.XLOOKUP($A29,Index!$B$2:B$995,Index!$A$2:$A$995,"Not Found")),"")} | E29: {=IF(NOT(ISBLANK($A29)), (_xlfn.XLOOKUP($A29,Index!$B$2:$B$995,Index!$D$2:$D$995,"Not Found")),"")} | F29: {=IF(NOT(ISBLANK($A29)), (_xlfn.XLOOKUP($A29,Index!$B$2:$B$995,Index!$E$2:$E$995,"Not Found")),"")} | G29: {=IF(NOT(ISBLANK(A29)), ((_xlfn.XLOOKUP(A29,Index!$B$2:$B$995,Index!$F$2:$F$995,"Not Found"))*B29),"")}
C30: {=IF(NOT(ISBLANK($A30)), (_xlfn.XLOOKUP($A30,Index!$B$2:$B$995,Index!$C$2:$C$995,"Not Found")),"")} | D30: {=IF(NOT(ISBLANK(A30)), (_xlfn.XLOOKUP($A30,Index!$B$2:B$995,Index!$A$2:$A$995,"Not Found")),"")} | E30: {=IF(NOT(ISBLANK($A30)), (_xlfn.XLOOKUP($A30,Index!$B$2:$B$995,Index!$D$2:$D$995,"Not Found")),"")} | F30: {=IF(NOT(ISBLANK($A30)), (_xlfn.XLOOKUP($A30,Index!$B$2:$B$995,Index!$E$2:$E$995,"Not Found")),"")} | G30: {=IF(NOT(ISBLANK(A30)), ((_xlfn.XLOOKUP(A30,Index!$B$2:$B$995,Index!$F$2:$F$995,"Not Found"))*B30),"")}
C31: {=IF(NOT(ISBLANK($A31)), (_xlfn.XLOOKUP($A31,Index!$B$2:$B$995,Index!$C$2:$C$995,"Not Found")),"")} | D31: {=IF(NOT(ISBLANK(A31)), (_xlfn.XLOOKUP($A31,Index!$B$2:B$995,Index!$A$2:$A$995,"Not Found")),"")} | E31: {=IF(NOT(ISBLANK($A31)), (_xlfn.XLOOKUP($A31,Index!$B$2:$B$995,Index!$D$2:$D$995,"Not Found")),"")} | F31: {=IF(NOT(ISBLANK($A31)), (_xlfn.XLOOKUP($A31,Index!$B$2:$B$995,Index!$E$2:$E$995,"Not Found")),"")} | G31: {=IF(NOT(ISBLANK(A31)), ((_xlfn.XLOOKUP(A31,Index!$B$2:$B$995,Index!$F$2:$F$995,"Not Found"))*B31),"")}
C32: {=IF(NOT(ISBLANK($A32)), (_xlfn.XLOOKUP($A32,Index!$B$2:$B$995,Index!$C$2:$C$995,"Not Found")),"")} | D32: {=IF(NOT(ISBLANK(A32)), (_xlfn.XLOOKUP($A32,Index!$B$2:B$995,Index!$A$2:$A$995,"Not Found")),"")} | E32: {=IF(NOT(ISBLANK($A32)), (_xlfn.XLOOKUP($A32,Index!$B$2:$B$995,Index!$D$2:$D$995,"Not Found")),"")} | F32: {=IF(NOT(ISBLANK($A32)), (_xlfn.XLOOKUP($A32,Index!$B$2:$B$995,Index!$E$2:$E$995,"Not Found")),"")} | G32: {=IF(NOT(ISBLANK(A32)), ((_xlfn.XLOOKUP(A32,Index!$B$2:$B$995,Index!$F$2:$F$995,"Not Found"))*B32),"")}
C33: {=IF(NOT(ISBLANK($A33)), (_xlfn.XLOOKUP($A33,Index!$B$2:$B$995,Index!$C$2:$C$995,"Not Found")),"")} | D33: {=IF(NOT(ISBLANK(A33)), (_xlfn.XLOOKUP($A33,Index!$B$2:B$995,Index!$A$2:$A$995,"Not Found")),"")} | E33: {=IF(NOT(ISBLANK($A33)), (_xlfn.XLOOKUP($A33,Index!$B$2:$B$995,Index!$D$2:$D$995,"Not Found")),"")} | F33: {=IF(NOT(ISBLANK($A33)), (_xlfn.XLOOKUP($A33,Index!$B$2:$B$995,Index!$E$2:$E$995,"Not Found")),"")} | G33: {=IF(NOT(ISBLANK(A33)), ((_xlfn.XLOOKUP(A33,Index!$B$2:$B$995,Index!$F$2:$F$995,"Not Found"))*B33),"")}
C34: {=IF(NOT(ISBLANK($A34)), (_xlfn.XLOOKUP($A34,Index!$B$2:$B$995,Index!$C$2:$C$995,"Not Found")),"")} | D34: {=IF(NOT(ISBLANK(A34)), (_xlfn.XLOOKUP($A34,Index!$B$2:B$995,Index!$A$2:$A$995,"Not Found")),"")} | E34: {=IF(NOT(ISBLANK($A34)), (_xlfn.XLOOKUP($A34,Index!$B$2:$B$995,Index!$D$2:$D$995,"Not Found")),"")} | F34: {=IF(NOT(ISBLANK($A34)), (_xlfn.XLOOKUP($A34,Index!$B$2:$B$995,Index!$E$2:$E$995,"Not Found")),"")} | G34: {=IF(NOT(ISBLANK(A34)), ((_xlfn.XLOOKUP(A34,Index!$B$2:$B$995,Index!$F$2:$F$995,"Not Found"))*B34),"")}
C35: {=IF(NOT(ISBLANK($A35)), (_xlfn.XLOOKUP($A35,Index!$B$2:$B$995,Index!$C$2:$C$995,"Not Found")),"")} | D35: {=IF(NOT(ISBLANK(A35)), (_xlfn.XLOOKUP($A35,Index!$B$2:B$995,Index!$A$2:$A$995,"Not Found")),"")} | E35: {=IF(NOT(ISBLANK($A35)), (_xlfn.XLOOKUP($A35,Index!$B$2:$B$995,Index!$D$2:$D$995,"Not Found")),"")} | F35: {=IF(NOT(ISBLANK($A35)), (_xlfn.XLOOKUP($A35,Index!$B$2:$B$995,Index!$E$2:$E$995,"Not Found")),"")} | G35: {=IF(NOT(ISBLANK(A35)), ((_xlfn.XLOOKUP(A35,Index!$B$2:$B$995,Index!$F$2:$F$995,"Not Found"))*B35),"")}
C36: {=IF(NOT(ISBLANK($A36)), (_xlfn.XLOOKUP($A36,Index!$B$2:$B$995,Index!$C$2:$C$995,"Not Found")),"")} | D36: {=IF(NOT(ISBLANK(A36)), (_xlfn.XLOOKUP($A36,Index!$B$2:B$995,Index!$A$2:$A$995,"Not Found")),"")} | E36: {=IF(NOT(ISBLANK($A36)), (_xlfn.XLOOKUP($A36,Index!$B$2:$B$995,Index!$D$2:$D$995,"Not Found")),"")} | F36: {=IF(NOT(ISBLANK($A36)), (_xlfn.XLOOKUP($A36,Index!$B$2:$B$995,Index!$E$2:$E$995,"Not Found")),"")} | G36: {=IF(NOT(ISBLANK(A36)), ((_xlfn.XLOOKUP(A36,Index!$B$2:$B$995,Index!$F$2:$F$995,"Not Found"))*B36),"")}
... C77: {=IF(NOT(ISBLANK($A77)), (_xlfn.XLOOKUP($A77,Index!$B$2:$B$995,Index!$C$2:$C$995,"Not Found")),"")} | D77: {=IF(NOT(ISBLANK(A77)), (_xlfn.XLOOKUP($A77,Index!$B$2:B$995,Index!$A$2:$A$995,"Not Found")),"")} | E77: {=IF(NOT(ISBLANK($A77)), (_xlfn.XLOOKUP($A77,Index!$B$2:$B$995,Index!$D$2:$D$995,"Not Found")),"")} | F77: {=IF(NOT(ISBLANK($A77)), (_xlfn.XLOOKUP($A77,Index!$B$2:$B$995,Index!$E$2:$E$995,"Not Found")),"")} | G77: {=IF(NOT(ISBLANK(A77)), ((_xlfn.XLOOKUP(A77,Index!$B$2:$B$995,Index!$F$2:$F$995,"Not Found"))*B77),"")}

Sheet Lightning
A1: Card | B1: Quantity | C1: Type | D1: ID | E1: Stage / Rarity | F1: Remaining Evo | G1: Feature Weight | I1: Card Total | K1: Type | L1: Num | M1: Basic | N1: S1 Max | O1: S1 Mid | P1: S2 | Q1: No Evolve
A2: E Energy | B2: 24 | C2: {=IF(NOT(ISBLANK($A2)), (_xlfn.XLOOKUP($A2,Index!$B$2:$B$995,Index!$C$2:$C$995,"Not Found")),"")} -> Energy | D2: {=IF(NOT(ISBLANK(A2)), (_xlfn.XLOOKUP($A2,Index!$B$2:B$995,Index!$A$2:$A$995,"Not Found")),"")} -> base1-100 | E2: {=IF(NOT(ISBLANK($A2)), (_xlfn.XLOOKUP($A2,Index!$B$2:$B$995,Index!$D$2:$D$995,"Not Found")),"")} | F2: {=IF(NOT(ISBLANK($A2)), (_xlfn.XLOOKUP($A2,Index!$B$2:$B$995,Index!$E$2:$E$995,"Not Found")),"")} | G2: {=IF(NOT(ISBLANK(A2)), ((_xlfn.XLOOKUP(A2,Index!$B$2:$B$995,Index!$F$2:$F$995,"Not Found"))*B2),"")} -> 0 | I2: =SUM(B2:B38) -> 60 | K2: E | L2: =IF(NOT(ISBLANK(K2)), SUM(M2:P2), "") -> 17 | M2: =IF(NOT(ISBLANK($K2)), SUMIFS($B$2:$B$32, $E$2:$E$32, "B", $C$2:$C$32,$K2), "") -> 10 | N2: =IF(NOT(ISBLANK($K2)),SUMIFS($B$2:$B$32,$E$2:$E$32, "1", $C$2:$C$32,$K2,$F$2:$F$32,"N"), "") -> 7 | O2: =IF(NOT(ISBLANK($K2)),SUMIFS($B$2:$B$32,$E$2:$E$32, "1", $C$2:$C$32,$K2,$F$2:$F$32,"Y"), "") -> 0 | P2: =IF(NOT(ISBLANK($K2)),SUMIFS($B$2:$B$32,$E$2:$E$32, "2", $C$2:$C$32,$K2), "") -> 0 | Q2: =IF(NOT(ISBLANK($K2)),SUMIFS($B$2:$B$32,$E$2:$E$32, "B", $C$2:$C$32,$K2,$F$2:$F$32,"N"), "") -> 3
A3: Pikachu | B3: 1 | C3: {=IF(NOT(ISBLANK($A3)), (_xlfn.XLOOKUP($A3,Index!$B$2:$B$995,Index!$C$2:$C$995,"Not Found")),"")} -> E | D3: {=IF(NOT(ISBLANK(A3)), (_xlfn.XLOOKUP($A3,Index!$B$2:B$995,Index!$A$2:$A$995,"Not Found")),"")} -> base1-58 | E3: {=IF(NOT(ISBLANK($A3)), (_xlfn.XLOOKUP($A3,Index!$B$2:$B$995,Index!$D$2:$D$995,"Not Found")),"")} -> b | F3: {=IF(NOT(ISBLANK($A3)), (_xlfn.XLOOKUP($A3,Index!$B$2:$B$995,Index!$E$2:$E$995,"Not Found")),"")} -> y | G3: {=IF(NOT(ISBLANK(A3)), ((_xlfn.XLOOKUP(A3,Index!$B$2:$B$995,Index!$F$2:$F$995,"Not Found"))*B3),"")} -> 0 | K3: C | L3: =IF(NOT(ISBLANK(K3)), SUM(M3:P3), "") -> 3 | M3: =IF(NOT(ISBLANK($K3)), SUMIFS($B$2:$B$32, $E$2:$E$32, "B", $C$2:$C$32,$K3), "") -> 3 | N3: =IF(NOT(ISBLANK($K3)),SUMIFS($B$2:$B$32,$E$2:$E$32, "1", $C$2:$C$32,$K3,$F$2:$F$32,"N"), "") -> 0 | O3: =IF(NOT(ISBLANK($K3)),SUMIFS($B$2:$B$32,$E$2:$E$32, "1", $C$2:$C$32,$K3,$F$2:$F$32,"Y"), "") -> 0 | P3: =IF(NOT(ISBLANK($K3)),SUMIFS($B$2:$B$32,$E$2:$E$32, "2", $C$2:$C$32,$K3), "") -> 0 | Q3: =IF(NOT(ISBLANK($K3)),SUMIFS($B$2:$B$32,$E$2:$E$32, "B", $C$2:$C$32,$K3,$F$2:$F$32,"N"), "") -> 0
A4: Pikachu B2 | B4: 1 | C4: {=IF(NOT(ISBLANK($A4)), (_xlfn.XLOOKUP($A4,Index!$B$2:$B$995,Index!$C$2:$C$995,"Not Found")),"")} -> E | D4: {=IF(NOT(ISBLANK(A4)), (_xlfn.XLOOKUP($A4,Index!$B$2:B$995,Index!$A$2:$A$995,"Not Found")),"")} -> base2-60 | E4: {=IF(NOT(ISBLANK($A4)), (_xlfn.XLOOKUP($A4,Index!$B$2:$B$995,Index!$D$2:$D$995,"Not Found")),"")} -> b | F4: {=IF(NOT(ISBLANK($A4)), (_xlfn.XLOOKUP($A4,Index!$B$2:$B$995,Index!$E$2:$E$995,"Not Found")),"")} -> y | G4: {=IF(NOT(ISBLANK(A4)), ((_xlfn.XLOOKUP(A4,Index!$B$2:$B$995,Index!$F$2:$F$995,"Not Found"))*B4),"")} -> 0 | L4: =IF(NOT(ISBLANK(K4)), SUM(M4:P4), "") | M4: =IF(NOT(ISBLANK($K4)), SUMIFS($B$2:$B$32, $E$2:$E$32, "B", $C$2:$C$32,$K4), "") | N4: =IF(NOT(ISBLANK($K4)),SUMIFS($B$2:$B$32,$E$2:$E$32, "1", $C$2:$C$32,$K4,$F$2:$F$32,"N"), "") | O4: =IF(NOT(ISBLANK($K4)),SUMIFS($B$2:$B$32,$E$2:$E$32, "1", $C$2:$C$32,$K4,$F$2:$F$32,"Y"), "") | P4: =IF(NOT(ISBLANK($K4)),SUMIFS($B$2:$B$32,$E$2:$E$32, "2", $C$2:$C$32,$K4), "") | Q4: =IF(NOT(ISBLANK($K4)),SUMIFS($B$2:$B$32,$E$2:$E$32, "B", $C$2:$C$32,$K4,$F$2:$F$32,"N"), "")
A5: Pikachu GP | B5: 1 | C5: {=IF(NOT(ISBLANK($A5)), (_xlfn.XLOOKUP($A5,Index!$B$2:$B$995,Index!$C$2:$C$995,"Not Found")),"")} -> E | D5: {=IF(NOT(ISBLANK(A5)), (_xlfn.XLOOKUP($A5,Index!$B$2:B$995,Index!$A$2:$A$995,"Not Found")),"")} -> basep-1 | E5: {=IF(NOT(ISBLANK($A5)), (_xlfn.XLOOKUP($A5,Index!$B$2:$B$995,Index!$D$2:$D$995,"Not Found")),"")} -> b | F5: {=IF(NOT(ISBLANK($A5)), (_xlfn.XLOOKUP($A5,Index!$B$2:$B$995,Index!$E$2:$E$995,"Not Found")),"")} -> y | G5: {=IF(NOT(ISBLANK(A5)), ((_xlfn.XLOOKUP(A5,Index!$B$2:$B$995,Index!$F$2:$F$995,"Not Found"))*B5),"")} -> 0 | L5: =IF(NOT(ISBLANK(K5)), SUM(M5:P5), "") | M5: =IF(NOT(ISBLANK($K5)), SUMIFS($B$2:$B$32, $E$2:$E$32, "B", $C$2:$C$32,$K5), "") | N5: =IF(NOT(ISBLANK($K5)),SUMIFS($B$2:$B$32,$E$2:$E$32, "1", $C$2:$C$32,$K5,$F$2:$F$32,"N"), "") | O5: =IF(NOT(ISBLANK($K5)),SUMIFS($B$2:$B$32,$E$2:$E$32, "1", $C$2:$C$32,$K5,$F$2:$F$32,"Y"), "") | P5: =IF(NOT(ISBLANK($K5)),SUMIFS($B$2:$B$32,$E$2:$E$32, "2", $C$2:$C$32,$K5), "") | Q5: =IF(NOT(ISBLANK($K5)),SUMIFS($B$2:$B$32,$E$2:$E$32, "B", $C$2:$C$32,$K5,$F$2:$F$32,"N"), "")
A6: PIkachu GP 2 | B6: 1 | C6: {=IF(NOT(ISBLANK($A6)), (_xlfn.XLOOKUP($A6,Index!$B$2:$B$995,Index!$C$2:$C$995,"Not Found")),"")} -> E | D6: {=IF(NOT(ISBLANK(A6)), (_xlfn.XLOOKUP($A6,Index!$B$2:B$995,Index!$A$2:$A$995,"Not Found")),"")} -> basep-26 | E6: {=IF(NOT(ISBLANK($A6)), (_xlfn.XLOOKUP($A6,Index!$B$2:$B$995,Index!$D$2:$D$995,"Not Found")),"")} -> b | F6: {=IF(NOT(ISBLANK($A6)), (_xlfn.XLOOKUP($A6,Index!$B$2:$B$995,Index!$E$2:$E$995,"Not Found")),"")} -> y | G6: {=IF(NOT(ISBLANK(A6)), ((_xlfn.XLOOKUP(A6,Index!$B$2:$B$995,Index!$F$2:$F$995,"Not Found"))*B6),"")} -> 0 | L6: =IF(NOT(ISBLANK(K6)), SUM(M6:P6), "") | M6: =IF(NOT(ISBLANK($K6)), COUNTIFS($E$2:$E$32, "B", $C$2:$C$32,$K6), "") | N6: =IF(NOT(ISBLANK(K6)),COUNTIFS($E$2:$E$32, "1", $C$2:$C$32,$K6,$F$2:$F$32,"N"), "") | O6: =IF(NOT(ISBLANK($K6)),COUNTIFS($E$2:$E$32, "1", $C$2:$C$32,$K6,$F$2:$F$32,"Y"), "") | P6: =IF(NOT(ISBLANK($K6)),COUNTIFS($E$2:$E$32, "2", $C$2:$C$32,$K6), "") | Q6: =IF(NOT(ISBLANK($K6)),COUNTIFS($E$2:$E$32, "B", $C$2:$C$32,$K6,$F$2:$F$32,"N"), "")
A7: Raichu | B7: 1 | C7: {=IF(NOT(ISBLANK($A7)), (_xlfn.XLOOKUP($A7,Index!$B$2:$B$995,Index!$C$2:$C$995,"Not Found")),"")} -> E | D7: {=IF(NOT(ISBLANK(A7)), (_xlfn.XLOOKUP($A7,Index!$B$2:B$995,Index!$A$2:$A$995,"Not Found")),"")} -> base1-14 | E7: {=IF(NOT(ISBLANK($A7)), (_xlfn.XLOOKUP($A7,Index!$B$2:$B$995,Index!$D$2:$D$995,"Not Found")),"")} -> 1 | F7: {=IF(NOT(ISBLANK($A7)), (_xlfn.XLOOKUP($A7,Index!$B$2:$B$995,Index!$E$2:$E$995,"Not Found")),"")} -> n | G7: {=IF(NOT(ISBLANK(A7)), ((_xlfn.XLOOKUP(A7,Index!$B$2:$B$995,Index!$F$2:$F$995,"Not Found"))*B7),"")} -> 2 | K7: Total | L7: =SUM(L2:L6) -> 20 | M7: =SUM(M2:M6) -> 13 | N7: =SUM(N2:N6) -> 7 | O7: =SUM(O2:O6) -> 0 | P7: =SUM(P2:P6) -> 0 | Q7: =SUM(Q2:Q6) -> 3
A8: Raichu B3 | B8: 2 | C8: {=IF(NOT(ISBLANK($A8)), (_xlfn.XLOOKUP($A8,Index!$B$2:$B$995,Index!$C$2:$C$995,"Not Found")),"")} -> E | D8: {=IF(NOT(ISBLANK(A8)), (_xlfn.XLOOKUP($A8,Index!$B$2:B$995,Index!$A$2:$A$995,"Not Found")),"")} -> base3-14 | E8: {=IF(NOT(ISBLANK($A8)), (_xlfn.XLOOKUP($A8,Index!$B$2:$B$995,Index!$D$2:$D$995,"Not Found")),"")} -> 1 | F8: {=IF(NOT(ISBLANK($A8)), (_xlfn.XLOOKUP($A8,Index!$B$2:$B$995,Index!$E$2:$E$995,"Not Found")),"")} -> n | G8: {=IF(NOT(ISBLANK(A8)), ((_xlfn.XLOOKUP(A8,Index!$B$2:$B$995,Index!$F$2:$F$995,"Not Found"))*B8),"")} -> 4
A9: Magnemite | B9: 3 | C9: {=IF(NOT(ISBLANK($A9)), (_xlfn.XLOOKUP($A9,Index!$B$2:$B$995,Index!$C$2:$C$995,"Not Found")),"")} -> E | D9: {=IF(NOT(ISBLANK(A9)), (_xlfn.XLOOKUP($A9,Index!$B$2:B$995,Index!$A$2:$A$995,"Not Found")),"")} -> base1-53 | E9: {=IF(NOT(ISBLANK($A9)), (_xlfn.XLOOKUP($A9,Index!$B$2:$B$995,Index!$D$2:$D$995,"Not Found")),"")} -> b | F9: {=IF(NOT(ISBLANK($A9)), (_xlfn.XLOOKUP($A9,Index!$B$2:$B$995,Index!$E$2:$E$995,"Not Found")),"")} -> y | G9: {=IF(NOT(ISBLANK(A9)), ((_xlfn.XLOOKUP(A9,Index!$B$2:$B$995,Index!$F$2:$F$995,"Not Found"))*B9),"")} -> 0 | M9: Common | N9: Uncommon | O9: Rare
A10: Magneton | B10: 1 | C10: {=IF(NOT(ISBLANK($A10)), (_xlfn.XLOOKUP($A10,Index!$B$2:$B$995,Index!$C$2:$C$995,"Not Found")),"")} -> E | D10: {=IF(NOT(ISBLANK(A10)), (_xlfn.XLOOKUP($A10,Index!$B$2:B$995,Index!$A$2:$A$995,"Not Found")),"")} -> base1-9 | E10: {=IF(NOT(ISBLANK($A10)), (_xlfn.XLOOKUP($A10,Index!$B$2:$B$995,Index!$D$2:$D$995,"Not Found")),"")} -> 1 | F10: {=IF(NOT(ISBLANK($A10)), (_xlfn.XLOOKUP($A10,Index!$B$2:$B$995,Index!$E$2:$E$995,"Not Found")),"")} -> n | G10: {=IF(NOT(ISBLANK(A10)), ((_xlfn.XLOOKUP(A10,Index!$B$2:$B$995,Index!$F$2:$F$995,"Not Found"))*B10),"")} -> 2 | K10: Trainer | L10: =SUM(M10:P10) -> 16 | M10: =IF(NOT(ISBLANK($K10)), SUMIFS($B$2:$B$32,$E$2:$E$32, "C", $C$2:$C$32,"T"), "") -> 10 | N10: =IF(NOT(ISBLANK($K10)), SUMIFS($B$2:$B$32,$E$2:$E$32, "U", $C$2:$C$32,"T"), "") -> 4 | O10: =IF(NOT(ISBLANK($K$2)), SUMIFS($B$2:$B$32,$E$2:$E$32, "R", $C$2:$C$32,"T"), "") -> 2
A11: Magneton B3 | B11: 1 | C11: {=IF(NOT(ISBLANK($A11)), (_xlfn.XLOOKUP($A11,Index!$B$2:$B$995,Index!$C$2:$C$995,"Not Found")),"")} -> E | D11: {=IF(NOT(ISBLANK(A11)), (_xlfn.XLOOKUP($A11,Index!$B$2:B$995,Index!$A$2:$A$995,"Not Found")),"")} -> base3-11 | E11: {=IF(NOT(ISBLANK($A11)), (_xlfn.XLOOKUP($A11,Index!$B$2:$B$995,Index!$D$2:$D$995,"Not Found")),"")} -> 1 | F11: {=IF(NOT(ISBLANK($A11)), (_xlfn.XLOOKUP($A11,Index!$B$2:$B$995,Index!$E$2:$E$995,"Not Found")),"")} -> n | G11: {=IF(NOT(ISBLANK(A11)), ((_xlfn.XLOOKUP(A11,Index!$B$2:$B$995,Index!$F$2:$F$995,"Not Found"))*B11),"")} -> 2 | K11: Energy | L11: =IF(NOT(ISBLANK($K$2)), SUMIFS($B$2:$B$32, $C$2:$C$32,"Energy"), "") -> 24
A12: Zapdos B3 | B12: 2 | C12: {=IF(NOT(ISBLANK($A12)), (_xlfn.XLOOKUP($A12,Index!$B$2:$B$995,Index!$C$2:$C$995,"Not Found")),"")} -> E | D12: {=IF(NOT(ISBLANK(A12)), (_xlfn.XLOOKUP($A12,Index!$B$2:B$995,Index!$A$2:$A$995,"Not Found")),"")} -> base3-15 | E12: {=IF(NOT(ISBLANK($A12)), (_xlfn.XLOOKUP($A12,Index!$B$2:$B$995,Index!$D$2:$D$995,"Not Found")),"")} -> b | F12: {=IF(NOT(ISBLANK($A12)), (_xlfn.XLOOKUP($A12,Index!$B$2:$B$995,Index!$E$2:$E$995,"Not Found")),"")} -> n | G12: {=IF(NOT(ISBLANK(A12)), ((_xlfn.XLOOKUP(A12,Index!$B$2:$B$995,Index!$F$2:$F$995,"Not Found"))*B12),"")} -> 4 | K12: Pokemon | L12: =L7 -> 20
A13: Eevee CH | B13: 1 | C13: {=IF(NOT(ISBLANK($A13)), (_xlfn.XLOOKUP($A13,Index!$B$2:$B$995,Index!$C$2:$C$995,"Not Found")),"")} -> C | D13: {=IF(NOT(ISBLANK(A13)), (_xlfn.XLOOKUP($A13,Index!$B$2:B$995,Index!$A$2:$A$995,"Not Found")),"")} -> basep-11 | E13: {=IF(NOT(ISBLANK($A13)), (_xlfn.XLOOKUP($A13,Index!$B$2:$B$995,Index!$D$2:$D$995,"Not Found")),"")} -> b | F13: {=IF(NOT(ISBLANK($A13)), (_xlfn.XLOOKUP($A13,Index!$B$2:$B$995,Index!$E$2:$E$995,"Not Found")),"")} -> y | G13: {=IF(NOT(ISBLANK(A13)), ((_xlfn.XLOOKUP(A13,Index!$B$2:$B$995,Index!$F$2:$F$995,"Not Found"))*B13),"")} -> 0.5
A14: Jolteon | B14: 2 | C14: {=IF(NOT(ISBLANK($A14)), (_xlfn.XLOOKUP($A14,Index!$B$2:$B$995,Index!$C$2:$C$995,"Not Found")),"")} -> E | D14: {=IF(NOT(ISBLANK(A14)), (_xlfn.XLOOKUP($A14,Index!$B$2:B$995,Index!$A$2:$A$995,"Not Found")),"")} -> base2-4 | E14: {=IF(NOT(ISBLANK($A14)), (_xlfn.XLOOKUP($A14,Index!$B$2:$B$995,Index!$D$2:$D$995,"Not Found")),"")} -> 1 | F14: {=IF(NOT(ISBLANK($A14)), (_xlfn.XLOOKUP($A14,Index!$B$2:$B$995,Index!$E$2:$E$995,"Not Found")),"")} -> n | G14: {=IF(NOT(ISBLANK(A14)), ((_xlfn.XLOOKUP(A14,Index!$B$2:$B$995,Index!$F$2:$F$995,"Not Found"))*B14),"")} -> 4
A15: Electabuzz | B15: 1 | C15: {=IF(NOT(ISBLANK($A15)), (_xlfn.XLOOKUP($A15,Index!$B$2:$B$995,Index!$C$2:$C$995,"Not Found")),"")} -> E | D15: {=IF(NOT(ISBLANK(A15)), (_xlfn.XLOOKUP($A15,Index!$B$2:B$995,Index!$A$2:$A$995,"Not Found")),"")} -> base1-20 | E15: {=IF(NOT(ISBLANK($A15)), (_xlfn.XLOOKUP($A15,Index!$B$2:$B$995,Index!$D$2:$D$995,"Not Found")),"")} -> b | F15: {=IF(NOT(ISBLANK($A15)), (_xlfn.XLOOKUP($A15,Index!$B$2:$B$995,Index!$E$2:$E$995,"Not Found")),"")} -> n | G15: {=IF(NOT(ISBLANK(A15)), ((_xlfn.XLOOKUP(A15,Index!$B$2:$B$995,Index!$F$2:$F$995,"Not Found"))*B15),"")} -> 1 | K15: Feature Weight:
A16: Bill | B16: 3 | C16: {=IF(NOT(ISBLANK($A16)), (_xlfn.XLOOKUP($A16,Index!$B$2:$B$995,Index!$C$2:$C$995,"Not Found")),"")} -> T | D16: {=IF(NOT(ISBLANK(A16)), (_xlfn.XLOOKUP($A16,Index!$B$2:B$995,Index!$A$2:$A$995,"Not Found")),"")} -> base1-91 | E16: {=IF(NOT(ISBLANK($A16)), (_xlfn.XLOOKUP($A16,Index!$B$2:$B$995,Index!$D$2:$D$995,"Not Found")),"")} -> c | F16: {=IF(NOT(ISBLANK($A16)), (_xlfn.XLOOKUP($A16,Index!$B$2:$B$995,Index!$E$2:$E$995,"Not Found")),"")} | G16: {=IF(NOT(ISBLANK(A16)), ((_xlfn.XLOOKUP(A16,Index!$B$2:$B$995,Index!$F$2:$F$995,"Not Found"))*B16),"")} -> #VALUE! | K16: =K2 -> E | L16: =IF(NOT(ISBLANK($K2)), SUMIFS($G$2:$G$32, $C$2:$C$32,$K2), "") -> 19
A17: Professor Oak | B17: 1 | C17: {=IF(NOT(ISBLANK($A17)), (_xlfn.XLOOKUP($A17,Index!$B$2:$B$995,Index!$C$2:$C$995,"Not Found")),"")} -> T | D17: {=IF(NOT(ISBLANK(A17)), (_xlfn.XLOOKUP($A17,Index!$B$2:B$995,Index!$A$2:$A$995,"Not Found")),"")} -> base1-88 | E17: {=IF(NOT(ISBLANK($A17)), (_xlfn.XLOOKUP($A17,Index!$B$2:$B$995,Index!$D$2:$D$995,"Not Found")),"")} -> u | F17: {=IF(NOT(ISBLANK($A17)), (_xlfn.XLOOKUP($A17,Index!$B$2:$B$995,Index!$E$2:$E$995,"Not Found")),"")} | G17: {=IF(NOT(ISBLANK(A17)), ((_xlfn.XLOOKUP(A17,Index!$B$2:$B$995,Index!$F$2:$F$995,"Not Found"))*B17),"")} -> #VALUE! | K17: =K3 -> C | L17: =IF(NOT(ISBLANK($K3)), SUMIFS($G$2:$G$32, $C$2:$C$32,$K3), "") -> 0.5
A18: Gambler | B18: 2 | C18: {=IF(NOT(ISBLANK($A18)), (_xlfn.XLOOKUP($A18,Index!$B$2:$B$995,Index!$C$2:$C$995,"Not Found")),"")} -> T | D18: {=IF(NOT(ISBLANK(A18)), (_xlfn.XLOOKUP($A18,Index!$B$2:B$995,Index!$A$2:$A$995,"Not Found")),"")} -> base3-60 | E18: {=IF(NOT(ISBLANK($A18)), (_xlfn.XLOOKUP($A18,Index!$B$2:$B$995,Index!$D$2:$D$995,"Not Found")),"")} -> c | F18: {=IF(NOT(ISBLANK($A18)), (_xlfn.XLOOKUP($A18,Index!$B$2:$B$995,Index!$E$2:$E$995,"Not Found")),"")} | G18: {=IF(NOT(ISBLANK(A18)), ((_xlfn.XLOOKUP(A18,Index!$B$2:$B$995,Index!$F$2:$F$995,"Not Found"))*B18),"")} -> #VALUE! | K18: =K4 | L18: =IF(NOT(ISBLANK($K4)), SUMIFS($G$2:$G$32, $C$2:$C$32,$K4), "")
A19: Poke Ball | B19: 2 | C19: {=IF(NOT(ISBLANK($A19)), (_xlfn.XLOOKUP($A19,Index!$B$2:$B$995,Index!$C$2:$C$995,"Not Found")),"")} -> T | D19: {=IF(NOT(ISBLANK(A19)), (_xlfn.XLOOKUP($A19,Index!$B$2:B$995,Index!$A$2:$A$995,"Not Found")),"")} -> base2-64 | E19: {=IF(NOT(ISBLANK($A19)), (_xlfn.XLOOKUP($A19,Index!$B$2:$B$995,Index!$D$2:$D$995,"Not Found")),"")} -> c | F19: {=IF(NOT(ISBLANK($A19)), (_xlfn.XLOOKUP($A19,Index!$B$2:$B$995,Index!$E$2:$E$995,"Not Found")),"")} | G19: {=IF(NOT(ISBLANK(A19)), ((_xlfn.XLOOKUP(A19,Index!$B$2:$B$995,Index!$F$2:$F$995,"Not Found"))*B19),"")} -> #VALUE! | K19: =K5 | L19: =IF(NOT(ISBLANK($K5)), SUMIFS($G$2:$G$32, $C$2:$C$32,$K5), "")
A20: Potion | B20: 1 | C20: {=IF(NOT(ISBLANK($A20)), (_xlfn.XLOOKUP($A20,Index!$B$2:$B$995,Index!$C$2:$C$995,"Not Found")),"")} -> T | D20: {=IF(NOT(ISBLANK(A20)), (_xlfn.XLOOKUP($A20,Index!$B$2:B$995,Index!$A$2:$A$995,"Not Found")),"")} -> base1-94 | E20: {=IF(NOT(ISBLANK($A20)), (_xlfn.XLOOKUP($A20,Index!$B$2:$B$995,Index!$D$2:$D$995,"Not Found")),"")} -> c | F20: {=IF(NOT(ISBLANK($A20)), (_xlfn.XLOOKUP($A20,Index!$B$2:$B$995,Index!$E$2:$E$995,"Not Found")),"")} | G20: {=IF(NOT(ISBLANK(A20)), ((_xlfn.XLOOKUP(A20,Index!$B$2:$B$995,Index!$F$2:$F$995,"Not Found"))*B20),"")} -> #VALUE! | K20: =K6
A21: Gust of Wind | B21: 2 | C21: {=IF(NOT(ISBLANK($A21)), (_xlfn.XLOOKUP($A21,Index!$B$2:$B$995,Index!$C$2:$C$995,"Not Found")),"")} -> T | D21: {=IF(NOT(ISBLANK(A21)), (_xlfn.XLOOKUP($A21,Index!$B$2:B$995,Index!$A$2:$A$995,"Not Found")),"")} -> base1-93 | E21: {=IF(NOT(ISBLANK($A21)), (_xlfn.XLOOKUP($A21,Index!$B$2:$B$995,Index!$D$2:$D$995,"Not Found")),"")} -> c | F21: {=IF(NOT(ISBLANK($A21)), (_xlfn.XLOOKUP($A21,Index!$B$2:$B$995,Index!$E$2:$E$995,"Not Found")),"")} | G21: {=IF(NOT(ISBLANK(A21)), ((_xlfn.XLOOKUP(A21,Index!$B$2:$B$995,Index!$F$2:$F$995,"Not Found"))*B21),"")} -> #VALUE! | K21: Total: | L21: =SUM(L15:L19) -> 19.5
A22: Super Energy Removal | B22: 1 | C22: {=IF(NOT(ISBLANK($A22)), (_xlfn.XLOOKUP($A22,Index!$B$2:$B$995,Index!$C$2:$C$995,"Not Found")),"")} -> T | D22: {=IF(NOT(ISBLANK(A22)), (_xlfn.XLOOKUP($A22,Index!$B$2:B$995,Index!$A$2:$A$995,"Not Found")),"")} -> base1-79 | E22: {=IF(NOT(ISBLANK($A22)), (_xlfn.XLOOKUP($A22,Index!$B$2:$B$995,Index!$D$2:$D$995,"Not Found")),"")} -> r | F22: {=IF(NOT(ISBLANK($A22)), (_xlfn.XLOOKUP($A22,Index!$B$2:$B$995,Index!$E$2:$E$995,"Not Found")),"")} | G22: {=IF(NOT(ISBLANK(A22)), ((_xlfn.XLOOKUP(A22,Index!$B$2:$B$995,Index!$F$2:$F$995,"Not Found"))*B22),"")} -> #VALUE!
A23: PlusPower | B23: 2 | C23: {=IF(NOT(ISBLANK($A23)), (_xlfn.XLOOKUP($A23,Index!$B$2:$B$995,Index!$C$2:$C$995,"Not Found")),"")} -> T | D23: {=IF(NOT(ISBLANK(A23)), (_xlfn.XLOOKUP($A23,Index!$B$2:B$995,Index!$A$2:$A$995,"Not Found")),"")} -> base1-84 | E23: {=IF(NOT(ISBLANK($A23)), (_xlfn.XLOOKUP($A23,Index!$B$2:$B$995,Index!$D$2:$D$995,"Not Found")),"")} -> u | F23: {=IF(NOT(ISBLANK($A23)), (_xlfn.XLOOKUP($A23,Index!$B$2:$B$995,Index!$E$2:$E$995,"Not Found")),"")} | G23: {=IF(NOT(ISBLANK(A23)), ((_xlfn.XLOOKUP(A23,Index!$B$2:$B$995,Index!$F$2:$F$995,"Not Found"))*B23),"")} -> #VALUE!
A24: Defender | B24: 1 | C24: {=IF(NOT(ISBLANK($A24)), (_xlfn.XLOOKUP($A24,Index!$B$2:$B$995,Index!$C$2:$C$995,"Not Found")),"")} -> T | D24: {=IF(NOT(ISBLANK(A24)), (_xlfn.XLOOKUP($A24,Index!$B$2:B$995,Index!$A$2:$A$995,"Not Found")),"")} -> base1-80 | E24: {=IF(NOT(ISBLANK($A24)), (_xlfn.XLOOKUP($A24,Index!$B$2:$B$995,Index!$D$2:$D$995,"Not Found")),"")} -> u | F24: {=IF(NOT(ISBLANK($A24)), (_xlfn.XLOOKUP($A24,Index!$B$2:$B$995,Index!$E$2:$E$995,"Not Found")),"")} | G24: {=IF(NOT(ISBLANK(A24)), ((_xlfn.XLOOKUP(A24,Index!$B$2:$B$995,Index!$F$2:$F$995,"Not Found"))*B24),"")} -> #VALUE! | K24: Cover Card: | L24: Zapdos B3
A25: Item Finder | B25: 1 | C25: {=IF(NOT(ISBLANK($A25)), (_xlfn.XLOOKUP($A25,Index!$B$2:$B$995,Index!$C$2:$C$995,"Not Found")),"")} -> T | D25: {=IF(NOT(ISBLANK(A25)), (_xlfn.XLOOKUP($A25,Index!$B$2:B$995,Index!$A$2:$A$995,"Not Found")),"")} -> base1-74 | E25: {=IF(NOT(ISBLANK($A25)), (_xlfn.XLOOKUP($A25,Index!$B$2:$B$995,Index!$D$2:$D$995,"Not Found")),"")} -> r | F25: {=IF(NOT(ISBLANK($A25)), (_xlfn.XLOOKUP($A25,Index!$B$2:$B$995,Index!$E$2:$E$995,"Not Found")),"")} | G25: {=IF(NOT(ISBLANK(A25)), ((_xlfn.XLOOKUP(A25,Index!$B$2:$B$995,Index!$F$2:$F$995,"Not Found"))*B25),"")} -> #VALUE!
A26: Eevee | B26: 2 | C26: {=IF(NOT(ISBLANK($A26)), (_xlfn.XLOOKUP($A26,Index!$B$2:$B$995,Index!$C$2:$C$995,"Not Found")),"")} -> C | D26: {=IF(NOT(ISBLANK(A26)), (_xlfn.XLOOKUP($A26,Index!$B$2:B$995,Index!$A$2:$A$995,"Not Found")),"")} -> base2-51 | E26: {=IF(NOT(ISBLANK($A26)), (_xlfn.XLOOKUP($A26,Index!$B$2:$B$995,Index!$D$2:$D$995,"Not Found")),"")} -> b | F26: {=IF(NOT(ISBLANK($A26)), (_xlfn.XLOOKUP($A26,Index!$B$2:$B$995,Index!$E$2:$E$995,"Not Found")),"")} -> y | G26: {=IF(NOT(ISBLANK(A26)), ((_xlfn.XLOOKUP(A26,Index!$B$2:$B$995,Index!$F$2:$F$995,"Not Found"))*B26),"")} -> 0
C27: {=IF(NOT(ISBLANK($A27)), (_xlfn.XLOOKUP($A27,Index!$B$2:$B$995,Index!$C$2:$C$995,"Not Found")),"")} | D27: {=IF(NOT(ISBLANK(A27)), (_xlfn.XLOOKUP($A27,Index!$B$2:B$995,Index!$A$2:$A$995,"Not Found")),"")} | E27: {=IF(NOT(ISBLANK($A27)), (_xlfn.XLOOKUP($A27,Index!$B$2:$B$995,Index!$D$2:$D$995,"Not Found")),"")} | F27: {=IF(NOT(ISBLANK($A27)), (_xlfn.XLOOKUP($A27,Index!$B$2:$B$995,Index!$E$2:$E$995,"Not Found")),"")} | G27: {=IF(NOT(ISBLANK(A27)), ((_xlfn.XLOOKUP(A27,Index!$B$2:$B$995,Index!$F$2:$F$995,"Not Found"))*B27),"")}
C28: {=IF(NOT(ISBLANK($A28)), (_xlfn.XLOOKUP($A28,Index!$B$2:$B$995,Index!$C$2:$C$995,"Not Found")),"")} | D28: {=IF(NOT(ISBLANK(A28)), (_xlfn.XLOOKUP($A28,Index!$B$2:B$995,Index!$A$2:$A$995,"Not Found")),"")} | E28: {=IF(NOT(ISBLANK($A28)), (_xlfn.XLOOKUP($A28,Index!$B$2:$B$995,Index!$D$2:$D$995,"Not Found")),"")} | F28: {=IF(NOT(ISBLANK($A28)), (_xlfn.XLOOKUP($A28,Index!$B$2:$B$995,Index!$E$2:$E$995,"Not Found")),"")} | G28: {=IF(NOT(ISBLANK(A28)), ((_xlfn.XLOOKUP(A28,Index!$B$2:$B$995,Index!$F$2:$F$995,"Not Found"))*B28),"")}
C29: {=IF(NOT(ISBLANK($A29)), (_xlfn.XLOOKUP($A29,Index!$B$2:$B$995,Index!$C$2:$C$995,"Not Found")),"")} | D29: {=IF(NOT(ISBLANK(A29)), (_xlfn.XLOOKUP($A29,Index!$B$2:B$995,Index!$A$2:$A$995,"Not Found")),"")} | E29: {=IF(NOT(ISBLANK($A29)), (_xlfn.XLOOKUP($A29,Index!$B$2:$B$995,Index!$D$2:$D$995,"Not Found")),"")} | F29: {=IF(NOT(ISBLANK($A29)), (_xlfn.XLOOKUP($A29,Index!$B$2:$B$995,Index!$E$2:$E$995,"Not Found")),"")} | G29: {=IF(NOT(ISBLANK(A29)), ((_xlfn.XLOOKUP(A29,Index!$B$2:$B$995,Index!$F$2:$F$995,"Not Found"))*B29),"")}
C30: {=IF(NOT(ISBLANK($A30)), (_xlfn.XLOOKUP($A30,Index!$B$2:$B$995,Index!$C$2:$C$995,"Not Found")),"")} | D30: {=IF(NOT(ISBLANK(A30)), (_xlfn.XLOOKUP($A30,Index!$B$2:B$995,Index!$A$2:$A$995,"Not Found")),"")} | E30: {=IF(NOT(ISBLANK($A30)), (_xlfn.XLOOKUP($A30,Index!$B$2:$B$995,Index!$D$2:$D$995,"Not Found")),"")} | F30: {=IF(NOT(ISBLANK($A30)), (_xlfn.XLOOKUP($A30,Index!$B$2:$B$995,Index!$E$2:$E$995,"Not Found")),"")} | G30: {=IF(NOT(ISBLANK(A30)), ((_xlfn.XLOOKUP(A30,Index!$B$2:$B$995,Index!$F$2:$F$995,"Not Found"))*B30),"")}
C31: {=IF(NOT(ISBLANK($A31)), (_xlfn.XLOOKUP($A31,Index!$B$2:$B$995,Index!$C$2:$C$995,"Not Found")),"")} | D31: {=IF(NOT(ISBLANK(A31)), (_xlfn.XLOOKUP($A31,Index!$B$2:B$995,Index!$A$2:$A$995,"Not Found")),"")} | E31: {=IF(NOT(ISBLANK($A31)), (_xlfn.XLOOKUP($A31,Index!$B$2:$B$995,Index!$D$2:$D$995,"Not Found")),"")} | F31: {=IF(NOT(ISBLANK($A31)), (_xlfn.XLOOKUP($A31,Index!$B$2:$B$995,Index!$E$2:$E$995,"Not Found")),"")} | G31: {=IF(NOT(ISBLANK(A31)), ((_xlfn.XLOOKUP(A31,Index!$B$2:$B$995,Index!$F$2:$F$995,"Not Found"))*B31),"")}
C32: {=IF(NOT(ISBLANK($A32)), (_xlfn.XLOOKUP($A32,Index!$B$2:$B$995,Index!$C$2:$C$995,"Not Found")),"")} | D32: {=IF(NOT(ISBLANK(A32)), (_xlfn.XLOOKUP($A32,Index!$B$2:B$995,Index!$A$2:$A$995,"Not Found")),"")} | E32: {=IF(NOT(ISBLANK($A32)), (_xlfn.XLOOKUP($A32,Index!$B$2:$B$995,Index!$D$2:$D$995,"Not Found")),"")} | F32: {=IF(NOT(ISBLANK($A32)), (_xlfn.XLOOKUP($A32,Index!$B$2:$B$995,Index!$E$2:$E$995,"Not Found")),"")} | G32: {=IF(NOT(ISBLANK(A32)), ((_xlfn.XLOOKUP(A32,Index!$B$2:$B$995,Index!$F$2:$F$995,"Not Found"))*B32),"")}
C33: {=IF(NOT(ISBLANK($A33)), (_xlfn.XLOOKUP($A33,Index!$B$2:$B$995,Index!$C$2:$C$995,"Not Found")),"")} | D33: {=IF(NOT(ISBLANK(A33)), (_xlfn.XLOOKUP($A33,Index!$B$2:B$995,Index!$A$2:$A$995,"Not Found")),"")} | E33: {=IF(NOT(ISBLANK($A33)), (_xlfn.XLOOKUP($A33,Index!$B$2:$B$995,Index!$D$2:$D$995,"Not Found")),"")} | F33: {=IF(NOT(ISBLANK($A33)), (_xlfn.XLOOKUP($A33,Index!$B$2:$B$995,Index!$E$2:$E$995,"Not Found")),"")} | G33: {=IF(NOT(ISBLANK(A33)), ((_xlfn.XLOOKUP(A33,Index!$B$2:$B$995,Index!$F$2:$F$995,"Not Found"))*B33),"")}
C34: {=IF(NOT(ISBLANK($A34)), (_xlfn.XLOOKUP($A34,Index!$B$2:$B$995,Index!$C$2:$C$995,"Not Found")),"")} | D34: {=IF(NOT(ISBLANK(A34)), (_xlfn.XLOOKUP($A34,Index!$B$2:B$995,Index!$A$2:$A$995,"Not Found")),"")} | E34: {=IF(NOT(ISBLANK($A34)), (_xlfn.XLOOKUP($A34,Index!$B$2:$B$995,Index!$D$2:$D$995,"Not Found")),"")} | F34: {=IF(NOT(ISBLANK($A34)), (_xlfn.XLOOKUP($A34,Index!$B$2:$B$995,Index!$E$2:$E$995,"Not Found")),"")} | G34: {=IF(NOT(ISBLANK(A34)), ((_xlfn.XLOOKUP(A34,Index!$B$2:$B$995,Index!$F$2:$F$995,"Not Found"))*B34),"")}
C35: {=IF(NOT(ISBLANK($A35)), (_xlfn.XLOOKUP($A35,Index!$B$2:$B$995,Index!$C$2:$C$995,"Not Found")),"")} | D35: {=IF(NOT(ISBLANK(A35)), (_xlfn.XLOOKUP($A35,Index!$B$2:B$995,Index!$A$2:$A$995,"Not Found")),"")} | E35: {=IF(NOT(ISBLANK($A35)), (_xlfn.XLOOKUP($A35,Index!$B$2:$B$995,Index!$D$2:$D$995,"Not Found")),"")} | F35: {=IF(NOT(ISBLANK($A35)), (_xlfn.XLOOKUP($A35,Index!$B$2:$B$995,Index!$E$2:$E$995,"Not Found")),"")} | G35: {=IF(NOT(ISBLANK(A35)), ((_xlfn.XLOOKUP(A35,Index!$B$2:$B$995,Index!$F$2:$F$995,"Not Found"))*B35),"")}
C36: {=IF(NOT(ISBLANK($A36)), (_xlfn.XLOOKUP($A36,Index!$B$2:$B$995,Index!$C$2:$C$995,"Not Found")),"")} | D36: {=IF(NOT(ISBLANK(A36)), (_xlfn.XLOOKUP($A36,Index!$B$2:B$995,Index!$A$2:$A$995,"Not Found")),"")} | E36: {=IF(NOT(ISBLANK($A36)), (_xlfn.XLOOKUP($A36,Index!$B$2:$B$995,Index!$D$2:$D$995,"Not Found")),"")} | F36: {=IF(NOT(ISBLANK($A36)), (_xlfn.XLOOKUP($A36,Index!$B$2:$B$995,Index!$E$2:$E$995,"Not Found")),"")} | G36: {=IF(NOT(ISBLANK(A36)), ((_xlfn.XLOOKUP(A36,Index!$B$2:$B$995,Index!$F$2:$F$995,"Not Found"))*B36),"")}
C37: {=IF(NOT(ISBLANK($A37)), (_xlfn.XLOOKUP($A37,Index!$B$2:$B$995,Index!$C$2:$C$995,"Not Found")),"")} | D37: {=IF(NOT(ISBLANK(A37)), (_xlfn.XLOOKUP($A37,Index!$B$2:B$995,Index!$A$2:$A$995,"Not Found")),"")} | E37: {=IF(NOT(ISBLANK($A37)), (_xlfn.XLOOKUP($A37,Index!$B$2:$B$995,Index!$D$2:$D$995,"Not Found")),"")} | F37: {=IF(NOT(ISBLANK($A37)), (_xlfn.XLOOKUP($A37,Index!$B$2:$B$995,Index!$E$2:$E$995,"Not Found")),"")} | G37: {=IF(NOT(ISBLANK(A37)), ((_xlfn.XLOOKUP(A37,Index!$B$2:$B$995,Index!$F$2:$F$995,"Not Found"))*B37),"")}
C38: {=IF(NOT(ISBLANK($A38)), (_xlfn.XLOOKUP($A38,Index!$B$2:$B$995,Index!$C$2:$C$995,"Not Found")),"")} | D38: {=IF(NOT(ISBLANK(A38)), (_xlfn.XLOOKUP($A38,Index!$B$2:B$995,Index!$A$2:$A$995,"Not Found")),"")} | E38: {=IF(NOT(ISBLANK($A38)), (_xlfn.XLOOKUP($A38,Index!$B$2:$B$995,Index!$D$2:$D$995,"Not Found")),"")} | F38: {=IF(NOT(ISBLANK($A38)), (_xlfn.XLOOKUP($A38,Index!$B$2:$B$995,Index!$E$2:$E$995,"Not Found")),"")} | G38: {=IF(NOT(ISBLANK(A38)), ((_xlfn.XLOOKUP(A38,Index!$B$2:$B$995,Index!$F$2:$F$995,"Not Found"))*B38),"")}
... C77: {=IF(NOT(ISBLANK($A77)), (_xlfn.XLOOKUP($A77,Index!$B$2:$B$995,Index!$C$2:$C$995,"Not Found")),"")} | D77: {=IF(NOT(ISBLANK(A77)), (_xlfn.XLOOKUP($A77,Index!$B$2:B$995,Index!$A$2:$A$995,"Not Found")),"")} | E77: {=IF(NOT(ISBLANK($A77)), (_xlfn.XLOOKUP($A77,Index!$B$2:$B$995,Index!$D$2:$D$995,"Not Found")),"")} | F77: {=IF(NOT(ISBLANK($A77)), (_xlfn.XLOOKUP($A77,Index!$B$2:$B$995,Index!$E$2:$E$995,"Not Found")),"")} | G77: {=IF(NOT(ISBLANK(A77)), ((_xlfn.XLOOKUP(A77,Index!$B$2:$B$995,Index!$F$2:$F$995,"Not Found"))*B77),"")}

Sheet Fighting
A1: Card | B1: Quantity | C1: Type | D1: ID | E1: Stage / Rarity | F1: Remaining Evo | G1: Feature Weight | I1: Card Total | K1: Type | L1: Num | M1: Basic | N1: S1 Max | O1: S1 Mid | P1: S2 | Q1: No Evolve
A2: F Energy | B2: 24 | C2: {=IF(NOT(ISBLANK($A2)), (_xlfn.XLOOKUP($A2,Index!$B$2:$B$995,Index!$C$2:$C$995,"Not Found")),"")} -> Energy | D2: {=IF(NOT(ISBLANK(A2)), (_xlfn.XLOOKUP($A2,Index!$B$2:B$995,Index!$A$2:$A$995,"Not Found")),"")} -> base1-97 | E2: {=IF(NOT(ISBLANK($A2)), (_xlfn.XLOOKUP($A2,Index!$B$2:$B$995,Index!$D$2:$D$995,"Not Found")),"")} | F2: {=IF(NOT(ISBLANK($A2)), (_xlfn.XLOOKUP($A2,Index!$B$2:$B$995,Index!$E$2:$E$995,"Not Found")),"")} | G2: {=IF(NOT(ISBLANK(A2)), ((_xlfn.XLOOKUP(A2,Index!$B$2:$B$995,Index!$F$2:$F$995,"Not Found"))*B2),"")} -> 0 | I2: =SUM(B2:B38) -> 60 | K2: F | L2: =IF(NOT(ISBLANK(K2)), SUM(M2:P2), "") -> 18 | M2: =IF(NOT(ISBLANK($K2)), SUMIFS($B$2:$B$32, $E$2:$E$32, "B", $C$2:$C$32,$K2), "") -> 12 | N2: =IF(NOT(ISBLANK($K2)),SUMIFS($B$2:$B$32,$E$2:$E$32, "1", $C$2:$C$32,$K2,$F$2:$F$32,"N"), "") -> 6 | O2: =IF(NOT(ISBLANK($K2)),SUMIFS($B$2:$B$32,$E$2:$E$32, "1", $C$2:$C$32,$K2,$F$2:$F$32,"Y"), "") -> 0 | P2: =IF(NOT(ISBLANK($K2)),SUMIFS($B$2:$B$32,$E$2:$E$32, "2", $C$2:$C$32,$K2), "") -> 0 | Q2: =IF(NOT(ISBLANK($K2)),SUMIFS($B$2:$B$32,$E$2:$E$32, "B", $C$2:$C$32,$K2,$F$2:$F$32,"N"), "") -> 6
A3: Hitmonlee | B3: 2 | C3: {=IF(NOT(ISBLANK($A3)), (_xlfn.XLOOKUP($A3,Index!$B$2:$B$995,Index!$C$2:$C$995,"Not Found")),"")} -> F | D3: {=IF(NOT(ISBLANK(A3)), (_xlfn.XLOOKUP($A3,Index!$B$2:B$995,Index!$A$2:$A$995,"Not Found")),"")} -> base3-7 | E3: {=IF(NOT(ISBLANK($A3)), (_xlfn.XLOOKUP($A3,Index!$B$2:$B$995,Index!$D$2:$D$995,"Not Found")),"")} -> b | F3: {=IF(NOT(ISBLANK($A3)), (_xlfn.XLOOKUP($A3,Index!$B$2:$B$995,Index!$E$2:$E$995,"Not Found")),"")} -> n | G3: {=IF(NOT(ISBLANK(A3)), ((_xlfn.XLOOKUP(A3,Index!$B$2:$B$995,Index!$F$2:$F$995,"Not Found"))*B3),"")} -> 2 | K3: C | L3: =IF(NOT(ISBLANK(K3)), SUM(M3:P3), "") -> 1 | M3: =IF(NOT(ISBLANK($K3)), SUMIFS($B$2:$B$32, $E$2:$E$32, "B", $C$2:$C$32,$K3), "") -> 1 | N3: =IF(NOT(ISBLANK($K3)),SUMIFS($B$2:$B$32,$E$2:$E$32, "1", $C$2:$C$32,$K3,$F$2:$F$32,"N"), "") -> 0 | O3: =IF(NOT(ISBLANK($K3)),SUMIFS($B$2:$B$32,$E$2:$E$32, "1", $C$2:$C$32,$K3,$F$2:$F$32,"Y"), "") -> 0 | P3: =IF(NOT(ISBLANK($K3)),SUMIFS($B$2:$B$32,$E$2:$E$32, "2", $C$2:$C$32,$K3), "") -> 0 | Q3: =IF(NOT(ISBLANK($K3)),SUMIFS($B$2:$B$32,$E$2:$E$32, "B", $C$2:$C$32,$K3,$F$2:$F$32,"N"), "") -> 1
