Workbook

Sheet Index
A1: ID | B1: Card | C1: Type | D1: Stage / Rarity (trainer) | E1: Remaining Evo | F1: Deck Feature Tier | G1: Opener Archetype | H1: Pressure | I1: Wants | J1: Possible CPU Deck Block? | K1: Included in opp Deck? | M1: Feature Tier Key
A2: base2-16 | B2: Wigglytuff | C2: C | D2: 1 | E2: n | F2: 3 | H2: HD, SL | I2: Many bench pokemon | K2: TRUE | M2: Not shown | N2: Not worth noting
A3: base2-24 | B3: Pidgeot NH | C3: C | D3: 2 | F3: 3 | H3: PC | K3: TRUE | M3: 1 | N3: Strategic Opener / Tank / Other utility
A4: base2-32 | B4: Wigglytuff NH | C4: C | D4: 1 | E4: n | F4: 3 | H4: HD, SL | I4: Many bench pokemon | K4: TRUE | M4: 2 | N4: Secondary Feature
A5: base2-8 | B5: Pidgeot | C5: C | D5: 2 | F5: 3 | H5: PC | K5: TRUE | M5: 3 | N5: Primary Feature
A6: base3-19 | B6: Dragonite NH | C6: C | D6: 2 | F6: 3 | H6: HD, PC | I6: To wait on the bench and use its Pokemon Power to Step In at opportune times | K6: TRUE | M6: 4 | N6: Elite Feature
A7: base3-4 | B7: Dragonite | C7: C | D7: 2 | F7: 3 | H7: HD, PC | I7: To wait on the bench and use its Pokemon Power to Step In at opportune times | K7: TRUE
A8: base2-1 | B8: Clefable | C8: C | D8: 1 | E8: n | F8: 2 | H8: HD | I8: A turn to copy a high damage opp pokemon's move | K8: TRUE
A9: base2-17 | B9: Clefable NH | C9: C | D9: 1 | E9: n | F9: 2 | H9: HD | I9: A turn to copy a high damage opp pokemon's move | K9: TRUE | M9: Tier ranking is only for last of evolution line and select useful others. Partially based in subjectivity and play experience
A10: base1-3 | B10: Chansey | C10: C | D10: b | E10: n | F10: 1.5 | G10: t | H10: WP | I10: Power up Scrunch and then tank | K10: TRUE | M10: Remaining Evo only applies to Basic and Stage 1. All stage 2 are assumed to not have evolutions remaining
A11: base2-21 | B11: Kangaskhan NH | C11: C | D11: b | E11: n | F11: 1.5 | G11: t | H11: BG | I11: To go first/stall while using Fetch. Only rarely wants to use Comet Punch | K11: TRUE | M11: Labels here are used for the lookup table on the deck tabs, but we can possibly get utility from it as well with the AI
A12: base2-5 | B12: Kangaskhan | C12: C | D12: b | E12: n | F12: 1.5 | G12: t | H12: BG | I12: To go first/stall while using Fetch. Only rarely wants to use Comet Punch | K12: TRUE | M12: Trainer rarity is used to gauge usefulness in decks
A13: base1-18 | B13: Dragonair | C13: C | D13: 1 | E13: y | F13: 1 | K13: TRUE | M13: Half steps are used. Consider those candidates for the next tier with proper support
A14: base2-11 | B14: Snorlax | C14: C | D14: b | E14: n | F14: 1 | G14: t | H14: WP | I14: To stall, not attack or retreat | K14: TRUE | M14: Opener archetypes per card are tracked. I don't know if we'll need these but it's cheap to do while going through the set anyway. Unlabeled ones should be deferred as openers when possible, but usually committed to once they're in. Based on battle utility, not whether they can evolve, etc
A15: base2-27 | B15: Snorlax NH | C15: C | D15: b | E15: n | F15: 1 | G15: t | H15: WP | I15: To stall, not attack or retreat | K15: TRUE | M15: Numbers added to the end of names is for differentiation purposes between cards with the same name. Ex: B2 means base2/Jungle
A16: base2-34 | B16: Dodrio | C16: C | D16: 1 | E16: n | F16: 1 | I16: To stay in when it takes high damage and is capable of using Rage | K16: TRUE | M16: Nonholo duplicates are tagged with NH after their name. It helps the lookup table
A17: base2-36 | B17: Fearow | C17: C | D17: 1 | E17: n | F17: 1 | H17: WP | I17: To use Agility unless Drill Peck can kill | K17: TRUE | M17: Trainer Function Key, Pressure, and Wants were added at the advice of #15 and haven't been fully applied retroactively yet
A18: base2-42 | B18: Persian | C18: C | D18: 1 | E18: n | F18: 1 | H18: WP | K18: TRUE | M18: Opener archetypes are only applied to basic pokemon here
A19: base1-5 | B19: Clefairy | C19: C | D19: b | E19: y | F19: 0.5 | K19: TRUE
A20: base2-38 | B20: Lickitung | C20: C | D20: b | E20: n | F20: 0.5 | G20: t | H20: SL | I20: An opening role | K20: TRUE
A21: base3-18 | B21: Ditto NH | C21: C | D21: b | E21: n | F21: 0.5 | I21: A low energy cost, high damage or otherwise pesky opponent to copy | K21: TRUE | M21: Opener Archetype Key:
A22: base3-3 | B22: Ditto | C22: C | D22: b | E22: n | F22: 0.5 | I22: A low energy cost, high damage or otherwise pesky opponent to copy | K22: TRUE
A23: base1-22 | B23: Pidgeotto | C23: C | D23: 1 | E23: y | K23: TRUE | M23: A | N23: Attack Opener. Openers that use stalling attacks, low damage attacks w/ high HP, or build up to damage quickly without evo. Should be weighted high for starter selection or stalling jobs, lower for retreat. Can sometimes also build up to stronger moves while stalling. Ex: Onix, Jynx
A24: base1-26 | B24: Dratini | C24: C | D24: b | E24: y | K24: TRUE | M24: T | N24: Tanks. Usually used as openers but attacks are usually defensive stalling or card drawing. Usually weighted higher than other openers. Ex: Chansey
A25: base1-27 | B25: Farfetch'd | C25: C | D25: b | E25: n | G25: a | K25: TRUE | M25: F | N25: Fallback opener. Good cheap attack option during game, not a main weapon but capable of bridging gaps. Good opener if other options aren't available. Ex: Mewtwo (1-10)
A26: base1-39 | B26: Porygon | C26: C | D26: b | E26: n | G26: a | K26: TRUE | M26: E | N26: Evo openerer. Lower weight when it comes to opening due to evolution possibility but does have stalling moves or can do damage, and should be prioritized when stalling is needed and no other options available. Higher priority if evolution exists in hand and is realistic to survive long enough to evolve. Ex: Squirtle
A27: base1-40 | B27: Raticate | C27: C | D27: 1 | E27: n | K27: TRUE | M27: N | N27: Avoid using as an opener when possible. Should be weighted lower than the baseline and possibly even switched out when other options become available. Ex: Magikarp
A28: base1-48 | B28: Doduo | C28: C | D28: b | E28: y | G28: a | K28: TRUE | M28: H | N28: HP staller. A high HP card that would normally be used as an attacker is substituted as a tank due to lack of other options. Committed to once in, not retreated or powered up unless smart to do so. A complete sacrifice. Ex: Zapdos
A29: base1-57 | B29: Pidgey | C29: C | D29: b | E29: y | K29: TRUE
A30: base1-61 | B30: Rattata | C30: C | D30: b | E30: y | K30: TRUE
A31: base2-47 | B31: Tauros | C31: C | D31: b | E31: n | G31: f | I31: To stay in and use Rampage when highly damaged | K31: TRUE
A32: base2-51 | B32: Eevee | C32: C | D32: b | E32: y | G32: e | H32: AP, SL | K32: TRUE | M32: Trainer Function Key:
A33: base2-54 | B33: Jigglypuff | C33: C | D33: b | E33: y | G33: a | H33: SL | K33: TRUE | M33: D | N33: Draw. Cards are picked up from the top of the deck
A34: base2-56 | B34: Meowth | C34: C | D34: b | E34: y | G34: a | H34: BG | I34: To go first/early and use Pay Day | K34: TRUE | M34: S | N34: Search. Search for a card in the deck
A35: base2-62 | B35: Spearow | C35: C | D35: b | E35: y | K35: TRUE | M35: P | N35: Disruption. Interferes with the opponent or the status of the board
A36: base1-9 | B36: Magneton | C36: E | D36: 1 | E36: n | F36: 2 | K36: TRUE | M36: H | N36: Heal. Removes damage from Pokemon
A37: base1-14 | B37: Raichu | C37: E | D37: 1 | E37: n | F37: 2 | K37: TRUE | M37: M | N37: Movement. Moves someone from somewhere to somewhere
A38: base1-21 | B38: Electrode | C38: E | D38: 1 | E38: n | F38: 2 | J38: y | K38: TRUE | M38: R | N38: Recovery. Removes status conditions
A39: base2-20 | B39: Jolteon NH | C39: E | D39: 1 | E39: n | F39: 2 | K39: TRUE | M39: E | N39: Exclude from baseline. Doesn't fall in with the other functions but should be excluded from baseline readings
A40: base2-4 | B40: Jolteon | C40: E | D40: 1 | E40: n | F40: 2 | K40: TRUE
...

Sheet Template
A1: Card | B1: Quantity | C1: Type | D1: ID | E1: Stage / Rarity | F1: Remaining Evo | G1: Feature Weight | I1: Card Total | K1: Type | L1: Num | M1: Basic | N1: S1 Max | O1: S1 Mid | P1: S2 | Q1: No Evolve
C2: {=IF(NOT(ISBLANK($A2)), (_xlfn.XLOOKUP($A2,Index!$B$2:$B$995,Index!$C$2:$C$995,"Not Found")),"")} | D2: {=IF(NOT(ISBLANK(A2)), (_xlfn.XLOOKUP($A2,Index!$B$2:B$995,Index!$A$2:$A$995,"Not Found")),"")} | E2: {=IF(NOT(ISBLANK($A2)), (_xlfn.XLOOKUP($A2,Index!$B$2:$B$995,Index!$D$2:$D$995,"Not Found")),"")} | F2: {=IF(NOT(ISBLANK($A2)), (_xlfn.XLOOKUP($A2,Index!$B$2:$B$995,Index!$E$2:$E$995,"Not Found")),"")} | G2: {=IF(NOT(ISBLANK(A2)), ((_xlfn.XLOOKUP(A2,Index!$B$2:$B$995,Index!$F$2:$F$995,"Not Found"))*B2),"")} | I2: =SUM(B2:B38) -> 0 | L2: =IF(NOT(ISBLANK(K2)), SUM(M2:P2), "") | M2: =IF(NOT(ISBLANK($K2)), SUMIFS($B$2:$B$32, $E$2:$E$32, "B", $C$2:$C$32,$K2), "") | N2: =IF(NOT(ISBLANK($K2)),SUMIFS($B$2:$B$32,$E$2:$E$32, "1", $C$2:$C$32,$K2,$F$2:$F$32,"N"), "") | O2: =IF(NOT(ISBLANK($K2)),SUMIFS($B$2:$B$32,$E$2:$E$32, "1", $C$2:$C$32,$K2,$F$2:$F$32,"Y"), "") | P2: =IF(NOT(ISBLANK($K2)),SUMIFS($B$2:$B$32,$E$2:$E$32, "2", $C$2:$C$32,$K2), "") | Q2: =IF(NOT(ISBLANK($K2)),SUMIFS($B$2:$B$32,$E$2:$E$32, "B", $C$2:$C$32,$K2,$F$2:$F$32,"N"), "")
C3: {=IF(NOT(ISBLANK($A3)), (_xlfn.XLOOKUP($A3,Index!$B$2:$B$995,Index!$C$2:$C$995,"Not Found")),"")} | D3: {=IF(NOT(ISBLANK(A3)), (_xlfn.XLOOKUP($A3,Index!$B$2:B$995,Index!$A$2:$A$995,"Not Found")),"")} | E3: {=IF(NOT(ISBLANK($A3)), (_xlfn.XLOOKUP($A3,Index!$B$2:$B$995,Index!$D$2:$D$995,"Not Found")),"")} | F3: {=IF(NOT(ISBLANK($A3)), (_xlfn.XLOOKUP($A3,Index!$B$2:$B$995,Index!$E$2:$E$995,"Not Found")),"")} | G3: {=IF(NOT(ISBLANK(A3)), ((_xlfn.XLOOKUP(A3,Index!$B$2:$B$995,Index!$F$2:$F$995,"Not Found"))*B3),"")} | L3: =IF(NOT(ISBLANK(K3)), SUM(M3:P3), "") | M3: =IF(NOT(ISBLANK($K3)), SUMIFS($B$2:$B$32, $E$2:$E$32, "B", $C$2:$C$32,$K3), "") | N3: =IF(NOT(ISBLANK($K3)),SUMIFS($B$2:$B$32,$E$2:$E$32, "1", $C$2:$C$32,$K3,$F$2:$F$32,"N"), "") | O3: =IF(NOT(ISBLANK($K3)),SUMIFS($B$2:$B$32,$E$2:$E$32, "1", $C$2:$C$32,$K3,$F$2:$F$32,"Y"), "") | P3: =IF(NOT(ISBLANK($K3)),SUMIFS($B$2:$B$32,$E$2:$E$32, "2", $C$2:$C$32,$K3), "") | Q3: =IF(NOT(ISBLANK($K3)),SUMIFS($B$2:$B$32,$E$2:$E$32, "B", $C$2:$C$32,$K3,$F$2:$F$32,"N"), "")
C4: {=IF(NOT(ISBLANK($A4)), (_xlfn.XLOOKUP($A4,Index!$B$2:$B$995,Index!$C$2:$C$995,"Not Found")),"")} | D4: {=IF(NOT(ISBLANK(A4)), (_xlfn.XLOOKUP($A4,Index!$B$2:B$995,Index!$A$2:$A$995,"Not Found")),"")} | E4: {=IF(NOT(ISBLANK($A4)), (_xlfn.XLOOKUP($A4,Index!$B$2:$B$995,Index!$D$2:$D$995,"Not Found")),"")} | F4: {=IF(NOT(ISBLANK($A4)), (_xlfn.XLOOKUP($A4,Index!$B$2:$B$995,Index!$E$2:$E$995,"Not Found")),"")} | G4: {=IF(NOT(ISBLANK(A4)), ((_xlfn.XLOOKUP(A4,Index!$B$2:$B$995,Index!$F$2:$F$995,"Not Found"))*B4),"")} | L4: =IF(NOT(ISBLANK(K4)), SUM(M4:P4), "") | M4: =IF(NOT(ISBLANK($K4)), SUMIFS($B$2:$B$32, $E$2:$E$32, "B", $C$2:$C$32,$K4), "") | N4: =IF(NOT(ISBLANK($K4)),SUMIFS($B$2:$B$32,$E$2:$E$32, "1", $C$2:$C$32,$K4,$F$2:$F$32,"N"), "") | O4: =IF(NOT(ISBLANK($K4)),SUMIFS($B$2:$B$32,$E$2:$E$32, "1", $C$2:$C$32,$K4,$F$2:$F$32,"Y"), "") | P4: =IF(NOT(ISBLANK($K4)),SUMIFS($B$2:$B$32,$E$2:$E$32, "2", $C$2:$C$32,$K4), "") | Q4: =IF(NOT(ISBLANK($K4)),SUMIFS($B$2:$B$32,$E$2:$E$32, "B", $C$2:$C$32,$K4,$F$2:$F$32,"N"), "")
C5: {=IF(NOT(ISBLANK($A5)), (_xlfn.XLOOKUP($A5,Index!$B$2:$B$995,Index!$C$2:$C$995,"Not Found")),"")} | D5: {=IF(NOT(ISBLANK(A5)), (_xlfn.XLOOKUP($A5,Index!$B$2:B$995,Index!$A$2:$A$995,"Not Found")),"")} | E5: {=IF(NOT(ISBLANK($A5)), (_xlfn.XLOOKUP($A5,Index!$B$2:$B$995,Index!$D$2:$D$995,"Not Found")),"")} | F5: {=IF(NOT(ISBLANK($A5)), (_xlfn.XLOOKUP($A5,Index!$B$2:$B$995,Index!$E$2:$E$995,"Not Found")),"")} | G5: {=IF(NOT(ISBLANK(A5)), ((_xlfn.XLOOKUP(A5,Index!$B$2:$B$995,Index!$F$2:$F$995,"Not Found"))*B5),"")} | L5: =IF(NOT(ISBLANK(K5)), SUM(M5:P5), "") | M5: =IF(NOT(ISBLANK($K5)), SUMIFS($B$2:$B$32, $E$2:$E$32, "B", $C$2:$C$32,$K5), "") | N5: =IF(NOT(ISBLANK($K5)),SUMIFS($B$2:$B$32,$E$2:$E$32, "1", $C$2:$C$32,$K5,$F$2:$F$32,"N"), "") | O5: =IF(NOT(ISBLANK($K5)),SUMIFS($B$2:$B$32,$E$2:$E$32, "1", $C$2:$C$32,$K5,$F$2:$F$32,"Y"), "") | P5: =IF(NOT(ISBLANK($K5)),SUMIFS($B$2:$B$32,$E$2:$E$32, "2", $C$2:$C$32,$K5), "") | Q5: =IF(NOT(ISBLANK($K5)),SUMIFS($B$2:$B$32,$E$2:$E$32, "B", $C$2:$C$32,$K5,$F$2:$F$32,"N"), "")
C6: {=IF(NOT(ISBLANK($A6)), (_xlfn.XLOOKUP($A6,Index!$B$2:$B$995,Index!$C$2:$C$995,"Not Found")),"")} | D6: {=IF(NOT(ISBLANK(A6)), (_xlfn.XLOOKUP($A6,Index!$B$2:B$995,Index!$A$2:$A$995,"Not Found")),"")} | E6: {=IF(NOT(ISBLANK($A6)), (_xlfn.XLOOKUP($A6,Index!$B$2:$B$995,Index!$D$2:$D$995,"Not Found")),"")} | F6: {=IF(NOT(ISBLANK($A6)), (_xlfn.XLOOKUP($A6,Index!$B$2:$B$995,Index!$E$2:$E$995,"Not Found")),"")} | G6: {=IF(NOT(ISBLANK(A6)), ((_xlfn.XLOOKUP(A6,Index!$B$2:$B$995,Index!$F$2:$F$995,"Not Found"))*B6),"")} | L6: =IF(NOT(ISBLANK(K6)), SUM(M6:P6), "") | M6: =IF(NOT(ISBLANK($K6)), COUNTIFS($E$2:$E$32, "B", $C$2:$C$32,$K6), "") | N6: =IF(NOT(ISBLANK(K6)),COUNTIFS($E$2:$E$32, "1", $C$2:$C$32,$K6,$F$2:$F$32,"N"), "") | O6: =IF(NOT(ISBLANK($K6)),COUNTIFS($E$2:$E$32, "1", $C$2:$C$32,$K6,$F$2:$F$32,"Y"), "") | P6: =IF(NOT(ISBLANK($K6)),COUNTIFS($E$2:$E$32, "2", $C$2:$C$32,$K6), "") | Q6: =IF(NOT(ISBLANK($K6)),COUNTIFS($E$2:$E$32, "B", $C$2:$C$32,$K6,$F$2:$F$32,"N"), "")
C7: {=IF(NOT(ISBLANK($A7)), (_xlfn.XLOOKUP($A7,Index!$B$2:$B$995,Index!$C$2:$C$995,"Not Found")),"")} | D7: {=IF(NOT(ISBLANK(A7)), (_xlfn.XLOOKUP($A7,Index!$B$2:B$995,Index!$A$2:$A$995,"Not Found")),"")} | E7: {=IF(NOT(ISBLANK($A7)), (_xlfn.XLOOKUP($A7,Index!$B$2:$B$995,Index!$D$2:$D$995,"Not Found")),"")} | F7: {=IF(NOT(ISBLANK($A7)), (_xlfn.XLOOKUP($A7,Index!$B$2:$B$995,Index!$E$2:$E$995,"Not Found")),"")} | G7: {=IF(NOT(ISBLANK(A7)), ((_xlfn.XLOOKUP(A7,Index!$B$2:$B$995,Index!$F$2:$F$995,"Not Found"))*B7),"")} | K7: Total | L7: =SUM(L2:L6) -> 0 | M7: =SUM(M2:M6) -> 0 | N7: =SUM(N2:N6) -> 0 | O7: =SUM(O2:O6) -> 0 | P7: =SUM(P2:P6) -> 0 | Q7: =SUM(Q2:Q6) -> 0
C8: {=IF(NOT(ISBLANK($A8)), (_xlfn.XLOOKUP($A8,Index!$B$2:$B$995,Index!$C$2:$C$995,"Not Found")),"")} | D8: {=IF(NOT(ISBLANK(A8)), (_xlfn.XLOOKUP($A8,Index!$B$2:B$995,Index!$A$2:$A$995,"Not Found")),"")} | E8: {=IF(NOT(ISBLANK($A8)), (_xlfn.XLOOKUP($A8,Index!$B$2:$B$995,Index!$D$2:$D$995,"Not Found")),"")} | F8: {=IF(NOT(ISBLANK($A8)), (_xlfn.XLOOKUP($A8,Index!$B$2:$B$995,Index!$E$2:$E$995,"Not Found")),"")} | G8: {=IF(NOT(ISBLANK(A8)), ((_xlfn.XLOOKUP(A8,Index!$B$2:$B$995,Index!$F$2:$F$995,"Not Found"))*B8),"")}
C9: {=IF(NOT(ISBLANK($A9)), (_xlfn.XLOOKUP($A9,Index!$B$2:$B$995,Index!$C$2:$C$995,"Not Found")),"")} | D9: {=IF(NOT(ISBLANK(A9)), (_xlfn.XLOOKUP($A9,Index!$B$2:B$995,Index!$A$2:$A$995,"Not Found")),"")} | E9: {=IF(NOT(ISBLANK($A9)), (_xlfn.XLOOKUP($A9,Index!$B$2:$B$995,Index!$D$2:$D$995,"Not Found")),"")} | F9: {=IF(NOT(ISBLANK($A9)), (_xlfn.XLOOKUP($A9,Index!$B$2:$B$995,Index!$E$2:$E$995,"Not Found")),"")} | G9: {=IF(NOT(ISBLANK(A9)), ((_xlfn.XLOOKUP(A9,Index!$B$2:$B$995,Index!$F$2:$F$995,"Not Found"))*B9),"")} | M9: Common | N9: Uncommon | O9: Rare
C10: {=IF(NOT(ISBLANK($A10)), (_xlfn.XLOOKUP($A10,Index!$B$2:$B$995,Index!$C$2:$C$995,"Not Found")),"")} | D10: {=IF(NOT(ISBLANK(A10)), (_xlfn.XLOOKUP($A10,Index!$B$2:B$995,Index!$A$2:$A$995,"Not Found")),"")} | E10: {=IF(NOT(ISBLANK($A10)), (_xlfn.XLOOKUP($A10,Index!$B$2:$B$995,Index!$D$2:$D$995,"Not Found")),"")} | F10: {=IF(NOT(ISBLANK($A10)), (_xlfn.XLOOKUP($A10,Index!$B$2:$B$995,Index!$E$2:$E$995,"Not Found")),"")} | G10: {=IF(NOT(ISBLANK(A10)), ((_xlfn.XLOOKUP(A10,Index!$B$2:$B$995,Index!$F$2:$F$995,"Not Found"))*B10),"")} | K10: Trainer | L10: =SUM(M10:P10) -> 0 | M10: =IF(NOT(ISBLANK($K10)), SUMIFS($B$2:$B$32,$E$2:$E$32, "C", $C$2:$C$32,"T"), "") -> 0 | N10: =IF(NOT(ISBLANK($K10)), SUMIFS($B$2:$B$32,$E$2:$E$32, "U", $C$2:$C$32,"T"), "") -> 0 | O10: =IF(NOT(ISBLANK($K$2)), SUMIFS($B$2:$B$32,$E$2:$E$32, "R", $C$2:$C$32,"T"), "")
C11: {=IF(NOT(ISBLANK($A11)), (_xlfn.XLOOKUP($A11,Index!$B$2:$B$995,Index!$C$2:$C$995,"Not Found")),"")} | D11: {=IF(NOT(ISBLANK(A11)), (_xlfn.XLOOKUP($A11,Index!$B$2:B$995,Index!$A$2:$A$995,"Not Found")),"")} | E11: {=IF(NOT(ISBLANK($A11)), (_xlfn.XLOOKUP($A11,Index!$B$2:$B$995,Index!$D$2:$D$995,"Not Found")),"")} | F11: {=IF(NOT(ISBLANK($A11)), (_xlfn.XLOOKUP($A11,Index!$B$2:$B$995,Index!$E$2:$E$995,"Not Found")),"")} | G11: {=IF(NOT(ISBLANK(A11)), ((_xlfn.XLOOKUP(A11,Index!$B$2:$B$995,Index!$F$2:$F$995,"Not Found"))*B11),"")} | K11: Energy | L11: =IF(NOT(ISBLANK($K$2)), SUMIFS($B$2:$B$32, $C$2:$C$32,"Energy"), "")
C12: {=IF(NOT(ISBLANK($A12)), (_xlfn.XLOOKUP($A12,Index!$B$2:$B$995,Index!$C$2:$C$995,"Not Found")),"")} | D12: {=IF(NOT(ISBLANK(A12)), (_xlfn.XLOOKUP($A12,Index!$B$2:B$995,Index!$A$2:$A$995,"Not Found")),"")} | E12: {=IF(NOT(ISBLANK($A12)), (_xlfn.XLOOKUP($A12,Index!$B$2:$B$995,Index!$D$2:$D$995,"Not Found")),"")} | F12: {=IF(NOT(ISBLANK($A12)), (_xlfn.XLOOKUP($A12,Index!$B$2:$B$995,Index!$E$2:$E$995,"Not Found")),"")} | G12: {=IF(NOT(ISBLANK(A12)), ((_xlfn.XLOOKUP(A12,Index!$B$2:$B$995,Index!$F$2:$F$995,"Not Found"))*B12),"")} | K12: Pokemon | L12: =L7 -> 0
C13: {=IF(NOT(ISBLANK($A13)), (_xlfn.XLOOKUP($A13,Index!$B$2:$B$995,Index!$C$2:$C$995,"Not Found")),"")} | D13: {=IF(NOT(ISBLANK(A13)), (_xlfn.XLOOKUP($A13,Index!$B$2:B$995,Index!$A$2:$A$995,"Not Found")),"")} | E13: {=IF(NOT(ISBLANK($A13)), (_xlfn.XLOOKUP($A13,Index!$B$2:$B$995,Index!$D$2:$D$995,"Not Found")),"")} | F13: {=IF(NOT(ISBLANK($A13)), (_xlfn.XLOOKUP($A13,Index!$B$2:$B$995,Index!$E$2:$E$995,"Not Found")),"")} | G13: {=IF(NOT(ISBLANK(A13)), ((_xlfn.XLOOKUP(A13,Index!$B$2:$B$995,Index!$F$2:$F$995,"Not Found"))*B13),"")}
C14: {=IF(NOT(ISBLANK($A14)), (_xlfn.XLOOKUP($A14,Index!$B$2:$B$995,Index!$C$2:$C$995,"Not Found")),"")} | D14: {=IF(NOT(ISBLANK(A14)), (_xlfn.XLOOKUP($A14,Index!$B$2:B$995,Index!$A$2:$A$995,"Not Found")),"")} | E14: {=IF(NOT(ISBLANK($A14)), (_xlfn.XLOOKUP($A14,Index!$B$2:$B$995,Index!$D$2:$D$995,"Not Found")),"")} | F14: {=IF(NOT(ISBLANK($A14)), (_xlfn.XLOOKUP($A14,Index!$B$2:$B$995,Index!$E$2:$E$995,"Not Found")),"")} | G14: {=IF(NOT(ISBLANK(A14)), ((_xlfn.XLOOKUP(A14,Index!$B$2:$B$995,Index!$F$2:$F$995,"Not Found"))*B14),"")}
C15: {=IF(NOT(ISBLANK($A15)), (_xlfn.XLOOKUP($A15,Index!$B$2:$B$995,Index!$C$2:$C$995,"Not Found")),"")} | D15: {=IF(NOT(ISBLANK(A15)), (_xlfn.XLOOKUP($A15,Index!$B$2:B$995,Index!$A$2:$A$995,"Not Found")),"")} | E15: {=IF(NOT(ISBLANK($A15)), (_xlfn.XLOOKUP($A15,Index!$B$2:$B$995,Index!$D$2:$D$995,"Not Found")),"")} | F15: {=IF(NOT(ISBLANK($A15)), (_xlfn.XLOOKUP($A15,Index!$B$2:$B$995,Index!$E$2:$E$995,"Not Found")),"")} | G15: {=IF(NOT(ISBLANK(A15)), ((_xlfn.XLOOKUP(A15,Index!$B$2:$B$995,Index!$F$2:$F$995,"Not Found"))*B15),"")} | K15: Feature Weight:
C16: {=IF(NOT(ISBLANK($A16)), (_xlfn.XLOOKUP($A16,Index!$B$2:$B$995,Index!$C$2:$C$995,"Not Found")),"")} | D16: {=IF(NOT(ISBLANK(A16)), (_xlfn.XLOOKUP($A16,Index!$B$2:B$995,Index!$A$2:$A$995,"Not Found")),"")} | E16: {=IF(NOT(ISBLANK($A16)), (_xlfn.XLOOKUP($A16,Index!$B$2:$B$995,Index!$D$2:$D$995,"Not Found")),"")} | F16: {=IF(NOT(ISBLANK($A16)), (_xlfn.XLOOKUP($A16,Index!$B$2:$B$995,Index!$E$2:$E$995,"Not Found")),"")} | G16: {=IF(NOT(ISBLANK(A16)), ((_xlfn.XLOOKUP(A16,Index!$B$2:$B$995,Index!$F$2:$F$995,"Not Found"))*B16),"")} | K16: =K2 | L16: =IF(NOT(ISBLANK($K2)), SUMIFS($G$2:$G$32, $C$2:$C$32,$K2), "")
C17: {=IF(NOT(ISBLANK($A17)), (_xlfn.XLOOKUP($A17,Index!$B$2:$B$995,Index!$C$2:$C$995,"Not Found")),"")} | D17: {=IF(NOT(ISBLANK(A17)), (_xlfn.XLOOKUP($A17,Index!$B$2:B$995,Index!$A$2:$A$995,"Not Found")),"")} | E17: {=IF(NOT(ISBLANK($A17)), (_xlfn.XLOOKUP($A17,Index!$B$2:$B$995,Index!$D$2:$D$995,"Not Found")),"")} | F17: {=IF(NOT(ISBLANK($A17)), (_xlfn.XLOOKUP($A17,Index!$B$2:$B$995,Index!$E$2:$E$995,"Not Found")),"")} | G17: {=IF(NOT(ISBLANK(A17)), ((_xlfn.XLOOKUP(A17,Index!$B$2:$B$995,Index!$F$2:$F$995,"Not Found"))*B17),"")} | K17: =K3 | L17: =IF(NOT(ISBLANK($K3)), SUMIFS($G$2:$G$32, $C$2:$C$32,$K3), "")
C18: {=IF(NOT(ISBLANK($A18)), (_xlfn.XLOOKUP($A18,Index!$B$2:$B$995,Index!$C$2:$C$995,"Not Found")),"")} | D18: {=IF(NOT(ISBLANK(A18)), (_xlfn.XLOOKUP($A18,Index!$B$2:B$995,Index!$A$2:$A$995,"Not Found")),"")} | E18: {=IF(NOT(ISBLANK($A18)), (_xlfn.XLOOKUP($A18,Index!$B$2:$B$995,Index!$D$2:$D$995,"Not Found")),"")} | F18: {=IF(NOT(ISBLANK($A18)), (_xlfn.XLOOKUP($A18,Index!$B$2:$B$995,Index!$E$2:$E$995,"Not Found")),"")} | G18: {=IF(NOT(ISBLANK(A18)), ((_xlfn.XLOOKUP(A18,Index!$B$2:$B$995,Index!$F$2:$F$995,"Not Found"))*B18),"")} | K18: =K4 | L18: =IF(NOT(ISBLANK($K4)), SUMIFS($G$2:$G$32, $C$2:$C$32,$K4), "")
C19: {=IF(NOT(ISBLANK($A19)), (_xlfn.XLOOKUP($A19,Index!$B$2:$B$995,Index!$C$2:$C$995,"Not Found")),"")} | D19: {=IF(NOT(ISBLANK(A19)), (_xlfn.XLOOKUP($A19,Index!$B$2:B$995,Index!$A$2:$A$995,"Not Found")),"")} | E19: {=IF(NOT(ISBLANK($A19)), (_xlfn.XLOOKUP($A19,Index!$B$2:$B$995,Index!$D$2:$D$995,"Not Found")),"")} | F19: {=IF(NOT(ISBLANK($A19)), (_xlfn.XLOOKUP($A19,Index!$B$2:$B$995,Index!$E$2:$E$995,"Not Found")),"")} | G19: {=IF(NOT(ISBLANK(A19)), ((_xlfn.XLOOKUP(A19,Index!$B$2:$B$995,Index!$F$2:$F$995,"Not Found"))*B19),"")} | K19: =K5 | L19: =IF(NOT(ISBLANK($K5)), SUMIFS($G$2:$G$32, $C$2:$C$32,$K5), "")
C20: {=IF(NOT(ISBLANK($A20)), (_xlfn.XLOOKUP($A20,Index!$B$2:$B$995,Index!$C$2:$C$995,"Not Found")),"")} | D20: {=IF(NOT(ISBLANK(A20)), (_xlfn.XLOOKUP($A20,Index!$B$2:B$995,Index!$A$2:$A$995,"Not Found")),"")} | E20: {=IF(NOT(ISBLANK($A20)), (_xlfn.XLOOKUP($A20,Index!$B$2:$B$995,Index!$D$2:$D$995,"Not Found")),"")} | F20: {=IF(NOT(ISBLANK($A20)), (_xlfn.XLOOKUP($A20,Index!$B$2:$B$995,Index!$E$2:$E$995,"Not Found")),"")} | G20: {=IF(NOT(ISBLANK(A20)), ((_xlfn.XLOOKUP(A20,Index!$B$2:$B$995,Index!$F$2:$F$995,"Not Found"))*B20),"")} | K20: =K6
C21: {=IF(NOT(ISBLANK($A21)), (_xlfn.XLOOKUP($A21,Index!$B$2:$B$995,Index!$C$2:$C$995,"Not Found")),"")} | D21: {=IF(NOT(ISBLANK(A21)), (_xlfn.XLOOKUP($A21,Index!$B$2:B$995,Index!$A$2:$A$995,"Not Found")),"")} | E21: {=IF(NOT(ISBLANK($A21)), (_xlfn.XLOOKUP($A21,Index!$B$2:$B$995,Index!$D$2:$D$995,"Not Found")),"")} | F21: {=IF(NOT(ISBLANK($A21)), (_xlfn.XLOOKUP($A21,Index!$B$2:$B$995,Index!$E$2:$E$995,"Not Found")),"")} | G21: {=IF(NOT(ISBLANK(A21)), ((_xlfn.XLOOKUP(A21,Index!$B$2:$B$995,Index!$F$2:$F$995,"Not Found"))*B21),"")} | K21: Total: | L21: =SUM(L15:L19) -> 0
C22: {=IF(NOT(ISBLANK($A22)), (_xlfn.XLOOKUP($A22,Index!$B$2:$B$995,Index!$C$2:$C$995,"Not Found")),"")} | D22: {=IF(NOT(ISBLANK(A22)), (_xlfn.XLOOKUP($A22,Index!$B$2:B$995,Index!$A$2:$A$995,"Not Found")),"")} | E22: {=IF(NOT(ISBLANK($A22)), (_xlfn.XLOOKUP($A22,Index!$B$2:$B$995,Index!$D$2:$D$995,"Not Found")),"")} | F22: {=IF(NOT(ISBLANK($A22)), (_xlfn.XLOOKUP($A22,Index!$B$2:$B$995,Index!$E$2:$E$995,"Not Found")),"")} | G22: {=IF(NOT(ISBLANK(A22)), ((_xlfn.XLOOKUP(A22,Index!$B$2:$B$995,Index!$F$2:$F$995,"Not Found"))*B22),"")}
C23: {=IF(NOT(ISBLANK($A23)), (_xlfn.XLOOKUP($A23,Index!$B$2:$B$995,Index!$C$2:$C$995,"Not Found")),"")} | D23: {=IF(NOT(ISBLANK(A23)), (_xlfn.XLOOKUP($A23,Index!$B$2:B$995,Index!$A$2:$A$995,"Not Found")),"")} | E23: {=IF(NOT(ISBLANK($A23)), (_xlfn.XLOOKUP($A23,Index!$B$2:$B$995,Index!$D$2:$D$995,"Not Found")),"")} | F23: {=IF(NOT(ISBLANK($A23)), (_xlfn.XLOOKUP($A23,Index!$B$2:$B$995,Index!$E$2:$E$995,"Not Found")),"")} | G23: {=IF(NOT(ISBLANK(A23)), ((_xlfn.XLOOKUP(A23,Index!$B$2:$B$995,Index!$F$2:$F$995,"Not Found"))*B23),"")}
C24: {=IF(NOT(ISBLANK($A24)), (_xlfn.XLOOKUP($A24,Index!$B$2:$B$995,Index!$C$2:$C$995,"Not Found")),"")} | D24: {=IF(NOT(ISBLANK(A24)), (_xlfn.XLOOKUP($A24,Index!$B$2:B$995,Index!$A$2:$A$995,"Not Found")),"")} | E24: {=IF(NOT(ISBLANK($A24)), (_xlfn.XLOOKUP($A24,Index!$B$2:$B$995,Index!$D$2:$D$995,"Not Found")),"")} | F24: {=IF(NOT(ISBLANK($A24)), (_xlfn.XLOOKUP($A24,Index!$B$2:$B$995,Index!$E$2:$E$995,"Not Found")),"")} | G24: {=IF(NOT(ISBLANK(A24)), ((_xlfn.XLOOKUP(A24,Index!$B$2:$B$995,Index!$F$2:$F$995,"Not Found"))*B24),"")} | K24: Cover Card:
C25: {=IF(NOT(ISBLANK($A25)), (_xlfn.XLOOKUP($A25,Index!$B$2:$B$995,Index!$C$2:$C$995,"Not Found")),"")} | D25: {=IF(NOT(ISBLANK(A25)), (_xlfn.XLOOKUP($A25,Index!$B$2:B$995,Index!$A$2:$A$995,"Not Found")),"")} | E25: {=IF(NOT(ISBLANK($A25)), (_xlfn.XLOOKUP($A25,Index!$B$2:$B$995,Index!$D$2:$D$995,"Not Found")),"")} | F25: {=IF(NOT(ISBLANK($A25)), (_xlfn.XLOOKUP($A25,Index!$B$2:$B$995,Index!$E$2:$E$995,"Not Found")),"")} | G25: {=IF(NOT(ISBLANK(A25)), ((_xlfn.XLOOKUP(A25,Index!$B$2:$B$995,Index!$F$2:$F$995,"Not Found"))*B25),"")}
C26: {=IF(NOT(ISBLANK($A26)), (_xlfn.XLOOKUP($A26,Index!$B$2:$B$995,Index!$C$2:$C$995,"Not Found")),"")} | D26: {=IF(NOT(ISBLANK(A26)), (_xlfn.XLOOKUP($A26,Index!$B$2:B$995,Index!$A$2:$A$995,"Not Found")),"")} | E26: {=IF(NOT(ISBLANK($A26)), (_xlfn.XLOOKUP($A26,Index!$B$2:$B$995,Index!$D$2:$D$995,"Not Found")),"")} | F26: {=IF(NOT(ISBLANK($A26)), (_xlfn.XLOOKUP($A26,Index!$B$2:$B$995,Index!$E$2:$E$995,"Not Found")),"")} | G26: {=IF(NOT(ISBLANK(A26)), ((_xlfn.XLOOKUP(A26,Index!$B$2:$B$995,Index!$F$2:$F$995,"Not Found"))*B26),"")}
C27: {=IF(NOT(ISBLANK($A27)), (_xlfn.XLOOKUP($A27,Index!$B$2:$B$995,Index!$C$2:$C$995,"Not Found")),"")} | D27: {=IF(NOT(ISBLANK(A27)), (_xlfn.XLOOKUP($A27,Index!$B$2:B$995,Index!$A$2:$A$995,"Not Found")),"")} | E27: {=IF(NOT(ISBLANK($A27)), (_xlfn.XLOOKUP($A27,Index!$B$2:$B$995,Index!$D$2:$D$995,"Not Found")),"")} | F27: {=IF(NOT(ISBLANK($A27)), (_xlfn.XLOOKUP($A27,Index!$B$2:$B$995,Index!$E$2:$E$995,"Not Found")),"")} | G27: {=IF(NOT(ISBLANK(A27)), ((_xlfn.XLOOKUP(A27,Index!$B$2:$B$995,Index!$F$2:$F$995,"Not Found"))*B27),"")}
C28: {=IF(NOT(ISBLANK($A28)), (_xlfn.XLOOKUP($A28,Index!$B$2:$B$995,Index!$C$2:$C$995,"Not Found")),"")} | D28: {=IF(NOT(ISBLANK(A28)), (_xlfn.XLOOKUP($A28,Index!$B$2:B$995,Index!$A$2:$A$995,"Not Found")),"")} | E28: {=IF(NOT(ISBLANK($A28)), (_xlfn.XLOOKUP($A28,Index!$B$2:$B$995,Index!$D$2:$D$995,"Not Found")),"")} | F28: {=IF(NOT(ISBLANK($A28)), (_xlfn.XLOOKUP($A28,Index!$B$2:$B$995,Index!$E$2:$E$995,"Not Found")),"")} | G28: {=IF(NOT(ISBLANK(A28)), ((_xlfn.XLOOKUP(A28,Index!$B$2:$B$995,Index!$F$2:$F$995,"Not Found"))*B28),"")}
C29: {=IF(NOT(ISBLANK($A29)), (_xlfn.XLOOKUP($A29,Index!$B$2:$B$995,Index!$C$2:$C$995,"Not Found")),"")} | D29: {=IF(NOT(ISBLANK(A29)), (_xlfn.XLOOKUP($A29,Index!$B$2:B$995,Index!$A$2:$A$995,"Not Found")),"")} | E29: {=IF(NOT(ISBLANK($A29)), (_xlfn.XLOOKUP($A29,Index!$B$2:$B$995,Index!$D$2:$D$995,"Not Found")),"")} | F29: {=IF(NOT(ISBLANK($A29)), (_xlfn.XLOOKUP($A29,Index!$B$2:$B$995,Index!$E$2:$E$995,"Not Found")),"")} | G29: {=IF(NOT(ISBLANK(A29)), ((_xlfn.XLOOKUP(A29,Index!$B$2:$B$995,Index!$F$2:$F$995,"Not Found"))*B29),"")}
C30: {=IF(NOT(ISBLANK($A30)), (_xlfn.XLOOKUP($A30,Index!$B$2:$B$995,Index!$C$2:$C$995,"Not Found")),"")} | D30: {=IF(NOT(ISBLANK(A30)), (_xlfn.XLOOKUP($A30,Index!$B$2:B$995,Index!$A$2:$A$995,"Not Found")),"")} | E30: {=IF(NOT(ISBLANK($A30)), (_xlfn.XLOOKUP($A30,Index!$B$2:$B$995,Index!$D$2:$D$995,"Not Found")),"")} | F30: {=IF(NOT(ISBLANK($A30)), (_xlfn.XLOOKUP($A30,Index!$B$2:$B$995,Index!$E$2:$E$995,"Not Found")),"")} | G30: {=IF(NOT(ISBLANK(A30)), ((_xlfn.XLOOKUP(A30,Index!$B$2:$B$995,Index!$F$2:$F$995,"Not Found"))*B30),"")}
C31: {=IF(NOT(ISBLANK($A31)), (_xlfn.XLOOKUP($A31,Index!$B$2:$B$995,Index!$C$2:$C$995,"Not Found")),"")} | D31: {=IF(NOT(ISBLANK(A31)), (_xlfn.XLOOKUP($A31,Index!$B$2:B$995,Index!$A$2:$A$995,"Not Found")),"")} | E31: {=IF(NOT(ISBLANK($A31)), (_xlfn.XLOOKUP($A31,Index!$B$2:$B$995,Index!$D$2:$D$995,"Not Found")),"")} | F31: {=IF(NOT(ISBLANK($A31)), (_xlfn.XLOOKUP($A31,Index!$B$2:$B$995,Index!$E$2:$E$995,"Not Found")),"")} | G31: {=IF(NOT(ISBLANK(A31)), ((_xlfn.XLOOKUP(A31,Index!$B$2:$B$995,Index!$F$2:$F$995,"Not Found"))*B31),"")}
C32: {=IF(NOT(ISBLANK($A32)), (_xlfn.XLOOKUP($A32,Index!$B$2:$B$995,Index!$C$2:$C$995,"Not Found")),"")} | D32: {=IF(NOT(ISBLANK(A32)), (_xlfn.XLOOKUP($A32,Index!$B$2:B$995,Index!$A$2:$A$995,"Not Found")),"")} | E32: {=IF(NOT(ISBLANK($A32)), (_xlfn.XLOOKUP($A32,Index!$B$2:$B$995,Index!$D$2:$D$995,"Not Found")),"")} | F32: {=IF(NOT(ISBLANK($A32)), (_xlfn.XLOOKUP($A32,Index!$B$2:$B$995,Index!$E$2:$E$995,"Not Found")),"")} | G32: {=IF(NOT(ISBLANK(A32)), ((_xlfn.XLOOKUP(A32,Index!$B$2:$B$995,Index!$F$2:$F$995,"Not Found"))*B32),"")}
C33: {=IF(NOT(ISBLANK($A33)), (_xlfn.XLOOKUP($A33,Index!$B$2:$B$995,Index!$C$2:$C$995,"Not Found")),"")} | D33: {=IF(NOT(ISBLANK(A33)), (_xlfn.XLOOKUP($A33,Index!$B$2:B$995,Index!$A$2:$A$995,"Not Found")),"")} | E33: {=IF(NOT(ISBLANK($A33)), (_xlfn.XLOOKUP($A33,Index!$B$2:$B$995,Index!$D$2:$D$995,"Not Found")),"")} | F33: {=IF(NOT(ISBLANK($A33)), (_xlfn.XLOOKUP($A33,Index!$B$2:$B$995,Index!$E$2:$E$995,"Not Found")),"")} | G33: {=IF(NOT(ISBLANK(A33)), ((_xlfn.XLOOKUP(A33,Index!$B$2:$B$995,Index!$F$2:$F$995,"Not Found"))*B33),"")}
C34: {=IF(NOT(ISBLANK($A34)), (_xlfn.XLOOKUP($A34,Index!$B$2:$B$995,Index!$C$2:$C$995,"Not Found")),"")} | D34: {=IF(NOT(ISBLANK(A34)), (_xlfn.XLOOKUP($A34,Index!$B$2:B$995,Index!$A$2:$A$995,"Not Found")),"")} | E34: {=IF(NOT(ISBLANK($A34)), (_xlfn.XLOOKUP($A34,Index!$B$2:$B$995,Index!$D$2:$D$995,"Not Found")),"")} | F34: {=IF(NOT(ISBLANK($A34)), (_xlfn.XLOOKUP($A34,Index!$B$2:$B$995,Index!$E$2:$E$995,"Not Found")),"")} | G34: {=IF(NOT(ISBLANK(A34)), ((_xlfn.XLOOKUP(A34,Index!$B$2:$B$995,Index!$F$2:$F$995,"Not Found"))*B34),"")}
C35: {=IF(NOT(ISBLANK($A35)), (_xlfn.XLOOKUP($A35,Index!$B$2:$B$995,Index!$C$2:$C$995,"Not Found")),"")} | D35: {=IF(NOT(ISBLANK(A35)), (_xlfn.XLOOKUP($A35,Index!$B$2:B$995,Index!$A$2:$A$995,"Not Found")),"")} | E35: {=IF(NOT(ISBLANK($A35)), (_xlfn.XLOOKUP($A35,Index!$B$2:$B$995,Index!$D$2:$D$995,"Not Found")),"")} | F35: {=IF(NOT(ISBLANK($A35)), (_xlfn.XLOOKUP($A35,Index!$B$2:$B$995,Index!$E$2:$E$995,"Not Found")),"")} | G35: {=IF(NOT(ISBLANK(A35)), ((_xlfn.XLOOKUP(A35,Index!$B$2:$B$995,Index!$F$2:$F$995,"Not Found"))*B35),"")}
C36: {=IF(NOT(ISBLANK($A36)), (_xlfn.XLOOKUP($A36,Index!$B$2:$B$995,Index!$C$2:$C$995,"Not Found")),"")} | D36: {=IF(NOT(ISBLANK(A36)), (_xlfn.XLOOKUP($A36,Index!$B$2:B$995,Index!$A$2:$A$995,"Not Found")),"")} | E36: {=IF(NOT(ISBLANK($A36)), (_xlfn.XLOOKUP($A36,Index!$B$2:$B$995,Index!$D$2:$D$995,"Not Found")),"")} | F36: {=IF(NOT(ISBLANK($A36)), (_xlfn.XLOOKUP($A36,Index!$B$2:$B$995,Index!$E$2:$E$995,"Not Found")),"")} | G36: {=IF(NOT(ISBLANK(A36)), ((_xlfn.XLOOKUP(A36,Index!$B$2:$B$995,Index!$F$2:$F$995,"Not Found"))*B36),"")}
... C77: {=IF(NOT(ISBLANK($A77)), (_xlfn.XLOOKUP($A77,Index!$B$2:$B$995,Index!$C$2:$C$995,"Not Found")),"")} | D77: {=IF(NOT(ISBLANK(A77)), (_xlfn.XLOOKUP($A77,Index!$B$2:B$995,Index!$A$2:$A$995,"Not Found")),"")} | E77: {=IF(NOT(ISBLANK($A77)), (_xlfn.XLOOKUP($A77,Index!$B$2:$B$995,Index!$D$2:$D$995,"Not Found")),"")} | F77: {=IF(NOT(ISBLANK($A77)), (_xlfn.XLOOKUP($A77,Index!$B$2:$B$995,Index!$E$2:$E$995,"Not Found")),"")} | G77: {=IF(NOT(ISBLANK(A77)), ((_xlfn.XLOOKUP(A77,Index!$B$2:$B$995,Index!$F$2:$F$995,"Not Found"))*B77),"")}

Sheet F T2-1
A1: Card | B1: Quantity | C1: Type | D1: ID | E1: Stage / Rarity | F1: Remaining Evo | G1: Feature Weight | I1: Card Total | K1: Type | L1: Num | M1: Basic | N1: S1 Max | O1: S1 Mid | P1: S2 | Q1: No Evolve
A2: Horsea | B2: 4 | C2: {=IF(NOT(ISBLANK($A2)), (_xlfn.XLOOKUP($A2,Index!$B$2:$B$995,Index!$C$2:$C$995,"Not Found")),"")} -> W | D2: {=IF(NOT(ISBLANK(A2)), (_xlfn.XLOOKUP($A2,Index!$B$2:B$995,Index!$A$2:$A$995,"Not Found")),"")} -> base3-49 | E2: {=IF(NOT(ISBLANK($A2)), (_xlfn.XLOOKUP($A2,Index!$B$2:$B$995,Index!$D$2:$D$995,"Not Found")),"")} -> b | F2: {=IF(NOT(ISBLANK($A2)), (_xlfn.XLOOKUP($A2,Index!$B$2:$B$995,Index!$E$2:$E$995,"Not Found")),"")} -> y | G2: {=IF(NOT(ISBLANK(A2)), ((_xlfn.XLOOKUP(A2,Index!$B$2:$B$995,Index!$F$2:$F$995,"Not Found"))*B2),"")} -> 0 | I2: =SUM(B2:B38) -> 60 | K2: W | L2: =IF(NOT(ISBLANK(K2)), SUM(M2:P2), "") -> 12 | M2: =IF(NOT(ISBLANK($K2)), SUMIFS($B$2:$B$32, $E$2:$E$32, "B", $C$2:$C$32,$K2), "") -> 8 | N2: =IF(NOT(ISBLANK($K2)),SUMIFS($B$2:$B$32,$E$2:$E$32, "1", $C$2:$C$32,$K2,$F$2:$F$32,"N"), "") -> 4 | O2: =IF(NOT(ISBLANK($K2)),SUMIFS($B$2:$B$32,$E$2:$E$32, "1", $C$2:$C$32,$K2,$F$2:$F$32,"Y"), "") -> 0 | P2: =IF(NOT(ISBLANK($K2)),SUMIFS($B$2:$B$32,$E$2:$E$32, "2", $C$2:$C$32,$K2), "") -> 0 | Q2: =IF(NOT(ISBLANK($K2)),SUMIFS($B$2:$B$32,$E$2:$E$32, "B", $C$2:$C$32,$K2,$F$2:$F$32,"N"), "") -> 1
A3: Seadra | B3: 2 | C3: {=IF(NOT(ISBLANK($A3)), (_xlfn.XLOOKUP($A3,Index!$B$2:$B$995,Index!$C$2:$C$995,"Not Found")),"")} -> W | D3: {=IF(NOT(ISBLANK(A3)), (_xlfn.XLOOKUP($A3,Index!$B$2:B$995,Index!$A$2:$A$995,"Not Found")),"")} -> base3-42 | E3: {=IF(NOT(ISBLANK($A3)), (_xlfn.XLOOKUP($A3,Index!$B$2:$B$995,Index!$D$2:$D$995,"Not Found")),"")} -> 1 | F3: {=IF(NOT(ISBLANK($A3)), (_xlfn.XLOOKUP($A3,Index!$B$2:$B$995,Index!$E$2:$E$995,"Not Found")),"")} -> n | G3: {=IF(NOT(ISBLANK(A3)), ((_xlfn.XLOOKUP(A3,Index!$B$2:$B$995,Index!$F$2:$F$995,"Not Found"))*B3),"")} -> 2 | K3: P | L3: =IF(NOT(ISBLANK(K3)), SUM(M3:P3), "") -> 9 | M3: =IF(NOT(ISBLANK($K3)), SUMIFS($B$2:$B$32, $E$2:$E$32, "B", $C$2:$C$32,$K3), "") -> 6 | N3: =IF(NOT(ISBLANK($K3)),SUMIFS($B$2:$B$32,$E$2:$E$32, "1", $C$2:$C$32,$K3,$F$2:$F$32,"N"), "") -> 3 | O3: =IF(NOT(ISBLANK($K3)),SUMIFS($B$2:$B$32,$E$2:$E$32, "1", $C$2:$C$32,$K3,$F$2:$F$32,"Y"), "") -> 0 | P3: =IF(NOT(ISBLANK($K3)),SUMIFS($B$2:$B$32,$E$2:$E$32, "2", $C$2:$C$32,$K3), "") -> 0 | Q3: =IF(NOT(ISBLANK($K3)),SUMIFS($B$2:$B$32,$E$2:$E$32, "B", $C$2:$C$32,$K3,$F$2:$F$32,"N"), "") -> 0
A4: Psyduck | B4: 3 | C4: {=IF(NOT(ISBLANK($A4)), (_xlfn.XLOOKUP($A4,Index!$B$2:$B$995,Index!$C$2:$C$995,"Not Found")),"")} -> W | D4: {=IF(NOT(ISBLANK(A4)), (_xlfn.XLOOKUP($A4,Index!$B$2:B$995,Index!$A$2:$A$995,"Not Found")),"")} -> base3-53 | E4: {=IF(NOT(ISBLANK($A4)), (_xlfn.XLOOKUP($A4,Index!$B$2:$B$995,Index!$D$2:$D$995,"Not Found")),"")} -> b | F4: {=IF(NOT(ISBLANK($A4)), (_xlfn.XLOOKUP($A4,Index!$B$2:$B$995,Index!$E$2:$E$995,"Not Found")),"")} -> y | G4: {=IF(NOT(ISBLANK(A4)), ((_xlfn.XLOOKUP(A4,Index!$B$2:$B$995,Index!$F$2:$F$995,"Not Found"))*B4),"")} -> 0 | K4: C | L4: =IF(NOT(ISBLANK(K4)), SUM(M4:P4), "") -> 1 | M4: =IF(NOT(ISBLANK($K4)), SUMIFS($B$2:$B$32, $E$2:$E$32, "B", $C$2:$C$32,$K4), "") -> 1 | N4: =IF(NOT(ISBLANK($K4)),SUMIFS($B$2:$B$32,$E$2:$E$32, "1", $C$2:$C$32,$K4,$F$2:$F$32,"N"), "") -> 0 | O4: =IF(NOT(ISBLANK($K4)),SUMIFS($B$2:$B$32,$E$2:$E$32, "1", $C$2:$C$32,$K4,$F$2:$F$32,"Y"), "") -> 0 | P4: =IF(NOT(ISBLANK($K4)),SUMIFS($B$2:$B$32,$E$2:$E$32, "2", $C$2:$C$32,$K4), "") -> 0 | Q4: =IF(NOT(ISBLANK($K4)),SUMIFS($B$2:$B$32,$E$2:$E$32, "B", $C$2:$C$32,$K4,$F$2:$F$32,"N"), "") -> 1
A5: Golduck | B5: 2 | C5: {=IF(NOT(ISBLANK($A5)), (_xlfn.XLOOKUP($A5,Index!$B$2:$B$995,Index!$C$2:$C$995,"Not Found")),"")} -> W | D5: {=IF(NOT(ISBLANK(A5)), (_xlfn.XLOOKUP($A5,Index!$B$2:B$995,Index!$A$2:$A$995,"Not Found")),"")} -> base3-35 | E5: {=IF(NOT(ISBLANK($A5)), (_xlfn.XLOOKUP($A5,Index!$B$2:$B$995,Index!$D$2:$D$995,"Not Found")),"")} -> 1 | F5: {=IF(NOT(ISBLANK($A5)), (_xlfn.XLOOKUP($A5,Index!$B$2:$B$995,Index!$E$2:$E$995,"Not Found")),"")} -> n | G5: {=IF(NOT(ISBLANK(A5)), ((_xlfn.XLOOKUP(A5,Index!$B$2:$B$995,Index!$F$2:$F$995,"Not Found"))*B5),"")} -> 3 | L5: =IF(NOT(ISBLANK(K5)), SUM(M5:P5), "") | M5: =IF(NOT(ISBLANK($K5)), SUMIFS($B$2:$B$32, $E$2:$E$32, "B", $C$2:$C$32,$K5), "") | N5: =IF(NOT(ISBLANK($K5)),SUMIFS($B$2:$B$32,$E$2:$E$32, "1", $C$2:$C$32,$K5,$F$2:$F$32,"N"), "") | O5: =IF(NOT(ISBLANK($K5)),SUMIFS($B$2:$B$32,$E$2:$E$32, "1", $C$2:$C$32,$K5,$F$2:$F$32,"Y"), "") | P5: =IF(NOT(ISBLANK($K5)),SUMIFS($B$2:$B$32,$E$2:$E$32, "2", $C$2:$C$32,$K5), "") | Q5: =IF(NOT(ISBLANK($K5)),SUMIFS($B$2:$B$32,$E$2:$E$32, "B", $C$2:$C$32,$K5,$F$2:$F$32,"N"), "")
A6: Lapras NH | B6: 1 | C6: {=IF(NOT(ISBLANK($A6)), (_xlfn.XLOOKUP($A6,Index!$B$2:$B$995,Index!$C$2:$C$995,"Not Found")),"")} -> W | D6: {=IF(NOT(ISBLANK(A6)), (_xlfn.XLOOKUP($A6,Index!$B$2:B$995,Index!$A$2:$A$995,"Not Found")),"")} -> base3-25 | E6: {=IF(NOT(ISBLANK($A6)), (_xlfn.XLOOKUP($A6,Index!$B$2:$B$995,Index!$D$2:$D$995,"Not Found")),"")} -> b | F6: {=IF(NOT(ISBLANK($A6)), (_xlfn.XLOOKUP($A6,Index!$B$2:$B$995,Index!$E$2:$E$995,"Not Found")),"")} -> n | G6: {=IF(NOT(ISBLANK(A6)), ((_xlfn.XLOOKUP(A6,Index!$B$2:$B$995,Index!$F$2:$F$995,"Not Found"))*B6),"")} -> 1 | L6: =IF(NOT(ISBLANK(K6)), SUM(M6:P6), "") | M6: =IF(NOT(ISBLANK($K6)), COUNTIFS($E$2:$E$32, "B", $C$2:$C$32,$K6), "") | N6: =IF(NOT(ISBLANK(K6)),COUNTIFS($E$2:$E$32, "1", $C$2:$C$32,$K6,$F$2:$F$32,"N"), "") | O6: =IF(NOT(ISBLANK($K6)),COUNTIFS($E$2:$E$32, "1", $C$2:$C$32,$K6,$F$2:$F$32,"Y"), "") | P6: =IF(NOT(ISBLANK($K6)),COUNTIFS($E$2:$E$32, "2", $C$2:$C$32,$K6), "") | Q6: =IF(NOT(ISBLANK($K6)),COUNTIFS($E$2:$E$32, "B", $C$2:$C$32,$K6,$F$2:$F$32,"N"), "")
A7: Slowpoke | B7: 3 | C7: {=IF(NOT(ISBLANK($A7)), (_xlfn.XLOOKUP($A7,Index!$B$2:$B$995,Index!$C$2:$C$995,"Not Found")),"")} -> P | D7: {=IF(NOT(ISBLANK(A7)), (_xlfn.XLOOKUP($A7,Index!$B$2:B$995,Index!$A$2:$A$995,"Not Found")),"")} -> base3-55 | E7: {=IF(NOT(ISBLANK($A7)), (_xlfn.XLOOKUP($A7,Index!$B$2:$B$995,Index!$D$2:$D$995,"Not Found")),"")} -> b | F7: {=IF(NOT(ISBLANK($A7)), (_xlfn.XLOOKUP($A7,Index!$B$2:$B$995,Index!$E$2:$E$995,"Not Found")),"")} -> y | G7: {=IF(NOT(ISBLANK(A7)), ((_xlfn.XLOOKUP(A7,Index!$B$2:$B$995,Index!$F$2:$F$995,"Not Found"))*B7),"")} -> 0 | K7: Total | L7: =SUM(L2:L6) -> 22 | M7: =SUM(M2:M6) -> 15 | N7: =SUM(N2:N6) -> 7 | O7: =SUM(O2:O6) -> 0 | P7: =SUM(P2:P6) -> 0 | Q7: =SUM(Q2:Q6) -> 2
A8: Slowbro | B8: 2 | C8: {=IF(NOT(ISBLANK($A8)), (_xlfn.XLOOKUP($A8,Index!$B$2:$B$995,Index!$C$2:$C$995,"Not Found")),"")} -> P | D8: {=IF(NOT(ISBLANK(A8)), (_xlfn.XLOOKUP($A8,Index!$B$2:B$995,Index!$A$2:$A$995,"Not Found")),"")} -> base3-43 | E8: {=IF(NOT(ISBLANK($A8)), (_xlfn.XLOOKUP($A8,Index!$B$2:$B$995,Index!$D$2:$D$995,"Not Found")),"")} -> 1 | F8: {=IF(NOT(ISBLANK($A8)), (_xlfn.XLOOKUP($A8,Index!$B$2:$B$995,Index!$E$2:$E$995,"Not Found")),"")} -> n | G8: {=IF(NOT(ISBLANK(A8)), ((_xlfn.XLOOKUP(A8,Index!$B$2:$B$995,Index!$F$2:$F$995,"Not Found"))*B8),"")} -> 3
A9: Drowzee | B9: 3 | C9: {=IF(NOT(ISBLANK($A9)), (_xlfn.XLOOKUP($A9,Index!$B$2:$B$995,Index!$C$2:$C$995,"Not Found")),"")} -> P | D9: {=IF(NOT(ISBLANK(A9)), (_xlfn.XLOOKUP($A9,Index!$B$2:B$995,Index!$A$2:$A$995,"Not Found")),"")} -> base1-49 | E9: {=IF(NOT(ISBLANK($A9)), (_xlfn.XLOOKUP($A9,Index!$B$2:$B$995,Index!$D$2:$D$995,"Not Found")),"")} -> b | F9: {=IF(NOT(ISBLANK($A9)), (_xlfn.XLOOKUP($A9,Index!$B$2:$B$995,Index!$E$2:$E$995,"Not Found")),"")} -> y | G9: {=IF(NOT(ISBLANK(A9)), ((_xlfn.XLOOKUP(A9,Index!$B$2:$B$995,Index!$F$2:$F$995,"Not Found"))*B9),"")} -> 0 | M9: Common | N9: Uncommon | O9: Rare
A10: Hypno NH | B10: 1 | C10: {=IF(NOT(ISBLANK($A10)), (_xlfn.XLOOKUP($A10,Index!$B$2:$B$995,Index!$C$2:$C$995,"Not Found")),"")} -> P | D10: {=IF(NOT(ISBLANK(A10)), (_xlfn.XLOOKUP($A10,Index!$B$2:B$995,Index!$A$2:$A$995,"Not Found")),"")} -> base3-23 | E10: {=IF(NOT(ISBLANK($A10)), (_xlfn.XLOOKUP($A10,Index!$B$2:$B$995,Index!$D$2:$D$995,"Not Found")),"")} -> 1 | F10: {=IF(NOT(ISBLANK($A10)), (_xlfn.XLOOKUP($A10,Index!$B$2:$B$995,Index!$E$2:$E$995,"Not Found")),"")} -> n | G10: {=IF(NOT(ISBLANK(A10)), ((_xlfn.XLOOKUP(A10,Index!$B$2:$B$995,Index!$F$2:$F$995,"Not Found"))*B10),"")} -> 2 | K10: Trainer | L10: =SUM(M10:P10) -> 10 | M10: =IF(NOT(ISBLANK($K10)), SUMIFS($B$2:$B$32,$E$2:$E$32, "C", $C$2:$C$32,"T"), "") -> 6 | N10: =IF(NOT(ISBLANK($K10)), SUMIFS($B$2:$B$32,$E$2:$E$32, "U", $C$2:$C$32,"T"), "") -> 3 | O10: =IF(NOT(ISBLANK($K$2)), SUMIFS($B$2:$B$32,$E$2:$E$32, "R", $C$2:$C$32,"T"), "") -> 1
A11: Lickitung | B11: 1 | C11: {=IF(NOT(ISBLANK($A11)), (_xlfn.XLOOKUP($A11,Index!$B$2:$B$995,Index!$C$2:$C$995,"Not Found")),"")} -> C | D11: {=IF(NOT(ISBLANK(A11)), (_xlfn.XLOOKUP($A11,Index!$B$2:B$995,Index!$A$2:$A$995,"Not Found")),"")} -> base2-38 | E11: {=IF(NOT(ISBLANK($A11)), (_xlfn.XLOOKUP($A11,Index!$B$2:$B$995,Index!$D$2:$D$995,"Not Found")),"")} -> b | F11: {=IF(NOT(ISBLANK($A11)), (_xlfn.XLOOKUP($A11,Index!$B$2:$B$995,Index!$E$2:$E$995,"Not Found")),"")} -> n | G11: {=IF(NOT(ISBLANK(A11)), ((_xlfn.XLOOKUP(A11,Index!$B$2:$B$995,Index!$F$2:$F$995,"Not Found"))*B11),"")} -> 0.5 | K11: Energy | L11: =IF(NOT(ISBLANK($K$2)), SUMIFS($B$2:$B$32, $C$2:$C$32,"Energy"), "") -> 28
A12: W Energy | B12: 16 | C12: {=IF(NOT(ISBLANK($A12)), (_xlfn.XLOOKUP($A12,Index!$B$2:$B$995,Index!$C$2:$C$995,"Not Found")),"")} -> Energy | D12: {=IF(NOT(ISBLANK(A12)), (_xlfn.XLOOKUP($A12,Index!$B$2:B$995,Index!$A$2:$A$995,"Not Found")),"")} -> base1-102 | E12: {=IF(NOT(ISBLANK($A12)), (_xlfn.XLOOKUP($A12,Index!$B$2:$B$995,Index!$D$2:$D$995,"Not Found")),"")} | F12: {=IF(NOT(ISBLANK($A12)), (_xlfn.XLOOKUP($A12,Index!$B$2:$B$995,Index!$E$2:$E$995,"Not Found")),"")} | G12: {=IF(NOT(ISBLANK(A12)), ((_xlfn.XLOOKUP(A12,Index!$B$2:$B$995,Index!$F$2:$F$995,"Not Found"))*B12),"")} -> 0 | K12: Pokemon | L12: =L7 -> 22
A13: P Energy | B13: 12 | C13: {=IF(NOT(ISBLANK($A13)), (_xlfn.XLOOKUP($A13,Index!$B$2:$B$995,Index!$C$2:$C$995,"Not Found")),"")} -> Energy | D13: {=IF(NOT(ISBLANK(A13)), (_xlfn.XLOOKUP($A13,Index!$B$2:B$995,Index!$A$2:$A$995,"Not Found")),"")} -> base1-101 | E13: {=IF(NOT(ISBLANK($A13)), (_xlfn.XLOOKUP($A13,Index!$B$2:$B$995,Index!$D$2:$D$995,"Not Found")),"")} | F13: {=IF(NOT(ISBLANK($A13)), (_xlfn.XLOOKUP($A13,Index!$B$2:$B$995,Index!$E$2:$E$995,"Not Found")),"")} | G13: {=IF(NOT(ISBLANK(A13)), ((_xlfn.XLOOKUP(A13,Index!$B$2:$B$995,Index!$F$2:$F$995,"Not Found"))*B13),"")} -> 0
A14: Energy Search | B14: 1 | C14: {=IF(NOT(ISBLANK($A14)), (_xlfn.XLOOKUP($A14,Index!$B$2:$B$995,Index!$C$2:$C$995,"Not Found")),"")} -> T | D14: {=IF(NOT(ISBLANK(A14)), (_xlfn.XLOOKUP($A14,Index!$B$2:B$995,Index!$A$2:$A$995,"Not Found")),"")} -> base3-59 | E14: {=IF(NOT(ISBLANK($A14)), (_xlfn.XLOOKUP($A14,Index!$B$2:$B$995,Index!$D$2:$D$995,"Not Found")),"")} -> c | F14: {=IF(NOT(ISBLANK($A14)), (_xlfn.XLOOKUP($A14,Index!$B$2:$B$995,Index!$E$2:$E$995,"Not Found")),"")} | G14: {=IF(NOT(ISBLANK(A14)), ((_xlfn.XLOOKUP(A14,Index!$B$2:$B$995,Index!$F$2:$F$995,"Not Found"))*B14),"")} -> #VALUE!
A15: Pokemon Trader | B15: 1 | C15: {=IF(NOT(ISBLANK($A15)), (_xlfn.XLOOKUP($A15,Index!$B$2:$B$995,Index!$C$2:$C$995,"Not Found")),"")} -> T | D15: {=IF(NOT(ISBLANK(A15)), (_xlfn.XLOOKUP($A15,Index!$B$2:B$995,Index!$A$2:$A$995,"Not Found")),"")} -> base1-77 | E15: {=IF(NOT(ISBLANK($A15)), (_xlfn.XLOOKUP($A15,Index!$B$2:$B$995,Index!$D$2:$D$995,"Not Found")),"")} -> r | F15: {=IF(NOT(ISBLANK($A15)), (_xlfn.XLOOKUP($A15,Index!$B$2:$B$995,Index!$E$2:$E$995,"Not Found")),"")} | G15: {=IF(NOT(ISBLANK(A15)), ((_xlfn.XLOOKUP(A15,Index!$B$2:$B$995,Index!$F$2:$F$995,"Not Found"))*B15),"")} -> #VALUE! | K15: Feature Weight:
A16: Super Potion | B16: 1 | C16: {=IF(NOT(ISBLANK($A16)), (_xlfn.XLOOKUP($A16,Index!$B$2:$B$995,Index!$C$2:$C$995,"Not Found")),"")} -> T | D16: {=IF(NOT(ISBLANK(A16)), (_xlfn.XLOOKUP($A16,Index!$B$2:B$995,Index!$A$2:$A$995,"Not Found")),"")} -> base1-90 | E16: {=IF(NOT(ISBLANK($A16)), (_xlfn.XLOOKUP($A16,Index!$B$2:$B$995,Index!$D$2:$D$995,"Not Found")),"")} -> u | F16: {=IF(NOT(ISBLANK($A16)), (_xlfn.XLOOKUP($A16,Index!$B$2:$B$995,Index!$E$2:$E$995,"Not Found")),"")} | G16: {=IF(NOT(ISBLANK(A16)), ((_xlfn.XLOOKUP(A16,Index!$B$2:$B$995,Index!$F$2:$F$995,"Not Found"))*B16),"")} -> #VALUE! | K16: =K2 -> W | L16: =IF(NOT(ISBLANK($K2)), SUMIFS($G$2:$G$32, $C$2:$C$32,$K2), "") -> 6
A17: Bill | B17: 2 | C17: {=IF(NOT(ISBLANK($A17)), (_xlfn.XLOOKUP($A17,Index!$B$2:$B$995,Index!$C$2:$C$995,"Not Found")),"")} -> T | D17: {=IF(NOT(ISBLANK(A17)), (_xlfn.XLOOKUP($A17,Index!$B$2:B$995,Index!$A$2:$A$995,"Not Found")),"")} -> base1-91 | E17: {=IF(NOT(ISBLANK($A17)), (_xlfn.XLOOKUP($A17,Index!$B$2:$B$995,Index!$D$2:$D$995,"Not Found")),"")} -> c | F17: {=IF(NOT(ISBLANK($A17)), (_xlfn.XLOOKUP($A17,Index!$B$2:$B$995,Index!$E$2:$E$995,"Not Found")),"")} | G17: {=IF(NOT(ISBLANK(A17)), ((_xlfn.XLOOKUP(A17,Index!$B$2:$B$995,Index!$F$2:$F$995,"Not Found"))*B17),"")} -> #VALUE! | K17: =K3 -> P | L17: =IF(NOT(ISBLANK($K3)), SUMIFS($G$2:$G$32, $C$2:$C$32,$K3), "") -> 5
A18: Professor Oak | B18: 1 | C18: {=IF(NOT(ISBLANK($A18)), (_xlfn.XLOOKUP($A18,Index!$B$2:$B$995,Index!$C$2:$C$995,"Not Found")),"")} -> T | D18: {=IF(NOT(ISBLANK(A18)), (_xlfn.XLOOKUP($A18,Index!$B$2:B$995,Index!$A$2:$A$995,"Not Found")),"")} -> base1-88 | E18: {=IF(NOT(ISBLANK($A18)), (_xlfn.XLOOKUP($A18,Index!$B$2:$B$995,Index!$D$2:$D$995,"Not Found")),"")} -> u | F18: {=IF(NOT(ISBLANK($A18)), (_xlfn.XLOOKUP($A18,Index!$B$2:$B$995,Index!$E$2:$E$995,"Not Found")),"")} | G18: {=IF(NOT(ISBLANK(A18)), ((_xlfn.XLOOKUP(A18,Index!$B$2:$B$995,Index!$F$2:$F$995,"Not Found"))*B18),"")} -> #VALUE! | K18: =K4 -> C | L18: =IF(NOT(ISBLANK($K4)), SUMIFS($G$2:$G$32, $C$2:$C$32,$K4), "") -> 0.5
A19: Poke Ball | B19: 2 | C19: {=IF(NOT(ISBLANK($A19)), (_xlfn.XLOOKUP($A19,Index!$B$2:$B$995,Index!$C$2:$C$995,"Not Found")),"")} -> T | D19: {=IF(NOT(ISBLANK(A19)), (_xlfn.XLOOKUP($A19,Index!$B$2:B$995,Index!$A$2:$A$995,"Not Found")),"")} -> base2-64 | E19: {=IF(NOT(ISBLANK($A19)), (_xlfn.XLOOKUP($A19,Index!$B$2:$B$995,Index!$D$2:$D$995,"Not Found")),"")} -> c | F19: {=IF(NOT(ISBLANK($A19)), (_xlfn.XLOOKUP($A19,Index!$B$2:$B$995,Index!$E$2:$E$995,"Not Found")),"")} | G19: {=IF(NOT(ISBLANK(A19)), ((_xlfn.XLOOKUP(A19,Index!$B$2:$B$995,Index!$F$2:$F$995,"Not Found"))*B19),"")} -> #VALUE! | K19: =K5 | L19: =IF(NOT(ISBLANK($K5)), SUMIFS($G$2:$G$32, $C$2:$C$32,$K5), "")
A20: Gust of Wind | B20: 1 | C20: {=IF(NOT(ISBLANK($A20)), (_xlfn.XLOOKUP($A20,Index!$B$2:$B$995,Index!$C$2:$C$995,"Not Found")),"")} -> T | D20: {=IF(NOT(ISBLANK(A20)), (_xlfn.XLOOKUP($A20,Index!$B$2:B$995,Index!$A$2:$A$995,"Not Found")),"")} -> base1-93 | E20: {=IF(NOT(ISBLANK($A20)), (_xlfn.XLOOKUP($A20,Index!$B$2:$B$995,Index!$D$2:$D$995,"Not Found")),"")} -> c | F20: {=IF(NOT(ISBLANK($A20)), (_xlfn.XLOOKUP($A20,Index!$B$2:$B$995,Index!$E$2:$E$995,"Not Found")),"")} | G20: {=IF(NOT(ISBLANK(A20)), ((_xlfn.XLOOKUP(A20,Index!$B$2:$B$995,Index!$F$2:$F$995,"Not Found"))*B20),"")} -> #VALUE! | K20: =K6
A21: Energy Retrieval | B21: 1 | C21: {=IF(NOT(ISBLANK($A21)), (_xlfn.XLOOKUP($A21,Index!$B$2:$B$995,Index!$C$2:$C$995,"Not Found")),"")} -> T | D21: {=IF(NOT(ISBLANK(A21)), (_xlfn.XLOOKUP($A21,Index!$B$2:B$995,Index!$A$2:$A$995,"Not Found")),"")} -> base1-81 | E21: {=IF(NOT(ISBLANK($A21)), (_xlfn.XLOOKUP($A21,Index!$B$2:$B$995,Index!$D$2:$D$995,"Not Found")),"")} -> u | F21: {=IF(NOT(ISBLANK($A21)), (_xlfn.XLOOKUP($A21,Index!$B$2:$B$995,Index!$E$2:$E$995,"Not Found")),"")} | G21: {=IF(NOT(ISBLANK(A21)), ((_xlfn.XLOOKUP(A21,Index!$B$2:$B$995,Index!$F$2:$F$995,"Not Found"))*B21),"")} -> #VALUE! | K21: Total: | L21: =SUM(L15:L19) -> 11.5
C22: {=IF(NOT(ISBLANK($A22)), (_xlfn.XLOOKUP($A22,Index!$B$2:$B$995,Index!$C$2:$C$995,"Not Found")),"")} | D22: {=IF(NOT(ISBLANK(A22)), (_xlfn.XLOOKUP($A22,Index!$B$2:B$995,Index!$A$2:$A$995,"Not Found")),"")} | E22: {=IF(NOT(ISBLANK($A22)), (_xlfn.XLOOKUP($A22,Index!$B$2:$B$995,Index!$D$2:$D$995,"Not Found")),"")} | F22: {=IF(NOT(ISBLANK($A22)), (_xlfn.XLOOKUP($A22,Index!$B$2:$B$995,Index!$E$2:$E$995,"Not Found")),"")} | G22: {=IF(NOT(ISBLANK(A22)), ((_xlfn.XLOOKUP(A22,Index!$B$2:$B$995,Index!$F$2:$F$995,"Not Found"))*B22),"")}
C23: {=IF(NOT(ISBLANK($A23)), (_xlfn.XLOOKUP($A23,Index!$B$2:$B$995,Index!$C$2:$C$995,"Not Found")),"")} | D23: {=IF(NOT(ISBLANK(A23)), (_xlfn.XLOOKUP($A23,Index!$B$2:B$995,Index!$A$2:$A$995,"Not Found")),"")} | E23: {=IF(NOT(ISBLANK($A23)), (_xlfn.XLOOKUP($A23,Index!$B$2:$B$995,Index!$D$2:$D$995,"Not Found")),"")} | F23: {=IF(NOT(ISBLANK($A23)), (_xlfn.XLOOKUP($A23,Index!$B$2:$B$995,Index!$E$2:$E$995,"Not Found")),"")} | G23: {=IF(NOT(ISBLANK(A23)), ((_xlfn.XLOOKUP(A23,Index!$B$2:$B$995,Index!$F$2:$F$995,"Not Found"))*B23),"")}
C24: {=IF(NOT(ISBLANK($A24)), (_xlfn.XLOOKUP($A24,Index!$B$2:$B$995,Index!$C$2:$C$995,"Not Found")),"")} | D24: {=IF(NOT(ISBLANK(A24)), (_xlfn.XLOOKUP($A24,Index!$B$2:B$995,Index!$A$2:$A$995,"Not Found")),"")} | E24: {=IF(NOT(ISBLANK($A24)), (_xlfn.XLOOKUP($A24,Index!$B$2:$B$995,Index!$D$2:$D$995,"Not Found")),"")} | F24: {=IF(NOT(ISBLANK($A24)), (_xlfn.XLOOKUP($A24,Index!$B$2:$B$995,Index!$E$2:$E$995,"Not Found")),"")} | G24: {=IF(NOT(ISBLANK(A24)), ((_xlfn.XLOOKUP(A24,Index!$B$2:$B$995,Index!$F$2:$F$995,"Not Found"))*B24),"")} | K24: Cover Card: | L24: Omastar
C25: {=IF(NOT(ISBLANK($A25)), (_xlfn.XLOOKUP($A25,Index!$B$2:$B$995,Index!$C$2:$C$995,"Not Found")),"")} | D25: {=IF(NOT(ISBLANK(A25)), (_xlfn.XLOOKUP($A25,Index!$B$2:B$995,Index!$A$2:$A$995,"Not Found")),"")} | E25: {=IF(NOT(ISBLANK($A25)), (_xlfn.XLOOKUP($A25,Index!$B$2:$B$995,Index!$D$2:$D$995,"Not Found")),"")} | F25: {=IF(NOT(ISBLANK($A25)), (_xlfn.XLOOKUP($A25,Index!$B$2:$B$995,Index!$E$2:$E$995,"Not Found")),"")} | G25: {=IF(NOT(ISBLANK(A25)), ((_xlfn.XLOOKUP(A25,Index!$B$2:$B$995,Index!$F$2:$F$995,"Not Found"))*B25),"")}
C26: {=IF(NOT(ISBLANK($A26)), (_xlfn.XLOOKUP($A26,Index!$B$2:$B$995,Index!$C$2:$C$995,"Not Found")),"")} | D26: {=IF(NOT(ISBLANK(A26)), (_xlfn.XLOOKUP($A26,Index!$B$2:B$995,Index!$A$2:$A$995,"Not Found")),"")} | E26: {=IF(NOT(ISBLANK($A26)), (_xlfn.XLOOKUP($A26,Index!$B$2:$B$995,Index!$D$2:$D$995,"Not Found")),"")} | F26: {=IF(NOT(ISBLANK($A26)), (_xlfn.XLOOKUP($A26,Index!$B$2:$B$995,Index!$E$2:$E$995,"Not Found")),"")} | G26: {=IF(NOT(ISBLANK(A26)), ((_xlfn.XLOOKUP(A26,Index!$B$2:$B$995,Index!$F$2:$F$995,"Not Found"))*B26),"")}
C27: {=IF(NOT(ISBLANK($A27)), (_xlfn.XLOOKUP($A27,Index!$B$2:$B$995,Index!$C$2:$C$995,"Not Found")),"")} | D27: {=IF(NOT(ISBLANK(A27)), (_xlfn.XLOOKUP($A27,Index!$B$2:B$995,Index!$A$2:$A$995,"Not Found")),"")} | E27: {=IF(NOT(ISBLANK($A27)), (_xlfn.XLOOKUP($A27,Index!$B$2:$B$995,Index!$D$2:$D$995,"Not Found")),"")} | F27: {=IF(NOT(ISBLANK($A27)), (_xlfn.XLOOKUP($A27,Index!$B$2:$B$995,Index!$E$2:$E$995,"Not Found")),"")} | G27: {=IF(NOT(ISBLANK(A27)), ((_xlfn.XLOOKUP(A27,Index!$B$2:$B$995,Index!$F$2:$F$995,"Not Found"))*B27),"")}
C28: {=IF(NOT(ISBLANK($A28)), (_xlfn.XLOOKUP($A28,Index!$B$2:$B$995,Index!$C$2:$C$995,"Not Found")),"")} | D28: {=IF(NOT(ISBLANK(A28)), (_xlfn.XLOOKUP($A28,Index!$B$2:B$995,Index!$A$2:$A$995,"Not Found")),"")} | E28: {=IF(NOT(ISBLANK($A28)), (_xlfn.XLOOKUP($A28,Index!$B$2:$B$995,Index!$D$2:$D$995,"Not Found")),"")} | F28: {=IF(NOT(ISBLANK($A28)), (_xlfn.XLOOKUP($A28,Index!$B$2:$B$995,Index!$E$2:$E$995,"Not Found")),"")} | G28: {=IF(NOT(ISBLANK(A28)), ((_xlfn.XLOOKUP(A28,Index!$B$2:$B$995,Index!$F$2:$F$995,"Not Found"))*B28),"")}
C29: {=IF(NOT(ISBLANK($A29)), (_xlfn.XLOOKUP($A29,Index!$B$2:$B$995,Index!$C$2:$C$995,"Not Found")),"")} | D29: {=IF(NOT(ISBLANK(A29)), (_xlfn.XLOOKUP($A29,Index!$B$2:B$995,Index!$A$2:$A$995,"Not Found")),"")} | E29: {=IF(NOT(ISBLANK($A29)), (_xlfn.XLOOKUP($A29,Index!$B$2:$B$995,Index!$D$2:$D$995,"Not Found")),"")} | F29: {=IF(NOT(ISBLANK($A29)), (_xlfn.XLOOKUP($A29,Index!$B$2:$B$995,Index!$E$2:$E$995,"Not Found")),"")} | G29: {=IF(NOT(ISBLANK(A29)), ((_xlfn.XLOOKUP(A29,Index!$B$2:$B$995,Index!$F$2:$F$995,"Not Found"))*B29),"")}
C30: {=IF(NOT(ISBLANK($A30)), (_xlfn.XLOOKUP($A30,Index!$B$2:$B$995,Index!$C$2:$C$995,"Not Found")),"")} | D30: {=IF(NOT(ISBLANK(A30)), (_xlfn.XLOOKUP($A30,Index!$B$2:B$995,Index!$A$2:$A$995,"Not Found")),"")} | E30: {=IF(NOT(ISBLANK($A30)), (_xlfn.XLOOKUP($A30,Index!$B$2:$B$995,Index!$D$2:$D$995,"Not Found")),"")} | F30: {=IF(NOT(ISBLANK($A30)), (_xlfn.XLOOKUP($A30,Index!$B$2:$B$995,Index!$E$2:$E$995,"Not Found")),"")} | G30: {=IF(NOT(ISBLANK(A30)), ((_xlfn.XLOOKUP(A30,Index!$B$2:$B$995,Index!$F$2:$F$995,"Not Found"))*B30),"")}
C31: {=IF(NOT(ISBLANK($A31)), (_xlfn.XLOOKUP($A31,Index!$B$2:$B$995,Index!$C$2:$C$995,"Not Found")),"")} | D31: {=IF(NOT(ISBLANK(A31)), (_xlfn.XLOOKUP($A31,Index!$B$2:B$995,Index!$A$2:$A$995,"Not Found")),"")} | E31: {=IF(NOT(ISBLANK($A31)), (_xlfn.XLOOKUP($A31,Index!$B$2:$B$995,Index!$D$2:$D$995,"Not Found")),"")} | F31: {=IF(NOT(ISBLANK($A31)), (_xlfn.XLOOKUP($A31,Index!$B$2:$B$995,Index!$E$2:$E$995,"Not Found")),"")} | G31: {=IF(NOT(ISBLANK(A31)), ((_xlfn.XLOOKUP(A31,Index!$B$2:$B$995,Index!$F$2:$F$995,"Not Found"))*B31),"")}
C32: {=IF(NOT(ISBLANK($A32)), (_xlfn.XLOOKUP($A32,Index!$B$2:$B$995,Index!$C$2:$C$995,"Not Found")),"")} | D32: {=IF(NOT(ISBLANK(A32)), (_xlfn.XLOOKUP($A32,Index!$B$2:B$995,Index!$A$2:$A$995,"Not Found")),"")} | E32: {=IF(NOT(ISBLANK($A32)), (_xlfn.XLOOKUP($A32,Index!$B$2:$B$995,Index!$D$2:$D$995,"Not Found")),"")} | F32: {=IF(NOT(ISBLANK($A32)), (_xlfn.XLOOKUP($A32,Index!$B$2:$B$995,Index!$E$2:$E$995,"Not Found")),"")} | G32: {=IF(NOT(ISBLANK(A32)), ((_xlfn.XLOOKUP(A32,Index!$B$2:$B$995,Index!$F$2:$F$995,"Not Found"))*B32),"")}
C33: {=IF(NOT(ISBLANK($A33)), (_xlfn.XLOOKUP($A33,Index!$B$2:$B$995,Index!$C$2:$C$995,"Not Found")),"")} | D33: {=IF(NOT(ISBLANK(A33)), (_xlfn.XLOOKUP($A33,Index!$B$2:B$995,Index!$A$2:$A$995,"Not Found")),"")} | E33: {=IF(NOT(ISBLANK($A33)), (_xlfn.XLOOKUP($A33,Index!$B$2:$B$995,Index!$D$2:$D$995,"Not Found")),"")} | F33: {=IF(NOT(ISBLANK($A33)), (_xlfn.XLOOKUP($A33,Index!$B$2:$B$995,Index!$E$2:$E$995,"Not Found")),"")} | G33: {=IF(NOT(ISBLANK(A33)), ((_xlfn.XLOOKUP(A33,Index!$B$2:$B$995,Index!$F$2:$F$995,"Not Found"))*B33),"")}
C34: {=IF(NOT(ISBLANK($A34)), (_xlfn.XLOOKUP($A34,Index!$B$2:$B$995,Index!$C$2:$C$995,"Not Found")),"")} | D34: {=IF(NOT(ISBLANK(A34)), (_xlfn.XLOOKUP($A34,Index!$B$2:B$995,Index!$A$2:$A$995,"Not Found")),"")} | E34: {=IF(NOT(ISBLANK($A34)), (_xlfn.XLOOKUP($A34,Index!$B$2:$B$995,Index!$D$2:$D$995,"Not Found")),"")} | F34: {=IF(NOT(ISBLANK($A34)), (_xlfn.XLOOKUP($A34,Index!$B$2:$B$995,Index!$E$2:$E$995,"Not Found")),"")} | G34: {=IF(NOT(ISBLANK(A34)), ((_xlfn.XLOOKUP(A34,Index!$B$2:$B$995,Index!$F$2:$F$995,"Not Found"))*B34),"")}
C35: {=IF(NOT(ISBLANK($A35)), (_xlfn.XLOOKUP($A35,Index!$B$2:$B$995,Index!$C$2:$C$995,"Not Found")),"")} | D35: {=IF(NOT(ISBLANK(A35)), (_xlfn.XLOOKUP($A35,Index!$B$2:B$995,Index!$A$2:$A$995,"Not Found")),"")} | E35: {=IF(NOT(ISBLANK($A35)), (_xlfn.XLOOKUP($A35,Index!$B$2:$B$995,Index!$D$2:$D$995,"Not Found")),"")} | F35: {=IF(NOT(ISBLANK($A35)), (_xlfn.XLOOKUP($A35,Index!$B$2:$B$995,Index!$E$2:$E$995,"Not Found")),"")} | G35: {=IF(NOT(ISBLANK(A35)), ((_xlfn.XLOOKUP(A35,Index!$B$2:$B$995,Index!$F$2:$F$995,"Not Found"))*B35),"")}
C36: {=IF(NOT(ISBLANK($A36)), (_xlfn.XLOOKUP($A36,Index!$B$2:$B$995,Index!$C$2:$C$995,"Not Found")),"")} | D36: {=IF(NOT(ISBLANK(A36)), (_xlfn.XLOOKUP($A36,Index!$B$2:B$995,Index!$A$2:$A$995,"Not Found")),"")} | E36: {=IF(NOT(ISBLANK($A36)), (_xlfn.XLOOKUP($A36,Index!$B$2:$B$995,Index!$D$2:$D$995,"Not Found")),"")} | F36: {=IF(NOT(ISBLANK($A36)), (_xlfn.XLOOKUP($A36,Index!$B$2:$B$995,Index!$E$2:$E$995,"Not Found")),"")} | G36: {=IF(NOT(ISBLANK(A36)), ((_xlfn.XLOOKUP(A36,Index!$B$2:$B$995,Index!$F$2:$F$995,"Not Found"))*B36),"")}
... C77: {=IF(NOT(ISBLANK($A77)), (_xlfn.XLOOKUP($A77,Index!$B$2:$B$995,Index!$C$2:$C$995,"Not Found")),"")} | D77: {=IF(NOT(ISBLANK(A77)), (_xlfn.XLOOKUP($A77,Index!$B$2:B$995,Index!$A$2:$A$995,"Not Found")),"")} | E77: {=IF(NOT(ISBLANK($A77)), (_xlfn.XLOOKUP($A77,Index!$B$2:$B$995,Index!$D$2:$D$995,"Not Found")),"")} | F77: {=IF(NOT(ISBLANK($A77)), (_xlfn.XLOOKUP($A77,Index!$B$2:$B$995,Index!$E$2:$E$995,"Not Found")),"")} | G77: {=IF(NOT(ISBLANK(A77)), ((_xlfn.XLOOKUP(A77,Index!$B$2:$B$995,Index!$F$2:$F$995,"Not Found"))*B77),"")}

Sheet F T2-2
A1: Card | B1: Quantity | C1: Type | D1: ID | E1: Stage / Rarity | F1: Remaining Evo | G1: Feature Weight | I1: Card Total | K1: Type | L1: Num | M1: Basic | N1: S1 Max | O1: S1 Mid | P1: S2 | Q1: No Evolve
A2: Geodude | B2: 4 | C2: {=IF(NOT(ISBLANK($A2)), (_xlfn.XLOOKUP($A2,Index!$B$2:$B$995,Index!$C$2:$C$995,"Not Found")),"")} -> F | D2: {=IF(NOT(ISBLANK(A2)), (_xlfn.XLOOKUP($A2,Index!$B$2:B$995,Index!$A$2:$A$995,"Not Found")),"")} -> base3-47 | E2: {=IF(NOT(ISBLANK($A2)), (_xlfn.XLOOKUP($A2,Index!$B$2:$B$995,Index!$D$2:$D$995,"Not Found")),"")} -> b | F2: {=IF(NOT(ISBLANK($A2)), (_xlfn.XLOOKUP($A2,Index!$B$2:$B$995,Index!$E$2:$E$995,"Not Found")),"")} -> y | G2: {=IF(NOT(ISBLANK(A2)), ((_xlfn.XLOOKUP(A2,Index!$B$2:$B$995,Index!$F$2:$F$995,"Not Found"))*B2),"")} -> 0 | I2: =SUM(B2:B38) -> 60 | K2: F | L2: =IF(NOT(ISBLANK(K2)), SUM(M2:P2), "") -> 12 | M2: =IF(NOT(ISBLANK($K2)), SUMIFS($B$2:$B$32, $E$2:$E$32, "B", $C$2:$C$32,$K2), "") -> 8 | N2: =IF(NOT(ISBLANK($K2)),SUMIFS($B$2:$B$32,$E$2:$E$32, "1", $C$2:$C$32,$K2,$F$2:$F$32,"N"), "") -> 0 | O2: =IF(NOT(ISBLANK($K2)),SUMIFS($B$2:$B$32,$E$2:$E$32, "1", $C$2:$C$32,$K2,$F$2:$F$32,"Y"), "") -> 3 | P2: =IF(NOT(ISBLANK($K2)),SUMIFS($B$2:$B$32,$E$2:$E$32, "2", $C$2:$C$32,$K2), "") -> 1 | Q2: =IF(NOT(ISBLANK($K2)),SUMIFS($B$2:$B$32,$E$2:$E$32, "B", $C$2:$C$32,$K2,$F$2:$F$32,"N"), "") -> 4
A3: Graveler | B3: 3 | C3: {=IF(NOT(ISBLANK($A3)), (_xlfn.XLOOKUP($A3,Index!$B$2:$B$995,Index!$C$2:$C$995,"Not Found")),"")} -> F | D3: {=IF(NOT(ISBLANK(A3)), (_xlfn.XLOOKUP($A3,Index!$B$2:B$995,Index!$A$2:$A$995,"Not Found")),"")} -> base3-37 | E3: {=IF(NOT(ISBLANK($A3)), (_xlfn.XLOOKUP($A3,Index!$B$2:$B$995,Index!$D$2:$D$995,"Not Found")),"")} -> 1 | F3: {=IF(NOT(ISBLANK($A3)), (_xlfn.XLOOKUP($A3,Index!$B$2:$B$995,Index!$E$2:$E$995,"Not Found")),"")} -> y | G3: {=IF(NOT(ISBLANK(A3)), ((_xlfn.XLOOKUP(A3,Index!$B$2:$B$995,Index!$F$2:$F$995,"Not Found"))*B3),"")} -> 0 | K3: E | L3: =IF(NOT(ISBLANK(K3)), SUM(M3:P3), "") -> 6 | M3: =IF(NOT(ISBLANK($K3)), SUMIFS($B$2:$B$32, $E$2:$E$32, "B", $C$2:$C$32,$K3), "") -> 4 | N3: =IF(NOT(ISBLANK($K3)),SUMIFS($B$2:$B$32,$E$2:$E$32, "1", $C$2:$C$32,$K3,$F$2:$F$32,"N"), "") -> 2 | O3: =IF(NOT(ISBLANK($K3)),SUMIFS($B$2:$B$32,$E$2:$E$32, "1", $C$2:$C$32,$K3,$F$2:$F$32,"Y"), "") -> 0 | P3: =IF(NOT(ISBLANK($K3)),SUMIFS($B$2:$B$32,$E$2:$E$32, "2", $C$2:$C$32,$K3), "") -> 0 | Q3: =IF(NOT(ISBLANK($K3)),SUMIFS($B$2:$B$32,$E$2:$E$32, "B", $C$2:$C$32,$K3,$F$2:$F$32,"N"), "") -> 1
A4: Golem | B4: 1 | C4: {=IF(NOT(ISBLANK($A4)), (_xlfn.XLOOKUP($A4,Index!$B$2:$B$995,Index!$C$2:$C$995,"Not Found")),"")} -> F | D4: {=IF(NOT(ISBLANK(A4)), (_xlfn.XLOOKUP($A4,Index!$B$2:B$995,Index!$A$2:$A$995,"Not Found")),"")} -> base3-36 | E4: {=IF(NOT(ISBLANK($A4)), (_xlfn.XLOOKUP($A4,Index!$B$2:$B$995,Index!$D$2:$D$995,"Not Found")),"")} -> 2 | F4: {=IF(NOT(ISBLANK($A4)), (_xlfn.XLOOKUP($A4,Index!$B$2:$B$995,Index!$E$2:$E$995,"Not Found")),"")} | G4: {=IF(NOT(ISBLANK(A4)), ((_xlfn.XLOOKUP(A4,Index!$B$2:$B$995,Index!$F$2:$F$995,"Not Found"))*B4),"")} -> 3 | K4: C | L4: =IF(NOT(ISBLANK(K4)), SUM(M4:P4), "") -> 4 | M4: =IF(NOT(ISBLANK($K4)), SUMIFS($B$2:$B$32, $E$2:$E$32, "B", $C$2:$C$32,$K4), "") -> 3 | N4: =IF(NOT(ISBLANK($K4)),SUMIFS($B$2:$B$32,$E$2:$E$32, "1", $C$2:$C$32,$K4,$F$2:$F$32,"N"), "") -> 1 | O4: =IF(NOT(ISBLANK($K4)),SUMIFS($B$2:$B$32,$E$2:$E$32, "1", $C$2:$C$32,$K4,$F$2:$F$32,"Y"), "") -> 0 | P4: =IF(NOT(ISBLANK($K4)),SUMIFS($B$2:$B$32,$E$2:$E$32, "2", $C$2:$C$32,$K4), "") -> 0 | Q4: =IF(NOT(ISBLANK($K4)),SUMIFS($B$2:$B$32,$E$2:$E$32, "B", $C$2:$C$32,$K4,$F$2:$F$32,"N"), "") -> 1
A5: Hitmonlee NH | B5: 1 | C5: {=IF(NOT(ISBLANK($A5)), (_xlfn.XLOOKUP($A5,Index!$B$2:$B$995,Index!$C$2:$C$995,"Not Found")),"")} -> F | D5: {=IF(NOT(ISBLANK(A5)), (_xlfn.XLOOKUP($A5,Index!$B$2:B$995,Index!$A$2:$A$995,"Not Found")),"")} -> base3-22 | E5: {=IF(NOT(ISBLANK($A5)), (_xlfn.XLOOKUP($A5,Index!$B$2:$B$995,Index!$D$2:$D$995,"Not Found")),"")} -> b | F5: {=IF(NOT(ISBLANK($A5)), (_xlfn.XLOOKUP($A5,Index!$B$2:$B$995,Index!$E$2:$E$995,"Not Found")),"")} -> n | G5: {=IF(NOT(ISBLANK(A5)), ((_xlfn.XLOOKUP(A5,Index!$B$2:$B$995,Index!$F$2:$F$995,"Not Found"))*B5),"")} -> 1 | L5: =IF(NOT(ISBLANK(K5)), SUM(M5:P5), "") | M5: =IF(NOT(ISBLANK($K5)), SUMIFS($B$2:$B$32, $E$2:$E$32, "B", $C$2:$C$32,$K5), "") | N5: =IF(NOT(ISBLANK($K5)),SUMIFS($B$2:$B$32,$E$2:$E$32, "1", $C$2:$C$32,$K5,$F$2:$F$32,"N"), "") | O5: =IF(NOT(ISBLANK($K5)),SUMIFS($B$2:$B$32,$E$2:$E$32, "1", $C$2:$C$32,$K5,$F$2:$F$32,"Y"), "") | P5: =IF(NOT(ISBLANK($K5)),SUMIFS($B$2:$B$32,$E$2:$E$32, "2", $C$2:$C$32,$K5), "") | Q5: =IF(NOT(ISBLANK($K5)),SUMIFS($B$2:$B$32,$E$2:$E$32, "B", $C$2:$C$32,$K5,$F$2:$F$32,"N"), "")
