Workbook

Sheet Index
A1: ID | B1: Card | C1: Type | D1: Stage / Rarity (trainer) | E1: Remaining Evo | F1: Deck Feature Tier | G1: Opener Archetype | H1: Pressure | I1: Wants | J1: Possible CPU Deck Block? | K1: Included in opp Deck? | L1: Gated Until (promo only) | N1: Feature Tier Key
A2: base1-1 | B2: Alakazam | C2: P | D2: 2 | F2: 2.5 | H2: AP, SL | I2: Tanks on the bench to move damage to with its pokemon power. It's a competent fighter with its ability to confuse but leans toward prefering the bench. If it's in the active spot itself or if a valuable ally is, it likes to move damage counters off the active one onto a tank on the bench. It prefers decks with several high-HP tank pokemon like Kangaskhan, Chansey, and Snorlax | K2: TRUE | N2: Not shown | O2: Not worth noting
A3: base1-10 | B3: Mewtwo | C3: P | D3: b | E3: n | F3: 0.5 | G3: f | I3: Its damage from Psychic scales with opponent energy, so it likes to come in after there's already a powered-up opponent. The bot should be able to do the math in terms of how much damage Psychic would do to the opponent's active pokemon every time a new pokemon has to be promoted to active. I can't think of any situation Barrier would be used. It requires an energy funnel in order to survive long enough for the next energy funnel, all while the enegy funnel prevents you from powering anything up. | K3: TRUE | N3: 1 | O3: Strategic Opener / Tank / Other utility
A4: base1-100 | B4: E Energy | C4: Energy | K4: TRUE | N4: 2 | O4: Secondary Feature
A5: base1-101 | B5: P Energy | C5: Energy | K5: TRUE | N5: 3 | O5: Primary Feature
A6: base1-102 | B6: W Energy | C6: Energy | K6: TRUE | N6: 4 | O6: Elite Feature
A7: base1-11 | B7: Nidoking | C7: G | D7: 2 | F7: 3 | H7: SL | I7: Both its moves cost the same and both are worth using, but it usually wants to start with Toxic due to the extra poision damage before switching to Thrash, as the extra poision damage on top of Toxic's natural damage equal the 50/50 damage potential of Thrash. Once the opponent is poisoned, Toxic cannot add additional poison damage, so Thrash becomes more valuable. | K7: TRUE
A8: base1-12 | B8: Ninetales | C8: R | D8: 1 | E8: n | F8: 2 | H8: HD | I8: To come in after it's ready to use Fire Blast, and to never be required to choose between Lure and nothing. Fire Blast wants an energy funnel but does high damage, so it requires some maintenance and stops bench growth every turn it attacks, but can one-shot many opponents. Lure does have uses, such as removing a dangerous pokemon and replacing it with one that is not ready to attack and is not able to retreat. | K8: TRUE
A9: base1-13 | B9: Poliwrath | C9: W | D9: 2 | F9: 3 | H9: ED | I9: An Attack Choice, as both attacks are valid. Whirlpool is preferred due to the very high value of discarding opponent energy cards, but Water Gun can be Over-Attached into doing higher damage. Water Gun should be used when it results in a kill that Whrilpool wouldn't, and the bot should be willing to add that fifth energy to do so | K9: TRUE | N9: Tier ranking is only for last of evolution line and select useful others. Partially based in subjectivity and play experience
A10: base1-14 | B10: Raichu | C10: E | D10: 1 | E10: n | F10: 2 | H10: WP, HD | I10: To use Agility when Thunder wouldn't kill, or when Thunder risks a self-kill that isn't worthwhile. Does need some degree of Kamakaze Timing. Agility buys turns through damage *and status* denial on a coin flip, while Thunder risks 30 self-dmg on a coin flip. | K10: TRUE | N10: Remaining Evo only applies to Basic and Stage 1. All stage 2 are assumed to not have evolutions remaining
A11: base1-15 | B11: Venusaur | C11: G | D11: 2 | F11: 3 | H11: BG, HD | I11: Does not necessarily prefer the bench despite its pokemon power, but doesn't mind it there either. Uses Energy Trans to shift energy from bench pokemon to whatever is active for an instant power up, as long as the active pokemon isn't just going to die and lose it all right away. While the newly powered up active pokemon (which could be Venusaur itself) fights, its owner can slowly re-power the bench cards they stripped energy from | K11: TRUE | N11: Labels here are used for the lookup table on the deck tabs, but we can possibly get utility from it as well with the AI
A12: base1-16 | B12: Zapdos | C12: E | D12: b | E12: n | F12: 1.5 | G12: h | H12: HD | I12: To deal high damage and die rather quickly. Prefers to go down fighting over retreat, though not by self-kill. Thunder is the preferred attack until Zapdos looks like it will die on the opponent's next turn, or it risks a self-kill on this turn. In those cases, Thunderbolt should be used. | K12: TRUE | N12: Trainer rarity is used to gauge usefulness in decks
A13: base1-17 | B13: Beedrill | C13: G | D13: 2 | F13: 3 | H13: SL | I13: To use Poison Sting first, and then Twineedle when the opponent is already poisoned. Poison Sting is preferred again when a guaranteed 40 damage or less is needed, rather than gambled on Twineedle's coin flip | K13: TRUE | N13: Half steps are used. Consider those candidates for the next tier with proper support
A14: base1-18 | B14: Dragonair | C14: C | D14: 1 | E14: y | F14: 1 | H14: ED | I14: Is not afraid to fight even though it's not fully evolved, as long as Hyper Beam can be used and the opponent is unable to powerup for a kill because of it. Slam use is rare due to the value of discarding an opponent energy. | K14: TRUE | N14: Opener archetypes per card are tracked. I don't know if we'll need these but it's cheap to do while going through the set anyway. Unlabeled ones should be deferred as openers when possible, but usually committed to once they're in. Based on battle utility, not whether they can evolve, etc
A15: base1-19 | B15: Dugtrio | C15: F | D15: 1 | E15: n | F15: 2 | H15: HD | I15: Slash is preferred unless Earthquake would kill and Slash wouldn't. The damage to its user's own bench should be weighed against Earthquake | K15: TRUE | N15: Numbers added to the end of names is for differentiation purposes between cards with the same name. Ex: B2 means base2/Jungle
A16: base1-2 | B16: Blastoise | C16: W | D16: 2 | F16: 4 | H16: HD | I16: 5-ish extra W energy in deck, Over-Attach 2 extra energy for Hydro Pump's max potential, which is worth it. Loves to fight. When it evolves, its user should immediately use Rain Dance to dump as many energy cards on their pokemon as those pokemon require, prioritizing the ones currently fighting and Blastoise itself | K16: TRUE | N16: Nonholo duplicates are tagged with NH after their name. It helps the lookup table
A17: base1-20 | B17: Electabuzz | C17: E | D17: b | E17: n | F17: 1 | G17: a | H17: SL | I17: Loves to open. Chooses between its moves based on the quickest path to a kill (assuming Thunderpunch's guaranteed 30 damage rather than an average), but prefers Thundershock first when it doesn't lose it a turn by doing so. | K17: TRUE | N17: Trainer Function Key, Pressure, and Wants were added at the advice of #15 and haven't been fully applied retroactively yet
A18: base1-21 | B18: Electrode | C18: E | D18: 1 | E18: n | F18: 2 | J18: y | K18: TRUE | N18: Opener archetypes are only applied to basic pokemon here
A19: base1-22 | B19: Pidgeotto | C19: C | D19: 1 | E19: y | H19: PC | I19: Almost always uses Whirlwind to throw opponents around the play area and doens't even power up Mirror Move unless doing so to prepare for evolution. Mirror Move should only be used when it would result in a kill that Whirlwind wouldn't, and the bot should be willing to spend the energy at the time to do so rather than in advance | K19: TRUE
A20: base1-23 | B20: Arcanine | C20: R | D20: 1 | E20: n | F20: 2 | H20: HD | I20: Both attacks do high damage and both have drawbacks. Flamethrower requires an energy funnel but should be the default due to Take Down's self-damage. However, Take Down should stay powered up and ready to go for when it's needed, meaning the bot should not want to use even Flamethrower until Arcanine has four energies attached, as it requires that constant funnel that would make Take Down unavailable if used at three energies | K20: TRUE
A21: base1-24 | B21: Charmeleon | C21: R | D21: 1 | E21: y | I21: Does decent damage but does not want to fight. Prefers to sit on the bench and pre-Over-Attach energies for an evolution to Charizard, even when Charizard isn't in the hand. Flamethrower does good damage but requires an energy funnel on the card that you want to evolve into the biggest energy funnel of all, so it's best avoided unless necessary. A Charmeleon that ends up fighting and having to use Flamethrower should almost be written off for evolution and used only as a fodder attacker. | K21: TRUE | N21: Opener Archetype Key:
A22: base1-25 | B22: Dewgong | C22: W | D22: 1 | E22: n | F22: 2 | H22: SL | I22: Classic Attack Choice between Aurora Beam and Ice Beam. Punches above its weight and doesn't retreat | K22: TRUE
A23: base1-26 | B23: Dratini | C23: C | D23: b | E23: y | K23: TRUE | N23: A | O23: Attack Opener. Openers that use stalling attacks, low damage attacks w/ high HP, or build up to damage quickly without evo. Should be weighted high for starter selection or stalling jobs, lower for retreat. Can sometimes also build up to stronger moves while stalling. Ex: Onix, Jynx
A24: base1-27 | B24: Farfetch'd | C24: C | D24: b | E24: n | G24: a | I24: Likes to open, and its only useful role ever is to open, and even that is not very useful. Should use Leek Slap and then be left to die while other things are powered up, unless desperate enough to need to power up Pot Smash. Our autobuilder should probably weight this one rather low | K24: TRUE | N24: T | O24: Tanks. Usually used as openers but attacks are usually defensive stalling or card drawing. Usually weighted higher than other openers. Ex: Chansey
A25: base1-28 | B25: Growlithe | C25: R | D25: b | E25: y | I25: Low-weight opener. Arcanine's high energy cost makes it prefer the bench | K25: TRUE | N25: F | O25: Fallback opener. Good cheap attack option during game, not a main weapon but capable of bridging gaps. Good opener if other options aren't available. Ex: Mewtwo (1-10)
A26: base1-29 | B26: Haunter | C26: P | D26: 1 | E26: y | H26: SL | I26: Hypnosis + Dream Eater is a Setup Turn combo but Dream Eater only has a 1/4 chance of being successful before even before you factor in the opponent's chance to wake up by evolving. Therefore it doesn't want to fight, and should be used only as a staller when it does. It's still useful to keep at 2 energies rather than Dream Eater being a reactive energy-add at the time it's needed, due to Gengar's attack needing 3 energies. If kept at 2 while Haunter, it can evolve and attack the same turn a Gengar is drawn (as long as its player has the extra energy in hand) | K26: TRUE | N26: E | O26: Evo openerer. Lower weight when it comes to opening due to evolution possibility but does have stalling moves or can do damage, and should be prioritized when stalling is needed and no other options available. Higher priority if evolution exists in hand and is realistic to survive long enough to evolve. Ex: Squirtle
A27: base1-3 | B27: Chansey | C27: C | D27: b | E27: n | F27: 1 | G27: t | H27: WP | I27: To work as a tank or staller, hiding behind Scrunch and rarely ever retreating or using Double-Edge | K27: TRUE | N27: N | O27: Avoid using as an opener when possible. Should be weighted lower than the baseline and possibly even switched out when other options become available. Ex: Magikarp
A28: base1-30 | B28: Ivysaur | C28: G | D28: 1 | E28: y | H28: SL | I28: A middle stage that doesn't mind fighting due to Poisonpowder's guaranteed poisoning. If it evolved from Bulbasaur in the active spot, then it's already in good position to deal damage due to Bulbasaur's attack costing 2 energies, and both of Ivysaur's costing 3, meaning Bulbasaur can be evolved fluidly without being pre-loaded while fighting | K28: TRUE | N28: H | O28: HP staller. A high HP card that would normally be used as an attacker is substituted as a tank due to lack of other options. Committed to once in, not retreated or powered up unless smart to do so. A complete sacrifice. Ex: Zapdos
A29: base1-31 | B29: Jynx | C29: P | D29: b | E29: n | F29: 0.5 | G29: a | I29: Meditate is preferred and can be extremely effective against much stronger (but damaged) pokemon. Loves to start and use Doubleslap while powering up Meditate, or might choose to tank without only Doubleslap while something more valuable is powered up on the bench instead. Meditate's potential damage should always be considered by the bot when choosing something to promote | K29: TRUE
A30: base1-32 | B30: Kadabra | C30: P | D30: 1 | E30: y | H30: HD | I30: Super Psy does high damage for what it is, and even outdoes its own evolution's damage. The evolution is still preferred in most situations though due to its pokemon power and chance to confuse. Recover should never be used. It drains an energy from a pokemon that wants to stay at 3 energies at all times. Getting in a 50 dmg hit and dying is almost always preferable to recovery or retreat | K30: TRUE
A31: base1-33 | B31: Kakuna | C31: G | D31: 1 | E31: y | H31: SL | I31: Is a good fighting mid-stage that likes to meddle with Poisonpowder. Damage and chance to poison is almost always preferable to a 50/50 chance at damage prevention with Stiffen | K31: TRUE
A32: base1-34 | B32: Machoke | C32: F | D32: 1 | E32: y | I32: A tough card to use because one attack's damage shrinks very quickly with damage taken, and the other deals self-damage. Can deal high damage to an opponent quickly but can become useless after that. Prefers to evolve on the bench unless a quick cheap hit is needed, at which time it does have a use | K32: TRUE | N32: Trainer Function Key (uses the Deck Feature Tier column):
A33: base1-35 | B33: Magikarp | C33: W | D33: b | E33: y | G33: n | I33: If this guy is fighting, you're in a bad spot | K33: TRUE | N33: D | O33: Draw. Cards are picked up from the top of the deck
A34: base1-36 | B34: Magmar | C34: R | D34: b | E34: n | G34: f | H34: HD | I34: Flamethrower does good damage but requires an energy funnel, and this is not a pokemon you want consuming all your energies. Use Fire Punch as default but be ready for Flamethrower when needed. Low HP means it dies rather quickly. | K34: TRUE | N34: S | O34: Search. Search for a card in the deck
A35: base1-37 | B35: Nidorino | C35: G | D35: 1 | E35: y | I35: Horn Drill preferred, Double Kick only when it can't be afforded | K35: TRUE | N35: P | O35: Disruption. Interferes with the opponent or the status of the board
A36: base1-38 | B36: Poliwhirl | C36: W | D36: 1 | E36: y | I36: Amnesia can block an opponent's damage before Doubleslap has the energy to be used or if Poliwhirl needs to survive to the next turn to evolve. Otherwise Doubleslap is always preferred | K36: TRUE | N36: H | O36: Heal. Removes damage from Pokemon
A37: base1-39 | B37: Porygon | C37: C | D37: b | E37: n | G37: a | I37: To use Conversion 2 to stay resistant to its opponent while it stalls as long as it can before death. Conversion 1 should only be used when Conversion 2 can't be afforded, and when it is, the bot should shift the opponent's weakness the type of their own current strongest (non-colorless) bench pokemon | K37: TRUE | N37: M | O37: Movement. Moves someone from somewhere to somewhere
A38: base1-4 | B38: Charizard | C38: R | D38: 2 | F38: 4 | H38: HD | I38: A deck where four DCE replace four R energies, and to be pre-Over-Attached with as many energies as possibe before being sent into battle. Even Charmeleon should be preloaded on the bench before evolution in anticipation of this card's high Energy Funel costs. | K38: TRUE | N38: R | O38: Recovery. Removes status conditions
A39: base1-40 | B39: Raticate | C39: C | D39: 1 | E39: n | I39: Bite is primary, and Super Fang usually isn't worth it. Power up beyond Bite only if there are no better options for that energy | K39: TRUE | N39: E | O39: Exclude from baseline. Doesn't fall in with the other functions but should be excluded from baseline readings
A40: base1-41 | B40: Seel | C40: W | D40: b | E40: y | K40: TRUE
...

Sheet Deck List
B1: Base1 | D1: Jungle | F1: Fossil | H1: Challenge 1 | J1: Rocket
A2: T2-1 | B2: F, W | C2: Starmie | D2: E, R, W | E2: Eevee | F2: W, P | G2: Hypno NH | H2: G | I2: Weezing | J2: E, R, W | K2: Eevee R
A3: T2-2 | B3: P, R | C3: Alakazam | D3: G, P | E3: Nidoqueen | F3: F, E | G3: Hitmonlee | H3: F | I3: Aerodactyl | J3: E, G | K3: Dark Raichu
A4: T2-3 | B4: G, E | C4: Beedrill | D4: F, G | E4: Rhydon | F4: G, W | G4: Muk | H4: P | I4: Gengar | J4: R, P | K4: Dark Charizard
A5: T2-4 | B5: E, F | C5: Machamp | H5: R | I5: Moltres | J5: P, C | K5: Dark Alakazam
A6: T2-5 | B6: W, P | C6: Poliwrath | H6: E | I6: Zapdos B3
A7: T3-1 | B7: G | C7: Venusaur | D7: C, G | E7: Pidgeot | F7: W | G7: Omastar | H7: W | I7: Articuno | J7: G | K7: Dark Vileplume
A8: T3-2 | B8: W | C8: Blastoise | F8: C, F | G8: Dragonite | H8: C | I8: Wigglytuff | J8: F | K8: Dark Machamp
A9: T3-3 | J9: C, E, R, W | K9: Dark Dragonite
A10: T4 | B10: R | C10: Charizard | D10: G | E10: Vileplume | F10: P | G10: Haunter B3 | J10: W | K10: Dark Blastoise
A13: Challenge ignores regular Tier structure

Sheet Template
A1: Card | B1: Quantity | C1: Type | D1: ID | E1: Stage / Rarity | F1: Remaining Evo | G1: Feature Weight | I1: Card Total | K1: Type | L1: Num | M1: Basic | N1: S1 Max | O1: S1 Mid | P1: S2 | Q1: No Evolve
C2: {=IF(NOT(ISBLANK($A2)), (_xlfn.XLOOKUP($A2,Index!$B$2:$B$995,Index!$C$2:$C$995,"Not Found")),"")} | D2: {=IF(NOT(ISBLANK(A2)), (_xlfn.XLOOKUP($A2,Index!$B$2:B$995,Index!$A$2:$A$995,"Not Found")),"")} | E2: {=IF(NOT(ISBLANK($A2)), (_xlfn.XLOOKUP($A2,Index!$B$2:$B$995,Index!$D$2:$D$995,"Not Found")),"")} | F2: {=IF(NOT(ISBLANK($A2)), (_xlfn.XLOOKUP($A2,Index!$B$2:$B$995,Index!$E$2:$E$995,"Not Found")),"")} | G2: {=IF(NOT(ISBLANK(A2)), ((_xlfn.XLOOKUP(A2,Index!$B$2:$B$995,Index!$F$2:$F$995,"Not Found"))*B2),"")} | I2: =SUM(B2:B38) -> 0 | L2: =IF(NOT(ISBLANK(K2)), SUM(M2:P2), "") | M2: =IF(NOT(ISBLANK($K2)), SUMIFS($B$2:$B$32, $E$2:$E$32, "B", $C$2:$C$32,$K2), "") | N2: =IF(NOT(ISBLANK($K2)),SUMIFS($B$2:$B$32,$E$2:$E$32, "1", $C$2:$C$32,$K2,$F$2:$F$32,"N"), "") | O2: =IF(NOT(ISBLANK($K2)),SUMIFS($B$2:$B$32,$E$2:$E$32, "1", $C$2:$C$32,$K2,$F$2:$F$32,"Y"), "") | P2: =IF(NOT(ISBLANK($K2)),SUMIFS($B$2:$B$32,$E$2:$E$32, "2", $C$2:$C$32,$K2), "") | Q2: =IF(NOT(ISBLANK($K2)),SUMIFS($B$2:$B$32,$E$2:$E$32, "B", $C$2:$C$32,$K2,$F$2:$F$32,"N"), "")
C3: {=IF(NOT(ISBLANK($A3)), (_xlfn.XLOOKUP($A3,Index!$B$2:$B$995,Index!$C$2:$C$995,"Not Found")),"")} | D3: {=IF(NOT(ISBLANK(A3)), (_xlfn.XLOOKUP($A3,Index!$B$2:B$995,Index!$A$2:$A$995,"Not Found")),"")} | E3: {=IF(NOT(ISBLANK($A3)), (_xlfn.XLOOKUP($A3,Index!$B$2:$B$995,Index!$D$2:$D$995,"Not Found")),"")} | F3: {=IF(NOT(ISBLANK($A3)), (_xlfn.XLOOKUP($A3,Index!$B$2:$B$995,Index!$E$2:$E$995,"Not Found")),"")} | G3: {=IF(NOT(ISBLANK(A3)), ((_xlfn.XLOOKUP(A3,Index!$B$2:$B$995,Index!$F$2:$F$995,"Not Found"))*B3),"")} | L3: =IF(NOT(ISBLANK(K3)), SUM(M3:P3), "") | M3: =IF(NOT(ISBLANK($K3)), SUMIFS($B$2:$B$32, $E$2:$E$32, "B", $C$2:$C$32,$K3), "") | N3: =IF(NOT(ISBLANK($K3)),SUMIFS($B$2:$B$32,$E$2:$E$32, "1", $C$2:$C$32,$K3,$F$2:$F$32,"N"), "") | O3: =IF(NOT(ISBLANK($K3)),SUMIFS($B$2:$B$32,$E$2:$E$32, "1", $C$2:$C$32,$K3,$F$2:$F$32,"Y"), "") | P3: =IF(NOT(ISBLANK($K3)),SUMIFS($B$2:$B$32,$E$2:$E$32, "2", $C$2:$C$32,$K3), "") | Q3: =IF(NOT(ISBLANK($K3)),SUMIFS($B$2:$B$32,$E$2:$E$32, "B", $C$2:$C$32,$K3,$F$2:$F$32,"N"), "")
C4: {=IF(NOT(ISBLANK($A4)), (_xlfn.XLOOKUP($A4,Index!$B$2:$B$995,Index!$C$2:$C$995,"Not Found")),"")} | D4: {=IF(NOT(ISBLANK(A4)), (_xlfn.XLOOKUP($A4,Index!$B$2:B$995,Index!$A$2:$A$995,"Not Found")),"")} | E4: {=IF(NOT(ISBLANK($A4)), (_xlfn.XLOOKUP($A4,Index!$B$2:$B$995,Index!$D$2:$D$995,"Not Found")),"")} | F4: {=IF(NOT(ISBLANK($A4)), (_xlfn.XLOOKUP($A4,Index!$B$2:$B$995,Index!$E$2:$E$995,"Not Found")),"")} | G4: {=IF(NOT(ISBLANK(A4)), ((_xlfn.XLOOKUP(A4,Index!$B$2:$B$995,Index!$F$2:$F$995,"Not Found"))*B4),"")} | L4: =IF(NOT(ISBLANK(K4)), SUM(M4:P4), "") | M4: =IF(NOT(ISBLANK($K4)), SUMIFS($B$2:$B$32, $E$2:$E$32, "B", $C$2:$C$32,$K4), "") | N4: =IF(NOT(ISBLANK($K4)),SUMIFS($B$2:$B$32,$E$2:$E$32, "1", $C$2:$C$32,$K4,$F$2:$F$32,"N"), "") | O4: =IF(NOT(ISBLANK($K4)),SUMIFS($B$2:$B$32,$E$2:$E$32, "1", $C$2:$C$32,$K4,$F$2:$F$32,"Y"), "") | P4: =IF(NOT(ISBLANK($K4)),SUMIFS($B$2:$B$32,$E$2:$E$32, "2", $C$2:$C$32,$K4), "") | Q4: =IF(NOT(ISBLANK($K4)),SUMIFS($B$2:$B$32,$E$2:$E$32, "B", $C$2:$C$32,$K4,$F$2:$F$32,"N"), "")
C5: {=IF(NOT(ISBLANK($A5)), (_xlfn.XLOOKUP($A5,Index!$B$2:$B$995,Index!$C$2:$C$995,"Not Found")),"")} | D5: {=IF(NOT(ISBLANK(A5)), (_xlfn.XLOOKUP($A5,Index!$B$2:B$995,Index!$A$2:$A$995,"Not Found")),"")} | E5: {=IF(NOT(ISBLANK($A5)), (_xlfn.XLOOKUP($A5,Index!$B$2:$B$995,Index!$D$2:$D$995,"Not Found")),"")} | F5: {=IF(NOT(ISBLANK($A5)), (_xlfn.XLOOKUP($A5,Index!$B$2:$B$995,Index!$E$2:$E$995,"Not Found")),"")} | G5: {=IF(NOT(ISBLANK(A5)), ((_xlfn.XLOOKUP(A5,Index!$B$2:$B$995,Index!$F$2:$F$995,"Not Found"))*B5),"")} | L5: =IF(NOT(ISBLANK(K5)), SUM(M5:P5), "") | M5: =IF(NOT(ISBLANK($K5)), SUMIFS($B$2:$B$32, $E$2:$E$32, "B", $C$2:$C$32,$K5), "") | N5: =IF(NOT(ISBLANK($K5)),SUMIFS($B$2:$B$32,$E$2:$E$32, "1", $C$2:$C$32,$K5,$F$2:$F$32,"N"), "") | O5: =IF(NOT(ISBLANK($K5)),SUMIFS($B$2:$B$32,$E$2:$E$32, "1", $C$2:$C$32,$K5,$F$2:$F$32,"Y"), "") | P5: =IF(NOT(ISBLANK($K5)),SUMIFS($B$2:$B$32,$E$2:$E$32, "2", $C$2:$C$32,$K5), "") | Q5: =IF(NOT(ISBLANK($K5)),SUMIFS($B$2:$B$32,$E$2:$E$32, "B", $C$2:$C$32,$K5,$F$2:$F$32,"N"), "")
C6: {=IF(NOT(ISBLANK($A6)), (_xlfn.XLOOKUP($A6,Index!$B$2:$B$995,Index!$C$2:$C$995,"Not Found")),"")} | D6: {=IF(NOT(ISBLANK(A6)), (_xlfn.XLOOKUP($A6,Index!$B$2:B$995,Index!$A$2:$A$995,"Not Found")),"")} | E6: {=IF(NOT(ISBLANK($A6)), (_xlfn.XLOOKUP($A6,Index!$B$2:$B$995,Index!$D$2:$D$995,"Not Found")),"")} | F6: {=IF(NOT(ISBLANK($A6)), (_xlfn.XLOOKUP($A6,Index!$B$2:$B$995,Index!$E$2:$E$995,"Not Found")),"")} | G6: {=IF(NOT(ISBLANK(A6)), ((_xlfn.XLOOKUP(A6,Index!$B$2:$B$995,Index!$F$2:$F$995,"Not Found"))*B6),"")} | L6: =IF(NOT(ISBLANK(K6)), SUM(M6:P6), "") | M6: =IF(NOT(ISBLANK($K6)), COUNTIFS($E$2:$E$32, "B", $C$2:$C$32,$K6), "") | N6: =IF(NOT(ISBLANK(K6)),COUNTIFS($E$2:$E$32, "1", $C$2:$C$32,$K6,$F$2:$F$32,"N"), "") | O6: =IF(NOT(ISBLANK($K6)),COUNTIFS($E$2:$E$32, "1", $C$2:$C$32,$K6,$F$2:$F$32,"Y"), "") | P6: =IF(NOT(ISBLANK($K6)),COUNTIFS($E$2:$E$32, "2", $C$2:$C$32,$K6), "") | Q6: =IF(NOT(ISBLANK($K6)),COUNTIFS($E$2:$E$32, "B", $C$2:$C$32,$K6,$F$2:$F$32,"N"), "")
C7: {=IF(NOT(ISBLANK($A7)), (_xlfn.XLOOKUP($A7,Index!$B$2:$B$995,Index!$C$2:$C$995,"Not Found")),"")} | D7: {=IF(NOT(ISBLANK(A7)), (_xlfn.XLOOKUP($A7,Index!$B$2:B$995,Index!$A$2:$A$995,"Not Found")),"")} | E7: {=IF(NOT(ISBLANK($A7)), (_xlfn.XLOOKUP($A7,Index!$B$2:$B$995,Index!$D$2:$D$995,"Not Found")),"")} | F7: {=IF(NOT(ISBLANK($A7)), (_xlfn.XLOOKUP($A7,Index!$B$2:$B$995,Index!$E$2:$E$995,"Not Found")),"")} | G7: {=IF(NOT(ISBLANK(A7)), ((_xlfn.XLOOKUP(A7,Index!$B$2:$B$995,Index!$F$2:$F$995,"Not Found"))*B7),"")} | K7: Total | L7: =SUM(L2:L6) -> 0 | M7: =SUM(M2:M6) -> 0 | N7: =SUM(N2:N6) -> 0 | O7: =SUM(O2:O6) -> 0 | P7: =SUM(P2:P6) -> 0 | Q7: =SUM(Q2:Q6) -> 0
C8: {=IF(NOT(ISBLANK($A8)), (_xlfn.XLOOKUP($A8,Index!$B$2:$B$995,Index!$C$2:$C$995,"Not Found")),"")} | D8: {=IF(NOT(ISBLANK(A8)), (_xlfn.XLOOKUP($A8,Index!$B$2:B$995,Index!$A$2:$A$995,"Not Found")),"")} | E8: {=IF(NOT(ISBLANK($A8)), (_xlfn.XLOOKUP($A8,Index!$B$2:$B$995,Index!$D$2:$D$995,"Not Found")),"")} | F8: {=IF(NOT(ISBLANK($A8)), (_xlfn.XLOOKUP($A8,Index!$B$2:$B$995,Index!$E$2:$E$995,"Not Found")),"")} | G8: {=IF(NOT(ISBLANK(A8)), ((_xlfn.XLOOKUP(A8,Index!$B$2:$B$995,Index!$F$2:$F$995,"Not Found"))*B8),"")}
C9: {=IF(NOT(ISBLANK($A9)), (_xlfn.XLOOKUP($A9,Index!$B$2:$B$995,Index!$C$2:$C$995,"Not Found")),"")} | D9: {=IF(NOT(ISBLANK(A9)), (_xlfn.XLOOKUP($A9,Index!$B$2:B$995,Index!$A$2:$A$995,"Not Found")),"")} | E9: {=IF(NOT(ISBLANK($A9)), (_xlfn.XLOOKUP($A9,Index!$B$2:$B$995,Index!$D$2:$D$995,"Not Found")),"")} | F9: {=IF(NOT(ISBLANK($A9)), (_xlfn.XLOOKUP($A9,Index!$B$2:$B$995,Index!$E$2:$E$995,"Not Found")),"")} | G9: {=IF(NOT(ISBLANK(A9)), ((_xlfn.XLOOKUP(A9,Index!$B$2:$B$995,Index!$F$2:$F$995,"Not Found"))*B9),"")} | M9: Common | N9: Uncommon | O9: Rare
C10: {=IF(NOT(ISBLANK($A10)), (_xlfn.XLOOKUP($A10,Index!$B$2:$B$995,Index!$C$2:$C$995,"Not Found")),"")} | D10: {=IF(NOT(ISBLANK(A10)), (_xlfn.XLOOKUP($A10,Index!$B$2:B$995,Index!$A$2:$A$995,"Not Found")),"")} | E10: {=IF(NOT(ISBLANK($A10)), (_xlfn.XLOOKUP($A10,Index!$B$2:$B$995,Index!$D$2:$D$995,"Not Found")),"")} | F10: {=IF(NOT(ISBLANK($A10)), (_xlfn.XLOOKUP($A10,Index!$B$2:$B$995,Index!$E$2:$E$995,"Not Found")),"")} | G10: {=IF(NOT(ISBLANK(A10)), ((_xlfn.XLOOKUP(A10,Index!$B$2:$B$995,Index!$F$2:$F$995,"Not Found"))*B10),"")} | K10: Trainer | L10: =SUM(M10:P10) -> 0 | M10: =IF(NOT(ISBLANK($K10)), SUMIFS($B$2:$B$32,$E$2:$E$32, "C", $C$2:$C$32,"T"), "") -> 0 | N10: =IF(NOT(ISBLANK($K10)), SUMIFS($B$2:$B$32,$E$2:$E$32, "U", $C$2:$C$32,"T"), "") -> 0 | O10: =IF(NOT(ISBLANK($K$2)), SUMIFS($B$2:$B$32,$E$2:$E$32, "R", $C$2:$C$32,"T"), "")
C11: {=IF(NOT(ISBLANK($A11)), (_xlfn.XLOOKUP($A11,Index!$B$2:$B$995,Index!$C$2:$C$995,"Not Found")),"")} | D11: {=IF(NOT(ISBLANK(A11)), (_xlfn.XLOOKUP($A11,Index!$B$2:B$995,Index!$A$2:$A$995,"Not Found")),"")} | E11: {=IF(NOT(ISBLANK($A11)), (_xlfn.XLOOKUP($A11,Index!$B$2:$B$995,Index!$D$2:$D$995,"Not Found")),"")} | F11: {=IF(NOT(ISBLANK($A11)), (_xlfn.XLOOKUP($A11,Index!$B$2:$B$995,Index!$E$2:$E$995,"Not Found")),"")} | G11: {=IF(NOT(ISBLANK(A11)), ((_xlfn.XLOOKUP(A11,Index!$B$2:$B$995,Index!$F$2:$F$995,"Not Found"))*B11),"")} | K11: Energy | L11: =IF(NOT(ISBLANK($K$2)), SUMIFS($B$2:$B$32, $C$2:$C$32,"Energy"), "")
C12: {=IF(NOT(ISBLANK($A12)), (_xlfn.XLOOKUP($A12,Index!$B$2:$B$995,Index!$C$2:$C$995,"Not Found")),"")} | D12: {=IF(NOT(ISBLANK(A12)), (_xlfn.XLOOKUP($A12,Index!$B$2:B$995,Index!$A$2:$A$995,"Not Found")),"")} | E12: {=IF(NOT(ISBLANK($A12)), (_xlfn.XLOOKUP($A12,Index!$B$2:$B$995,Index!$D$2:$D$995,"Not Found")),"")} | F12: {=IF(NOT(ISBLANK($A12)), (_xlfn.XLOOKUP($A12,Index!$B$2:$B$995,Index!$E$2:$E$995,"Not Found")),"")} | G12: {=IF(NOT(ISBLANK(A12)), ((_xlfn.XLOOKUP(A12,Index!$B$2:$B$995,Index!$F$2:$F$995,"Not Found"))*B12),"")} | K12: Pokemon | L12: =L7 -> 0
C13: {=IF(NOT(ISBLANK($A13)), (_xlfn.XLOOKUP($A13,Index!$B$2:$B$995,Index!$C$2:$C$995,"Not Found")),"")} | D13: {=IF(NOT(ISBLANK(A13)), (_xlfn.XLOOKUP($A13,Index!$B$2:B$995,Index!$A$2:$A$995,"Not Found")),"")} | E13: {=IF(NOT(ISBLANK($A13)), (_xlfn.XLOOKUP($A13,Index!$B$2:$B$995,Index!$D$2:$D$995,"Not Found")),"")} | F13: {=IF(NOT(ISBLANK($A13)), (_xlfn.XLOOKUP($A13,Index!$B$2:$B$995,Index!$E$2:$E$995,"Not Found")),"")} | G13: {=IF(NOT(ISBLANK(A13)), ((_xlfn.XLOOKUP(A13,Index!$B$2:$B$995,Index!$F$2:$F$995,"Not Found"))*B13),"")}
C14: {=IF(NOT(ISBLANK($A14)), (_xlfn.XLOOKUP($A14,Index!$B$2:$B$995,Index!$C$2:$C$995,"Not Found")),"")} | D14: {=IF(NOT(ISBLANK(A14)), (_xlfn.XLOOKUP($A14,Index!$B$2:B$995,Index!$A$2:$A$995,"Not Found")),"")} | E14: {=IF(NOT(ISBLANK($A14)), (_xlfn.XLOOKUP($A14,Index!$B$2:$B$995,Index!$D$2:$D$995,"Not Found")),"")} | F14: {=IF(NOT(ISBLANK($A14)), (_xlfn.XLOOKUP($A14,Index!$B$2:$B$995,Index!$E$2:$E$995,"Not Found")),"")} | G14: {=IF(NOT(ISBLANK(A14)), ((_xlfn.XLOOKUP(A14,Index!$B$2:$B$995,Index!$F$2:$F$995,"Not Found"))*B14),"")}
C15: {=IF(NOT(ISBLANK($A15)), (_xlfn.XLOOKUP($A15,Index!$B$2:$B$995,Index!$C$2:$C$995,"Not Found")),"")} | D15: {=IF(NOT(ISBLANK(A15)), (_xlfn.XLOOKUP($A15,Index!$B$2:B$995,Index!$A$2:$A$995,"Not Found")),"")} | E15: {=IF(NOT(ISBLANK($A15)), (_xlfn.XLOOKUP($A15,Index!$B$2:$B$995,Index!$D$2:$D$995,"Not Found")),"")} | F15: {=IF(NOT(ISBLANK($A15)), (_xlfn.XLOOKUP($A15,Index!$B$2:$B$995,Index!$E$2:$E$995,"Not Found")),"")} | G15: {=IF(NOT(ISBLANK(A15)), ((_xlfn.XLOOKUP(A15,Index!$B$2:$B$995,Index!$F$2:$F$995,"Not Found"))*B15),"")} | K15: Feature Weight:
C16: {=IF(NOT(ISBLANK($A16)), (_xlfn.XLOOKUP($A16,Index!$B$2:$B$995,Index!$C$2:$C$995,"Not Found")),"")} | D16: {=IF(NOT(ISBLANK(A16)), (_xlfn.XLOOKUP($A16,Index!$B$2:B$995,Index!$A$2:$A$995,"Not Found")),"")} | E16: {=IF(NOT(ISBLANK($A16)), (_xlfn.XLOOKUP($A16,Index!$B$2:$B$995,Index!$D$2:$D$995,"Not Found")),"")} | F16: {=IF(NOT(ISBLANK($A16)), (_xlfn.XLOOKUP($A16,Index!$B$2:$B$995,Index!$E$2:$E$995,"Not Found")),"")} | G16: {=IF(NOT(ISBLANK(A16)), ((_xlfn.XLOOKUP(A16,Index!$B$2:$B$995,Index!$F$2:$F$995,"Not Found"))*B16),"")} | K16: =K2 | L16: =IF(NOT(ISBLANK($K2)), SUMIFS($G$2:$G$32, $C$2:$C$32,$K2), "")
C17: {=IF(NOT(ISBLANK($A17)), (_xlfn.XLOOKUP($A17,Index!$B$2:$B$995,Index!$C$2:$C$995,"Not Found")),"")} | D17: {=IF(NOT(ISBLANK(A17)), (_xlfn.XLOOKUP($A17,Index!$B$2:B$995,Index!$A$2:$A$995,"Not Found")),"")} | E17: {=IF(NOT(ISBLANK($A17)), (_xlfn.XLOOKUP($A17,Index!$B$2:$B$995,Index!$D$2:$D$995,"Not Found")),"")} | F17: {=IF(NOT(ISBLANK($A17)), (_xlfn.XLOOKUP($A17,Index!$B$2:$B$995,Index!$E$2:$E$995,"Not Found")),"")} | G17: {=IF(NOT(ISBLANK(A17)), ((_xlfn.XLOOKUP(A17,Index!$B$2:$B$995,Index!$F$2:$F$995,"Not Found"))*B17),"")} | K17: =K3 | L17: =IF(NOT(ISBLANK($K3)), SUMIFS($G$2:$G$32, $C$2:$C$32,$K3), "")
C18: {=IF(NOT(ISBLANK($A18)), (_xlfn.XLOOKUP($A18,Index!$B$2:$B$995,Index!$C$2:$C$995,"Not Found")),"")} | D18: {=IF(NOT(ISBLANK(A18)), (_xlfn.XLOOKUP($A18,Index!$B$2:B$995,Index!$A$2:$A$995,"Not Found")),"")} | E18: {=IF(NOT(ISBLANK($A18)), (_xlfn.XLOOKUP($A18,Index!$B$2:$B$995,Index!$D$2:$D$995,"Not Found")),"")} | F18: {=IF(NOT(ISBLANK($A18)), (_xlfn.XLOOKUP($A18,Index!$B$2:$B$995,Index!$E$2:$E$995,"Not Found")),"")} | G18: {=IF(NOT(ISBLANK(A18)), ((_xlfn.XLOOKUP(A18,Index!$B$2:$B$995,Index!$F$2:$F$995,"Not Found"))*B18),"")} | K18: =K4 | L18: =IF(NOT(ISBLANK($K4)), SUMIFS($G$2:$G$32, $C$2:$C$32,$K4), "")
C19: {=IF(NOT(ISBLANK($A19)), (_xlfn.XLOOKUP($A19,Index!$B$2:$B$995,Index!$C$2:$C$995,"Not Found")),"")} | D19: {=IF(NOT(ISBLANK(A19)), (_xlfn.XLOOKUP($A19,Index!$B$2:B$995,Index!$A$2:$A$995,"Not Found")),"")} | E19: {=IF(NOT(ISBLANK($A19)), (_xlfn.XLOOKUP($A19,Index!$B$2:$B$995,Index!$D$2:$D$995,"Not Found")),"")} | F19: {=IF(NOT(ISBLANK($A19)), (_xlfn.XLOOKUP($A19,Index!$B$2:$B$995,Index!$E$2:$E$995,"Not Found")),"")} | G19: {=IF(NOT(ISBLANK(A19)), ((_xlfn.XLOOKUP(A19,Index!$B$2:$B$995,Index!$F$2:$F$995,"Not Found"))*B19),"")} | K19: =K5 | L19: =IF(NOT(ISBLANK($K5)), SUMIFS($G$2:$G$32, $C$2:$C$32,$K5), "")
C20: {=IF(NOT(ISBLANK($A20)), (_xlfn.XLOOKUP($A20,Index!$B$2:$B$995,Index!$C$2:$C$995,"Not Found")),"")} | D20: {=IF(NOT(ISBLANK(A20)), (_xlfn.XLOOKUP($A20,Index!$B$2:B$995,Index!$A$2:$A$995,"Not Found")),"")} | E20: {=IF(NOT(ISBLANK($A20)), (_xlfn.XLOOKUP($A20,Index!$B$2:$B$995,Index!$D$2:$D$995,"Not Found")),"")} | F20: {=IF(NOT(ISBLANK($A20)), (_xlfn.XLOOKUP($A20,Index!$B$2:$B$995,Index!$E$2:$E$995,"Not Found")),"")} | G20: {=IF(NOT(ISBLANK(A20)), ((_xlfn.XLOOKUP(A20,Index!$B$2:$B$995,Index!$F$2:$F$995,"Not Found"))*B20),"")} | K20: =K6
C21: {=IF(NOT(ISBLANK($A21)), (_xlfn.XLOOKUP($A21,Index!$B$2:$B$995,Index!$C$2:$C$995,"Not Found")),"")} | D21: {=IF(NOT(ISBLANK(A21)), (_xlfn.XLOOKUP($A21,Index!$B$2:B$995,Index!$A$2:$A$995,"Not Found")),"")} | E21: {=IF(NOT(ISBLANK($A21)), (_xlfn.XLOOKUP($A21,Index!$B$2:$B$995,Index!$D$2:$D$995,"Not Found")),"")} | F21: {=IF(NOT(ISBLANK($A21)), (_xlfn.XLOOKUP($A21,Index!$B$2:$B$995,Index!$E$2:$E$995,"Not Found")),"")} | G21: {=IF(NOT(ISBLANK(A21)), ((_xlfn.XLOOKUP(A21,Index!$B$2:$B$995,Index!$F$2:$F$995,"Not Found"))*B21),"")} | K21: Total: | L21: =SUM(L15:L19) -> 0
C22: {=IF(NOT(ISBLANK($A22)), (_xlfn.XLOOKUP($A22,Index!$B$2:$B$995,Index!$C$2:$C$995,"Not Found")),"")} | D22: {=IF(NOT(ISBLANK(A22)), (_xlfn.XLOOKUP($A22,Index!$B$2:B$995,Index!$A$2:$A$995,"Not Found")),"")} | E22: {=IF(NOT(ISBLANK($A22)), (_xlfn.XLOOKUP($A22,Index!$B$2:$B$995,Index!$D$2:$D$995,"Not Found")),"")} | F22: {=IF(NOT(ISBLANK($A22)), (_xlfn.XLOOKUP($A22,Index!$B$2:$B$995,Index!$E$2:$E$995,"Not Found")),"")} | G22: {=IF(NOT(ISBLANK(A22)), ((_xlfn.XLOOKUP(A22,Index!$B$2:$B$995,Index!$F$2:$F$995,"Not Found"))*B22),"")}
C23: {=IF(NOT(ISBLANK($A23)), (_xlfn.XLOOKUP($A23,Index!$B$2:$B$995,Index!$C$2:$C$995,"Not Found")),"")} | D23: {=IF(NOT(ISBLANK(A23)), (_xlfn.XLOOKUP($A23,Index!$B$2:B$995,Index!$A$2:$A$995,"Not Found")),"")} | E23: {=IF(NOT(ISBLANK($A23)), (_xlfn.XLOOKUP($A23,Index!$B$2:$B$995,Index!$D$2:$D$995,"Not Found")),"")} | F23: {=IF(NOT(ISBLANK($A23)), (_xlfn.XLOOKUP($A23,Index!$B$2:$B$995,Index!$E$2:$E$995,"Not Found")),"")} | G23: {=IF(NOT(ISBLANK(A23)), ((_xlfn.XLOOKUP(A23,Index!$B$2:$B$995,Index!$F$2:$F$995,"Not Found"))*B23),"")}
C24: {=IF(NOT(ISBLANK($A24)), (_xlfn.XLOOKUP($A24,Index!$B$2:$B$995,Index!$C$2:$C$995,"Not Found")),"")} | D24: {=IF(NOT(ISBLANK(A24)), (_xlfn.XLOOKUP($A24,Index!$B$2:B$995,Index!$A$2:$A$995,"Not Found")),"")} | E24: {=IF(NOT(ISBLANK($A24)), (_xlfn.XLOOKUP($A24,Index!$B$2:$B$995,Index!$D$2:$D$995,"Not Found")),"")} | F24: {=IF(NOT(ISBLANK($A24)), (_xlfn.XLOOKUP($A24,Index!$B$2:$B$995,Index!$E$2:$E$995,"Not Found")),"")} | G24: {=IF(NOT(ISBLANK(A24)), ((_xlfn.XLOOKUP(A24,Index!$B$2:$B$995,Index!$F$2:$F$995,"Not Found"))*B24),"")} | K24: Cover Card:
C25: {=IF(NOT(ISBLANK($A25)), (_xlfn.XLOOKUP($A25,Index!$B$2:$B$995,Index!$C$2:$C$995,"Not Found")),"")} | D25: {=IF(NOT(ISBLANK(A25)), (_xlfn.XLOOKUP($A25,Index!$B$2:B$995,Index!$A$2:$A$995,"Not Found")),"")} | E25: {=IF(NOT(ISBLANK($A25)), (_xlfn.XLOOKUP($A25,Index!$B$2:$B$995,Index!$D$2:$D$995,"Not Found")),"")} | F25: {=IF(NOT(ISBLANK($A25)), (_xlfn.XLOOKUP($A25,Index!$B$2:$B$995,Index!$E$2:$E$995,"Not Found")),"")} | G25: {=IF(NOT(ISBLANK(A25)), ((_xlfn.XLOOKUP(A25,Index!$B$2:$B$995,Index!$F$2:$F$995,"Not Found"))*B25),"")}
C26: {=IF(NOT(ISBLANK($A26)), (_xlfn.XLOOKUP($A26,Index!$B$2:$B$995,Index!$C$2:$C$995,"Not Found")),"")} | D26: {=IF(NOT(ISBLANK(A26)), (_xlfn.XLOOKUP($A26,Index!$B$2:B$995,Index!$A$2:$A$995,"Not Found")),"")} | E26: {=IF(NOT(ISBLANK($A26)), (_xlfn.XLOOKUP($A26,Index!$B$2:$B$995,Index!$D$2:$D$995,"Not Found")),"")} | F26: {=IF(NOT(ISBLANK($A26)), (_xlfn.XLOOKUP($A26,Index!$B$2:$B$995,Index!$E$2:$E$995,"Not Found")),"")} | G26: {=IF(NOT(ISBLANK(A26)), ((_xlfn.XLOOKUP(A26,Index!$B$2:$B$995,Index!$F$2:$F$995,"Not Found"))*B26),"")}
C27: {=IF(NOT(ISBLANK($A27)), (_xlfn.XLOOKUP($A27,Index!$B$2:$B$995,Index!$C$2:$C$995,"Not Found")),"")} | D27: {=IF(NOT(ISBLANK(A27)), (_xlfn.XLOOKUP($A27,Index!$B$2:B$995,Index!$A$2:$A$995,"Not Found")),"")} | E27: {=IF(NOT(ISBLANK($A27)), (_xlfn.XLOOKUP($A27,Index!$B$2:$B$995,Index!$D$2:$D$995,"Not Found")),"")} | F27: {=IF(NOT(ISBLANK($A27)), (_xlfn.XLOOKUP($A27,Index!$B$2:$B$995,Index!$E$2:$E$995,"Not Found")),"")} | G27: {=IF(NOT(ISBLANK(A27)), ((_xlfn.XLOOKUP(A27,Index!$B$2:$B$995,Index!$F$2:$F$995,"Not Found"))*B27),"")}
C28: {=IF(NOT(ISBLANK($A28)), (_xlfn.XLOOKUP($A28,Index!$B$2:$B$995,Index!$C$2:$C$995,"Not Found")),"")} | D28: {=IF(NOT(ISBLANK(A28)), (_xlfn.XLOOKUP($A28,Index!$B$2:B$995,Index!$A$2:$A$995,"Not Found")),"")} | E28: {=IF(NOT(ISBLANK($A28)), (_xlfn.XLOOKUP($A28,Index!$B$2:$B$995,Index!$D$2:$D$995,"Not Found")),"")} | F28: {=IF(NOT(ISBLANK($A28)), (_xlfn.XLOOKUP($A28,Index!$B$2:$B$995,Index!$E$2:$E$995,"Not Found")),"")} | G28: {=IF(NOT(ISBLANK(A28)), ((_xlfn.XLOOKUP(A28,Index!$B$2:$B$995,Index!$F$2:$F$995,"Not Found"))*B28),"")}
C29: {=IF(NOT(ISBLANK($A29)), (_xlfn.XLOOKUP($A29,Index!$B$2:$B$995,Index!$C$2:$C$995,"Not Found")),"")} | D29: {=IF(NOT(ISBLANK(A29)), (_xlfn.XLOOKUP($A29,Index!$B$2:B$995,Index!$A$2:$A$995,"Not Found")),"")} | E29: {=IF(NOT(ISBLANK($A29)), (_xlfn.XLOOKUP($A29,Index!$B$2:$B$995,Index!$D$2:$D$995,"Not Found")),"")} | F29: {=IF(NOT(ISBLANK($A29)), (_xlfn.XLOOKUP($A29,Index!$B$2:$B$995,Index!$E$2:$E$995,"Not Found")),"")} | G29: {=IF(NOT(ISBLANK(A29)), ((_xlfn.XLOOKUP(A29,Index!$B$2:$B$995,Index!$F$2:$F$995,"Not Found"))*B29),"")}
C30: {=IF(NOT(ISBLANK($A30)), (_xlfn.XLOOKUP($A30,Index!$B$2:$B$995,Index!$C$2:$C$995,"Not Found")),"")} | D30: {=IF(NOT(ISBLANK(A30)), (_xlfn.XLOOKUP($A30,Index!$B$2:B$995,Index!$A$2:$A$995,"Not Found")),"")} | E30: {=IF(NOT(ISBLANK($A30)), (_xlfn.XLOOKUP($A30,Index!$B$2:$B$995,Index!$D$2:$D$995,"Not Found")),"")} | F30: {=IF(NOT(ISBLANK($A30)), (_xlfn.XLOOKUP($A30,Index!$B$2:$B$995,Index!$E$2:$E$995,"Not Found")),"")} | G30: {=IF(NOT(ISBLANK(A30)), ((_xlfn.XLOOKUP(A30,Index!$B$2:$B$995,Index!$F$2:$F$995,"Not Found"))*B30),"")}
C31: {=IF(NOT(ISBLANK($A31)), (_xlfn.XLOOKUP($A31,Index!$B$2:$B$995,Index!$C$2:$C$995,"Not Found")),"")} | D31: {=IF(NOT(ISBLANK(A31)), (_xlfn.XLOOKUP($A31,Index!$B$2:B$995,Index!$A$2:$A$995,"Not Found")),"")} | E31: {=IF(NOT(ISBLANK($A31)), (_xlfn.XLOOKUP($A31,Index!$B$2:$B$995,Index!$D$2:$D$995,"Not Found")),"")} | F31: {=IF(NOT(ISBLANK($A31)), (_xlfn.XLOOKUP($A31,Index!$B$2:$B$995,Index!$E$2:$E$995,"Not Found")),"")} | G31: {=IF(NOT(ISBLANK(A31)), ((_xlfn.XLOOKUP(A31,Index!$B$2:$B$995,Index!$F$2:$F$995,"Not Found"))*B31),"")}
C32: {=IF(NOT(ISBLANK($A32)), (_xlfn.XLOOKUP($A32,Index!$B$2:$B$995,Index!$C$2:$C$995,"Not Found")),"")} | D32: {=IF(NOT(ISBLANK(A32)), (_xlfn.XLOOKUP($A32,Index!$B$2:B$995,Index!$A$2:$A$995,"Not Found")),"")} | E32: {=IF(NOT(ISBLANK($A32)), (_xlfn.XLOOKUP($A32,Index!$B$2:$B$995,Index!$D$2:$D$995,"Not Found")),"")} | F32: {=IF(NOT(ISBLANK($A32)), (_xlfn.XLOOKUP($A32,Index!$B$2:$B$995,Index!$E$2:$E$995,"Not Found")),"")} | G32: {=IF(NOT(ISBLANK(A32)), ((_xlfn.XLOOKUP(A32,Index!$B$2:$B$995,Index!$F$2:$F$995,"Not Found"))*B32),"")}
C33: {=IF(NOT(ISBLANK($A33)), (_xlfn.XLOOKUP($A33,Index!$B$2:$B$995,Index!$C$2:$C$995,"Not Found")),"")} | D33: {=IF(NOT(ISBLANK(A33)), (_xlfn.XLOOKUP($A33,Index!$B$2:B$995,Index!$A$2:$A$995,"Not Found")),"")} | E33: {=IF(NOT(ISBLANK($A33)), (_xlfn.XLOOKUP($A33,Index!$B$2:$B$995,Index!$D$2:$D$995,"Not Found")),"")} | F33: {=IF(NOT(ISBLANK($A33)), (_xlfn.XLOOKUP($A33,Index!$B$2:$B$995,Index!$E$2:$E$995,"Not Found")),"")} | G33: {=IF(NOT(ISBLANK(A33)), ((_xlfn.XLOOKUP(A33,Index!$B$2:$B$995,Index!$F$2:$F$995,"Not Found"))*B33),"")}
C34: {=IF(NOT(ISBLANK($A34)), (_xlfn.XLOOKUP($A34,Index!$B$2:$B$995,Index!$C$2:$C$995,"Not Found")),"")} | D34: {=IF(NOT(ISBLANK(A34)), (_xlfn.XLOOKUP($A34,Index!$B$2:B$995,Index!$A$2:$A$995,"Not Found")),"")} | E34: {=IF(NOT(ISBLANK($A34)), (_xlfn.XLOOKUP($A34,Index!$B$2:$B$995,Index!$D$2:$D$995,"Not Found")),"")} | F34: {=IF(NOT(ISBLANK($A34)), (_xlfn.XLOOKUP($A34,Index!$B$2:$B$995,Index!$E$2:$E$995,"Not Found")),"")} | G34: {=IF(NOT(ISBLANK(A34)), ((_xlfn.XLOOKUP(A34,Index!$B$2:$B$995,Index!$F$2:$F$995,"Not Found"))*B34),"")}
C35: {=IF(NOT(ISBLANK($A35)), (_xlfn.XLOOKUP($A35,Index!$B$2:$B$995,Index!$C$2:$C$995,"Not Found")),"")} | D35: {=IF(NOT(ISBLANK(A35)), (_xlfn.XLOOKUP($A35,Index!$B$2:B$995,Index!$A$2:$A$995,"Not Found")),"")} | E35: {=IF(NOT(ISBLANK($A35)), (_xlfn.XLOOKUP($A35,Index!$B$2:$B$995,Index!$D$2:$D$995,"Not Found")),"")} | F35: {=IF(NOT(ISBLANK($A35)), (_xlfn.XLOOKUP($A35,Index!$B$2:$B$995,Index!$E$2:$E$995,"Not Found")),"")} | G35: {=IF(NOT(ISBLANK(A35)), ((_xlfn.XLOOKUP(A35,Index!$B$2:$B$995,Index!$F$2:$F$995,"Not Found"))*B35),"")}
C36: {=IF(NOT(ISBLANK($A36)), (_xlfn.XLOOKUP($A36,Index!$B$2:$B$995,Index!$C$2:$C$995,"Not Found")),"")} | D36: {=IF(NOT(ISBLANK(A36)), (_xlfn.XLOOKUP($A36,Index!$B$2:B$995,Index!$A$2:$A$995,"Not Found")),"")} | E36: {=IF(NOT(ISBLANK($A36)), (_xlfn.XLOOKUP($A36,Index!$B$2:$B$995,Index!$D$2:$D$995,"Not Found")),"")} | F36: {=IF(NOT(ISBLANK($A36)), (_xlfn.XLOOKUP($A36,Index!$B$2:$B$995,Index!$E$2:$E$995,"Not Found")),"")} | G36: {=IF(NOT(ISBLANK(A36)), ((_xlfn.XLOOKUP(A36,Index!$B$2:$B$995,Index!$F$2:$F$995,"Not Found"))*B36),"")}
... C77: {=IF(NOT(ISBLANK($A77)), (_xlfn.XLOOKUP($A77,Index!$B$2:$B$995,Index!$C$2:$C$995,"Not Found")),"")} | D77: {=IF(NOT(ISBLANK(A77)), (_xlfn.XLOOKUP($A77,Index!$B$2:B$995,Index!$A$2:$A$995,"Not Found")),"")} | E77: {=IF(NOT(ISBLANK($A77)), (_xlfn.XLOOKUP($A77,Index!$B$2:$B$995,Index!$D$2:$D$995,"Not Found")),"")} | F77: {=IF(NOT(ISBLANK($A77)), (_xlfn.XLOOKUP($A77,Index!$B$2:$B$995,Index!$E$2:$E$995,"Not Found")),"")} | G77: {=IF(NOT(ISBLANK(A77)), ((_xlfn.XLOOKUP(A77,Index!$B$2:$B$995,Index!$F$2:$F$995,"Not Found"))*B77),"")}

Sheet R T2-1
A1: Card | B1: Quantity | C1: Type | D1: ID | E1: Stage / Rarity | F1: Remaining Evo | G1: Feature Weight | I1: Card Total | K1: Type | L1: Num | M1: Basic | N1: S1 Max | O1: S1 Mid | P1: S2 | Q1: No Evolve
A2: Eevee R | B2: 4 | C2: {=IF(NOT(ISBLANK($A2)), (_xlfn.XLOOKUP($A2,Index!$B$2:$B$995,Index!$C$2:$C$995,"Not Found")),"")} -> C | D2: {=IF(NOT(ISBLANK(A2)), (_xlfn.XLOOKUP($A2,Index!$B$2:B$995,Index!$A$2:$A$995,"Not Found")),"")} -> base5-55 | E2: {=IF(NOT(ISBLANK($A2)), (_xlfn.XLOOKUP($A2,Index!$B$2:$B$995,Index!$D$2:$D$995,"Not Found")),"")} -> b | F2: {=IF(NOT(ISBLANK($A2)), (_xlfn.XLOOKUP($A2,Index!$B$2:$B$995,Index!$E$2:$E$995,"Not Found")),"")} -> y | G2: {=IF(NOT(ISBLANK(A2)), ((_xlfn.XLOOKUP(A2,Index!$B$2:$B$995,Index!$F$2:$F$995,"Not Found"))*B2),"")} -> 0 | I2: =SUM(B2:B38) -> 60 | K2: E | L2: =IF(NOT(ISBLANK(K2)), SUM(M2:P2), "") -> 6 | M2: =IF(NOT(ISBLANK($K2)), SUMIFS($B$2:$B$32, $E$2:$E$32, "B", $C$2:$C$32,$K2), "") -> 4 | N2: =IF(NOT(ISBLANK($K2)),SUMIFS($B$2:$B$32,$E$2:$E$32, "1", $C$2:$C$32,$K2,$F$2:$F$32,"N"), "") -> 2 | O2: =IF(NOT(ISBLANK($K2)),SUMIFS($B$2:$B$32,$E$2:$E$32, "1", $C$2:$C$32,$K2,$F$2:$F$32,"Y"), "") -> 0 | P2: =IF(NOT(ISBLANK($K2)),SUMIFS($B$2:$B$32,$E$2:$E$32, "2", $C$2:$C$32,$K2), "") -> 0 | Q2: =IF(NOT(ISBLANK($K2)),SUMIFS($B$2:$B$32,$E$2:$E$32, "B", $C$2:$C$32,$K2,$F$2:$F$32,"N"), "") -> 1
A3: Dark Jolteon | B3: 1 | C3: {=IF(NOT(ISBLANK($A3)), (_xlfn.XLOOKUP($A3,Index!$B$2:$B$995,Index!$C$2:$C$995,"Not Found")),"")} -> E | D3: {=IF(NOT(ISBLANK(A3)), (_xlfn.XLOOKUP($A3,Index!$B$2:B$995,Index!$A$2:$A$995,"Not Found")),"")} -> base5-38 | E3: {=IF(NOT(ISBLANK($A3)), (_xlfn.XLOOKUP($A3,Index!$B$2:$B$995,Index!$D$2:$D$995,"Not Found")),"")} -> 1 | F3: {=IF(NOT(ISBLANK($A3)), (_xlfn.XLOOKUP($A3,Index!$B$2:$B$995,Index!$E$2:$E$995,"Not Found")),"")} -> n | G3: {=IF(NOT(ISBLANK(A3)), ((_xlfn.XLOOKUP(A3,Index!$B$2:$B$995,Index!$F$2:$F$995,"Not Found"))*B3),"")} -> 2 | K3: R | L3: =IF(NOT(ISBLANK(K3)), SUM(M3:P3), "") -> 6 | M3: =IF(NOT(ISBLANK($K3)), SUMIFS($B$2:$B$32, $E$2:$E$32, "B", $C$2:$C$32,$K3), "") -> 4 | N3: =IF(NOT(ISBLANK($K3)),SUMIFS($B$2:$B$32,$E$2:$E$32, "1", $C$2:$C$32,$K3,$F$2:$F$32,"N"), "") -> 2 | O3: =IF(NOT(ISBLANK($K3)),SUMIFS($B$2:$B$32,$E$2:$E$32, "1", $C$2:$C$32,$K3,$F$2:$F$32,"Y"), "") -> 0 | P3: =IF(NOT(ISBLANK($K3)),SUMIFS($B$2:$B$32,$E$2:$E$32, "2", $C$2:$C$32,$K3), "") -> 0 | Q3: =IF(NOT(ISBLANK($K3)),SUMIFS($B$2:$B$32,$E$2:$E$32, "B", $C$2:$C$32,$K3,$F$2:$F$32,"N"), "") -> 1
A4: Dark Flareon | B4: 1 | C4: {=IF(NOT(ISBLANK($A4)), (_xlfn.XLOOKUP($A4,Index!$B$2:$B$995,Index!$C$2:$C$995,"Not Found")),"")} -> R | D4: {=IF(NOT(ISBLANK(A4)), (_xlfn.XLOOKUP($A4,Index!$B$2:B$995,Index!$A$2:$A$995,"Not Found")),"")} -> base5-35 | E4: {=IF(NOT(ISBLANK($A4)), (_xlfn.XLOOKUP($A4,Index!$B$2:$B$995,Index!$D$2:$D$995,"Not Found")),"")} -> 1 | F4: {=IF(NOT(ISBLANK($A4)), (_xlfn.XLOOKUP($A4,Index!$B$2:$B$995,Index!$E$2:$E$995,"Not Found")),"")} -> n | G4: {=IF(NOT(ISBLANK(A4)), ((_xlfn.XLOOKUP(A4,Index!$B$2:$B$995,Index!$F$2:$F$995,"Not Found"))*B4),"")} -> 1.5 | K4: W | L4: =IF(NOT(ISBLANK(K4)), SUM(M4:P4), "") -> 6 | M4: =IF(NOT(ISBLANK($K4)), SUMIFS($B$2:$B$32, $E$2:$E$32, "B", $C$2:$C$32,$K4), "") -> 4 | N4: =IF(NOT(ISBLANK($K4)),SUMIFS($B$2:$B$32,$E$2:$E$32, "1", $C$2:$C$32,$K4,$F$2:$F$32,"N"), "") -> 2 | O4: =IF(NOT(ISBLANK($K4)),SUMIFS($B$2:$B$32,$E$2:$E$32, "1", $C$2:$C$32,$K4,$F$2:$F$32,"Y"), "") -> 0 | P4: =IF(NOT(ISBLANK($K4)),SUMIFS($B$2:$B$32,$E$2:$E$32, "2", $C$2:$C$32,$K4), "") -> 0 | Q4: =IF(NOT(ISBLANK($K4)),SUMIFS($B$2:$B$32,$E$2:$E$32, "B", $C$2:$C$32,$K4,$F$2:$F$32,"N"), "") -> 1
A5: Dark Vaporeon | B5: 1 | C5: {=IF(NOT(ISBLANK($A5)), (_xlfn.XLOOKUP($A5,Index!$B$2:$B$995,Index!$C$2:$C$995,"Not Found")),"")} -> W | D5: {=IF(NOT(ISBLANK(A5)), (_xlfn.XLOOKUP($A5,Index!$B$2:B$995,Index!$A$2:$A$995,"Not Found")),"")} -> base5-45 | E5: {=IF(NOT(ISBLANK($A5)), (_xlfn.XLOOKUP($A5,Index!$B$2:$B$995,Index!$D$2:$D$995,"Not Found")),"")} -> 1 | F5: {=IF(NOT(ISBLANK($A5)), (_xlfn.XLOOKUP($A5,Index!$B$2:$B$995,Index!$E$2:$E$995,"Not Found")),"")} -> n | G5: {=IF(NOT(ISBLANK(A5)), ((_xlfn.XLOOKUP(A5,Index!$B$2:$B$995,Index!$F$2:$F$995,"Not Found"))*B5),"")} -> 1.5 | K5: C | L5: =IF(NOT(ISBLANK(K5)), SUM(M5:P5), "") -> 4 | M5: =IF(NOT(ISBLANK($K5)), SUMIFS($B$2:$B$32, $E$2:$E$32, "B", $C$2:$C$32,$K5), "") -> 4 | N5: =IF(NOT(ISBLANK($K5)),SUMIFS($B$2:$B$32,$E$2:$E$32, "1", $C$2:$C$32,$K5,$F$2:$F$32,"N"), "") -> 0 | O5: =IF(NOT(ISBLANK($K5)),SUMIFS($B$2:$B$32,$E$2:$E$32, "1", $C$2:$C$32,$K5,$F$2:$F$32,"Y"), "") -> 0 | P5: =IF(NOT(ISBLANK($K5)),SUMIFS($B$2:$B$32,$E$2:$E$32, "2", $C$2:$C$32,$K5), "") -> 0 | Q5: =IF(NOT(ISBLANK($K5)),SUMIFS($B$2:$B$32,$E$2:$E$32, "B", $C$2:$C$32,$K5,$F$2:$F$32,"N"), "") -> 0
A6: Magnemite R | B6: 3 | C6: {=IF(NOT(ISBLANK($A6)), (_xlfn.XLOOKUP($A6,Index!$B$2:$B$995,Index!$C$2:$C$995,"Not Found")),"")} -> E | D6: {=IF(NOT(ISBLANK(A6)), (_xlfn.XLOOKUP($A6,Index!$B$2:B$995,Index!$A$2:$A$995,"Not Found")),"")} -> base5-60 | E6: {=IF(NOT(ISBLANK($A6)), (_xlfn.XLOOKUP($A6,Index!$B$2:$B$995,Index!$D$2:$D$995,"Not Found")),"")} -> b | F6: {=IF(NOT(ISBLANK($A6)), (_xlfn.XLOOKUP($A6,Index!$B$2:$B$995,Index!$E$2:$E$995,"Not Found")),"")} -> y | G6: {=IF(NOT(ISBLANK(A6)), ((_xlfn.XLOOKUP(A6,Index!$B$2:$B$995,Index!$F$2:$F$995,"Not Found"))*B6),"")} -> 0 | L6: =IF(NOT(ISBLANK(K6)), SUM(M6:P6), "") | M6: =IF(NOT(ISBLANK($K6)), COUNTIFS($E$2:$E$32, "B", $C$2:$C$32,$K6), "") | N6: =IF(NOT(ISBLANK(K6)),COUNTIFS($E$2:$E$32, "1", $C$2:$C$32,$K6,$F$2:$F$32,"N"), "") | O6: =IF(NOT(ISBLANK($K6)),COUNTIFS($E$2:$E$32, "1", $C$2:$C$32,$K6,$F$2:$F$32,"Y"), "") | P6: =IF(NOT(ISBLANK($K6)),COUNTIFS($E$2:$E$32, "2", $C$2:$C$32,$K6), "") | Q6: =IF(NOT(ISBLANK($K6)),COUNTIFS($E$2:$E$32, "B", $C$2:$C$32,$K6,$F$2:$F$32,"N"), "")
A7: Dark Magneton NH | B7: 1 | C7: {=IF(NOT(ISBLANK($A7)), (_xlfn.XLOOKUP($A7,Index!$B$2:$B$995,Index!$C$2:$C$995,"Not Found")),"")} -> E | D7: {=IF(NOT(ISBLANK(A7)), (_xlfn.XLOOKUP($A7,Index!$B$2:B$995,Index!$A$2:$A$995,"Not Found")),"")} -> base5-28 | E7: {=IF(NOT(ISBLANK($A7)), (_xlfn.XLOOKUP($A7,Index!$B$2:$B$995,Index!$D$2:$D$995,"Not Found")),"")} -> 1 | F7: {=IF(NOT(ISBLANK($A7)), (_xlfn.XLOOKUP($A7,Index!$B$2:$B$995,Index!$E$2:$E$995,"Not Found")),"")} -> n | G7: {=IF(NOT(ISBLANK(A7)), ((_xlfn.XLOOKUP(A7,Index!$B$2:$B$995,Index!$F$2:$F$995,"Not Found"))*B7),"")} -> 2 | K7: Total | L7: =SUM(L2:L6) -> 22 | M7: =SUM(M2:M6) -> 16 | N7: =SUM(N2:N6) -> 6 | O7: =SUM(O2:O6) -> 0 | P7: =SUM(P2:P6) -> 0 | Q7: =SUM(Q2:Q6) -> 3
A8: Ponyta R | B8: 3 | C8: {=IF(NOT(ISBLANK($A8)), (_xlfn.XLOOKUP($A8,Index!$B$2:$B$995,Index!$C$2:$C$995,"Not Found")),"")} -> R | D8: {=IF(NOT(ISBLANK(A8)), (_xlfn.XLOOKUP($A8,Index!$B$2:B$995,Index!$A$2:$A$995,"Not Found")),"")} -> base5-64 | E8: {=IF(NOT(ISBLANK($A8)), (_xlfn.XLOOKUP($A8,Index!$B$2:$B$995,Index!$D$2:$D$995,"Not Found")),"")} -> b | F8: {=IF(NOT(ISBLANK($A8)), (_xlfn.XLOOKUP($A8,Index!$B$2:$B$995,Index!$E$2:$E$995,"Not Found")),"")} -> y | G8: {=IF(NOT(ISBLANK(A8)), ((_xlfn.XLOOKUP(A8,Index!$B$2:$B$995,Index!$F$2:$F$995,"Not Found"))*B8),"")} -> 0
A9: Dark Rapidash | B9: 1 | C9: {=IF(NOT(ISBLANK($A9)), (_xlfn.XLOOKUP($A9,Index!$B$2:$B$995,Index!$C$2:$C$995,"Not Found")),"")} -> R | D9: {=IF(NOT(ISBLANK(A9)), (_xlfn.XLOOKUP($A9,Index!$B$2:B$995,Index!$A$2:$A$995,"Not Found")),"")} -> base5-44 | E9: {=IF(NOT(ISBLANK($A9)), (_xlfn.XLOOKUP($A9,Index!$B$2:$B$995,Index!$D$2:$D$995,"Not Found")),"")} -> 1 | F9: {=IF(NOT(ISBLANK($A9)), (_xlfn.XLOOKUP($A9,Index!$B$2:$B$995,Index!$E$2:$E$995,"Not Found")),"")} -> n | G9: {=IF(NOT(ISBLANK(A9)), ((_xlfn.XLOOKUP(A9,Index!$B$2:$B$995,Index!$F$2:$F$995,"Not Found"))*B9),"")} -> 1.5 | M9: Common | N9: Uncommon | O9: Rare
A10: Tentacool | B10: 3 | C10: {=IF(NOT(ISBLANK($A10)), (_xlfn.XLOOKUP($A10,Index!$B$2:$B$995,Index!$C$2:$C$995,"Not Found")),"")} -> W | D10: {=IF(NOT(ISBLANK(A10)), (_xlfn.XLOOKUP($A10,Index!$B$2:B$995,Index!$A$2:$A$995,"Not Found")),"")} -> base3-56 | E10: {=IF(NOT(ISBLANK($A10)), (_xlfn.XLOOKUP($A10,Index!$B$2:$B$995,Index!$D$2:$D$995,"Not Found")),"")} -> b | F10: {=IF(NOT(ISBLANK($A10)), (_xlfn.XLOOKUP($A10,Index!$B$2:$B$995,Index!$E$2:$E$995,"Not Found")),"")} -> y | G10: {=IF(NOT(ISBLANK(A10)), ((_xlfn.XLOOKUP(A10,Index!$B$2:$B$995,Index!$F$2:$F$995,"Not Found"))*B10),"")} -> 0 | K10: Trainer | L10: =SUM(M10:P10) -> 10 | M10: =IF(NOT(ISBLANK($K10)), SUMIFS($B$2:$B$32,$E$2:$E$32, "C", $C$2:$C$32,"T"), "") -> 6 | N10: =IF(NOT(ISBLANK($K10)), SUMIFS($B$2:$B$32,$E$2:$E$32, "U", $C$2:$C$32,"T"), "") -> 3 | O10: =IF(NOT(ISBLANK($K$2)), SUMIFS($B$2:$B$32,$E$2:$E$32, "R", $C$2:$C$32,"T"), "") -> 1
A11: Tentacruel | B11: 1 | C11: {=IF(NOT(ISBLANK($A11)), (_xlfn.XLOOKUP($A11,Index!$B$2:$B$995,Index!$C$2:$C$995,"Not Found")),"")} -> W | D11: {=IF(NOT(ISBLANK(A11)), (_xlfn.XLOOKUP($A11,Index!$B$2:B$995,Index!$A$2:$A$995,"Not Found")),"")} -> base3-44 | E11: {=IF(NOT(ISBLANK($A11)), (_xlfn.XLOOKUP($A11,Index!$B$2:$B$995,Index!$D$2:$D$995,"Not Found")),"")} -> 1 | F11: {=IF(NOT(ISBLANK($A11)), (_xlfn.XLOOKUP($A11,Index!$B$2:$B$995,Index!$E$2:$E$995,"Not Found")),"")} -> n | G11: {=IF(NOT(ISBLANK(A11)), ((_xlfn.XLOOKUP(A11,Index!$B$2:$B$995,Index!$F$2:$F$995,"Not Found"))*B11),"")} -> 1.5 | K11: Energy | L11: =IF(NOT(ISBLANK($K$2)), SUMIFS($B$2:$B$32, $C$2:$C$32,"Energy"), "") -> 28
A12: E Energy | B12: 8 | C12: {=IF(NOT(ISBLANK($A12)), (_xlfn.XLOOKUP($A12,Index!$B$2:$B$995,Index!$C$2:$C$995,"Not Found")),"")} -> Energy | D12: {=IF(NOT(ISBLANK(A12)), (_xlfn.XLOOKUP($A12,Index!$B$2:B$995,Index!$A$2:$A$995,"Not Found")),"")} -> base1-100 | E12: {=IF(NOT(ISBLANK($A12)), (_xlfn.XLOOKUP($A12,Index!$B$2:$B$995,Index!$D$2:$D$995,"Not Found")),"")} | F12: {=IF(NOT(ISBLANK($A12)), (_xlfn.XLOOKUP($A12,Index!$B$2:$B$995,Index!$E$2:$E$995,"Not Found")),"")} | G12: {=IF(NOT(ISBLANK(A12)), ((_xlfn.XLOOKUP(A12,Index!$B$2:$B$995,Index!$F$2:$F$995,"Not Found"))*B12),"")} -> 0 | K12: Pokemon | L12: =L7 -> 22
A13: R Energy | B13: 8 | C13: {=IF(NOT(ISBLANK($A13)), (_xlfn.XLOOKUP($A13,Index!$B$2:$B$995,Index!$C$2:$C$995,"Not Found")),"")} -> Energy | D13: {=IF(NOT(ISBLANK(A13)), (_xlfn.XLOOKUP($A13,Index!$B$2:B$995,Index!$A$2:$A$995,"Not Found")),"")} -> base1-98 | E13: {=IF(NOT(ISBLANK($A13)), (_xlfn.XLOOKUP($A13,Index!$B$2:$B$995,Index!$D$2:$D$995,"Not Found")),"")} | F13: {=IF(NOT(ISBLANK($A13)), (_xlfn.XLOOKUP($A13,Index!$B$2:$B$995,Index!$E$2:$E$995,"Not Found")),"")} | G13: {=IF(NOT(ISBLANK(A13)), ((_xlfn.XLOOKUP(A13,Index!$B$2:$B$995,Index!$F$2:$F$995,"Not Found"))*B13),"")} -> 0
A14: W Energy | B14: 8 | C14: {=IF(NOT(ISBLANK($A14)), (_xlfn.XLOOKUP($A14,Index!$B$2:$B$995,Index!$C$2:$C$995,"Not Found")),"")} -> Energy | D14: {=IF(NOT(ISBLANK(A14)), (_xlfn.XLOOKUP($A14,Index!$B$2:B$995,Index!$A$2:$A$995,"Not Found")),"")} -> base1-102 | E14: {=IF(NOT(ISBLANK($A14)), (_xlfn.XLOOKUP($A14,Index!$B$2:$B$995,Index!$D$2:$D$995,"Not Found")),"")} | F14: {=IF(NOT(ISBLANK($A14)), (_xlfn.XLOOKUP($A14,Index!$B$2:$B$995,Index!$E$2:$E$995,"Not Found")),"")} | G14: {=IF(NOT(ISBLANK(A14)), ((_xlfn.XLOOKUP(A14,Index!$B$2:$B$995,Index!$F$2:$F$995,"Not Found"))*B14),"")} -> 0
A15: DC Energy | B15: 2 | C15: {=IF(NOT(ISBLANK($A15)), (_xlfn.XLOOKUP($A15,Index!$B$2:$B$995,Index!$C$2:$C$995,"Not Found")),"")} -> Energy | D15: {=IF(NOT(ISBLANK(A15)), (_xlfn.XLOOKUP($A15,Index!$B$2:B$995,Index!$A$2:$A$995,"Not Found")),"")} -> base1-96 | E15: {=IF(NOT(ISBLANK($A15)), (_xlfn.XLOOKUP($A15,Index!$B$2:$B$995,Index!$D$2:$D$995,"Not Found")),"")} | F15: {=IF(NOT(ISBLANK($A15)), (_xlfn.XLOOKUP($A15,Index!$B$2:$B$995,Index!$E$2:$E$995,"Not Found")),"")} | G15: {=IF(NOT(ISBLANK(A15)), ((_xlfn.XLOOKUP(A15,Index!$B$2:$B$995,Index!$F$2:$F$995,"Not Found"))*B15),"")} -> 0 | K15: Feature Weight:
A16: Magmar | B16: 1 | C16: {=IF(NOT(ISBLANK($A16)), (_xlfn.XLOOKUP($A16,Index!$B$2:$B$995,Index!$C$2:$C$995,"Not Found")),"")} -> R | D16: {=IF(NOT(ISBLANK(A16)), (_xlfn.XLOOKUP($A16,Index!$B$2:B$995,Index!$A$2:$A$995,"Not Found")),"")} -> base1-36 | E16: {=IF(NOT(ISBLANK($A16)), (_xlfn.XLOOKUP($A16,Index!$B$2:$B$995,Index!$D$2:$D$995,"Not Found")),"")} -> b | F16: {=IF(NOT(ISBLANK($A16)), (_xlfn.XLOOKUP($A16,Index!$B$2:$B$995,Index!$E$2:$E$995,"Not Found")),"")} -> n | G16: {=IF(NOT(ISBLANK(A16)), ((_xlfn.XLOOKUP(A16,Index!$B$2:$B$995,Index!$F$2:$F$995,"Not Found"))*B16),"")} -> 0 | K16: =K2 -> E | L16: =IF(NOT(ISBLANK($K2)), SUMIFS($G$2:$G$32, $C$2:$C$32,$K2), "") -> 5
A17: Electabuzz | B17: 1 | C17: {=IF(NOT(ISBLANK($A17)), (_xlfn.XLOOKUP($A17,Index!$B$2:$B$995,Index!$C$2:$C$995,"Not Found")),"")} -> E | D17: {=IF(NOT(ISBLANK(A17)), (_xlfn.XLOOKUP($A17,Index!$B$2:B$995,Index!$A$2:$A$995,"Not Found")),"")} -> base1-20 | E17: {=IF(NOT(ISBLANK($A17)), (_xlfn.XLOOKUP($A17,Index!$B$2:$B$995,Index!$D$2:$D$995,"Not Found")),"")} -> b | F17: {=IF(NOT(ISBLANK($A17)), (_xlfn.XLOOKUP($A17,Index!$B$2:$B$995,Index!$E$2:$E$995,"Not Found")),"")} -> n | G17: {=IF(NOT(ISBLANK(A17)), ((_xlfn.XLOOKUP(A17,Index!$B$2:$B$995,Index!$F$2:$F$995,"Not Found"))*B17),"")} -> 1 | K17: =K3 -> R | L17: =IF(NOT(ISBLANK($K3)), SUMIFS($G$2:$G$32, $C$2:$C$32,$K3), "") -> 3
A18: Lapras | B18: 1 | C18: {=IF(NOT(ISBLANK($A18)), (_xlfn.XLOOKUP($A18,Index!$B$2:$B$995,Index!$C$2:$C$995,"Not Found")),"")} -> W | D18: {=IF(NOT(ISBLANK(A18)), (_xlfn.XLOOKUP($A18,Index!$B$2:B$995,Index!$A$2:$A$995,"Not Found")),"")} -> base3-10 | E18: {=IF(NOT(ISBLANK($A18)), (_xlfn.XLOOKUP($A18,Index!$B$2:$B$995,Index!$D$2:$D$995,"Not Found")),"")} -> b | F18: {=IF(NOT(ISBLANK($A18)), (_xlfn.XLOOKUP($A18,Index!$B$2:$B$995,Index!$E$2:$E$995,"Not Found")),"")} -> n | G18: {=IF(NOT(ISBLANK(A18)), ((_xlfn.XLOOKUP(A18,Index!$B$2:$B$995,Index!$F$2:$F$995,"Not Found"))*B18),"")} -> 1 | K18: =K4 -> W | L18: =IF(NOT(ISBLANK($K4)), SUMIFS($G$2:$G$32, $C$2:$C$32,$K4), "") -> 4
A19: Rainbow Energy NH | B19: 2 | C19: {=IF(NOT(ISBLANK($A19)), (_xlfn.XLOOKUP($A19,Index!$B$2:$B$995,Index!$C$2:$C$995,"Not Found")),"")} -> Energy | D19: {=IF(NOT(ISBLANK(A19)), (_xlfn.XLOOKUP($A19,Index!$B$2:B$995,Index!$A$2:$A$995,"Not Found")),"")} -> base5-80 | E19: {=IF(NOT(ISBLANK($A19)), (_xlfn.XLOOKUP($A19,Index!$B$2:$B$995,Index!$D$2:$D$995,"Not Found")),"")} | F19: {=IF(NOT(ISBLANK($A19)), (_xlfn.XLOOKUP($A19,Index!$B$2:$B$995,Index!$E$2:$E$995,"Not Found")),"")} | G19: {=IF(NOT(ISBLANK(A19)), ((_xlfn.XLOOKUP(A19,Index!$B$2:$B$995,Index!$F$2:$F$995,"Not Found"))*B19),"")} -> 0 | K19: =K5 -> C | L19: =IF(NOT(ISBLANK($K5)), SUMIFS($G$2:$G$32, $C$2:$C$32,$K5), "") -> 0
A20: Energy Search | B20: 2 | C20: {=IF(NOT(ISBLANK($A20)), (_xlfn.XLOOKUP($A20,Index!$B$2:$B$995,Index!$C$2:$C$995,"Not Found")),"")} -> T | D20: {=IF(NOT(ISBLANK(A20)), (_xlfn.XLOOKUP($A20,Index!$B$2:B$995,Index!$A$2:$A$995,"Not Found")),"")} -> base3-59 | E20: {=IF(NOT(ISBLANK($A20)), (_xlfn.XLOOKUP($A20,Index!$B$2:$B$995,Index!$D$2:$D$995,"Not Found")),"")} -> c | F20: {=IF(NOT(ISBLANK($A20)), (_xlfn.XLOOKUP($A20,Index!$B$2:$B$995,Index!$E$2:$E$995,"Not Found")),"")} | G20: {=IF(NOT(ISBLANK(A20)), ((_xlfn.XLOOKUP(A20,Index!$B$2:$B$995,Index!$F$2:$F$995,"Not Found"))*B20),"")} -> #VALUE! | K20: =K6
A21: Energy Retrieval | B21: 2 | C21: {=IF(NOT(ISBLANK($A21)), (_xlfn.XLOOKUP($A21,Index!$B$2:$B$995,Index!$C$2:$C$995,"Not Found")),"")} -> T | D21: {=IF(NOT(ISBLANK(A21)), (_xlfn.XLOOKUP($A21,Index!$B$2:B$995,Index!$A$2:$A$995,"Not Found")),"")} -> base1-81 | E21: {=IF(NOT(ISBLANK($A21)), (_xlfn.XLOOKUP($A21,Index!$B$2:$B$995,Index!$D$2:$D$995,"Not Found")),"")} -> u | F21: {=IF(NOT(ISBLANK($A21)), (_xlfn.XLOOKUP($A21,Index!$B$2:$B$995,Index!$E$2:$E$995,"Not Found")),"")} | G21: {=IF(NOT(ISBLANK(A21)), ((_xlfn.XLOOKUP(A21,Index!$B$2:$B$995,Index!$F$2:$F$995,"Not Found"))*B21),"")} -> #VALUE! | K21: Total: | L21: =SUM(L15:L19) -> 12
A22: Bill | B22: 2 | C22: {=IF(NOT(ISBLANK($A22)), (_xlfn.XLOOKUP($A22,Index!$B$2:$B$995,Index!$C$2:$C$995,"Not Found")),"")} -> T | D22: {=IF(NOT(ISBLANK(A22)), (_xlfn.XLOOKUP($A22,Index!$B$2:B$995,Index!$A$2:$A$995,"Not Found")),"")} -> base1-91 | E22: {=IF(NOT(ISBLANK($A22)), (_xlfn.XLOOKUP($A22,Index!$B$2:$B$995,Index!$D$2:$D$995,"Not Found")),"")} -> c | F22: {=IF(NOT(ISBLANK($A22)), (_xlfn.XLOOKUP($A22,Index!$B$2:$B$995,Index!$E$2:$E$995,"Not Found")),"")} | G22: {=IF(NOT(ISBLANK(A22)), ((_xlfn.XLOOKUP(A22,Index!$B$2:$B$995,Index!$F$2:$F$995,"Not Found"))*B22),"")} -> #VALUE!
A23: Professor Oak | B23: 1 | C23: {=IF(NOT(ISBLANK($A23)), (_xlfn.XLOOKUP($A23,Index!$B$2:$B$995,Index!$C$2:$C$995,"Not Found")),"")} -> T | D23: {=IF(NOT(ISBLANK(A23)), (_xlfn.XLOOKUP($A23,Index!$B$2:B$995,Index!$A$2:$A$995,"Not Found")),"")} -> base1-88 | E23: {=IF(NOT(ISBLANK($A23)), (_xlfn.XLOOKUP($A23,Index!$B$2:$B$995,Index!$D$2:$D$995,"Not Found")),"")} -> u | F23: {=IF(NOT(ISBLANK($A23)), (_xlfn.XLOOKUP($A23,Index!$B$2:$B$995,Index!$E$2:$E$995,"Not Found")),"")} | G23: {=IF(NOT(ISBLANK(A23)), ((_xlfn.XLOOKUP(A23,Index!$B$2:$B$995,Index!$F$2:$F$995,"Not Found"))*B23),"")} -> #VALUE!
A24: Sleep! | B24: 1 | C24: {=IF(NOT(ISBLANK($A24)), (_xlfn.XLOOKUP($A24,Index!$B$2:$B$995,Index!$C$2:$C$995,"Not Found")),"")} -> T | D24: {=IF(NOT(ISBLANK(A24)), (_xlfn.XLOOKUP($A24,Index!$B$2:B$995,Index!$A$2:$A$995,"Not Found")),"")} -> base5-79 | E24: {=IF(NOT(ISBLANK($A24)), (_xlfn.XLOOKUP($A24,Index!$B$2:$B$995,Index!$D$2:$D$995,"Not Found")),"")} -> c | F24: {=IF(NOT(ISBLANK($A24)), (_xlfn.XLOOKUP($A24,Index!$B$2:$B$995,Index!$E$2:$E$995,"Not Found")),"")} | G24: {=IF(NOT(ISBLANK(A24)), ((_xlfn.XLOOKUP(A24,Index!$B$2:$B$995,Index!$F$2:$F$995,"Not Found"))*B24),"")} -> #VALUE! | K24: Cover Card: | L24: Eevee R
A25: Switch | B25: 1 | C25: {=IF(NOT(ISBLANK($A25)), (_xlfn.XLOOKUP($A25,Index!$B$2:$B$995,Index!$C$2:$C$995,"Not Found")),"")} -> T | D25: {=IF(NOT(ISBLANK(A25)), (_xlfn.XLOOKUP($A25,Index!$B$2:B$995,Index!$A$2:$A$995,"Not Found")),"")} -> base1-95 | E25: {=IF(NOT(ISBLANK($A25)), (_xlfn.XLOOKUP($A25,Index!$B$2:$B$995,Index!$D$2:$D$995,"Not Found")),"")} -> c | F25: {=IF(NOT(ISBLANK($A25)), (_xlfn.XLOOKUP($A25,Index!$B$2:$B$995,Index!$E$2:$E$995,"Not Found")),"")} | G25: {=IF(NOT(ISBLANK(A25)), ((_xlfn.XLOOKUP(A25,Index!$B$2:$B$995,Index!$F$2:$F$995,"Not Found"))*B25),"")} -> #VALUE!
A26: Pokemon Trader | B26: 1 | C26: {=IF(NOT(ISBLANK($A26)), (_xlfn.XLOOKUP($A26,Index!$B$2:$B$995,Index!$C$2:$C$995,"Not Found")),"")} -> T | D26: {=IF(NOT(ISBLANK(A26)), (_xlfn.XLOOKUP($A26,Index!$B$2:B$995,Index!$A$2:$A$995,"Not Found")),"")} -> base1-77 | E26: {=IF(NOT(ISBLANK($A26)), (_xlfn.XLOOKUP($A26,Index!$B$2:$B$995,Index!$D$2:$D$995,"Not Found")),"")} -> r | F26: {=IF(NOT(ISBLANK($A26)), (_xlfn.XLOOKUP($A26,Index!$B$2:$B$995,Index!$E$2:$E$995,"Not Found")),"")} | G26: {=IF(NOT(ISBLANK(A26)), ((_xlfn.XLOOKUP(A26,Index!$B$2:$B$995,Index!$F$2:$F$995,"Not Found"))*B26),"")} -> #VALUE!
C27: {=IF(NOT(ISBLANK($A27)), (_xlfn.XLOOKUP($A27,Index!$B$2:$B$995,Index!$C$2:$C$995,"Not Found")),"")} | D27: {=IF(NOT(ISBLANK(A27)), (_xlfn.XLOOKUP($A27,Index!$B$2:B$995,Index!$A$2:$A$995,"Not Found")),"")} | E27: {=IF(NOT(ISBLANK($A27)), (_xlfn.XLOOKUP($A27,Index!$B$2:$B$995,Index!$D$2:$D$995,"Not Found")),"")} | F27: {=IF(NOT(ISBLANK($A27)), (_xlfn.XLOOKUP($A27,Index!$B$2:$B$995,Index!$E$2:$E$995,"Not Found")),"")} | G27: {=IF(NOT(ISBLANK(A27)), ((_xlfn.XLOOKUP(A27,Index!$B$2:$B$995,Index!$F$2:$F$995,"Not Found"))*B27),"")}
